Workbook
Name ColumnTitle1: #REF!
Name ColumnTitle1: #REF!
Name ColumnTitle1: #REF!
Name ColumnTitle1: #REF!
Name ColumnTitle1: #REF!
Name ColumnTitle1: #REF!
Name Con_OnOff: #REF!
Name CONTENT: #REF!
Name CONTENT: #REF!
Name CONTENT: #REF!
Name CONTENT: #REF!
Name CONTENT: #REF!
Name CONTENT: #REF!
Name Currency_Symbol: #REF!
Name DD_TS_Denom: #REF!
Name Denomination_Selected: #REF!
Name EndingBalance: -FV(InterestRate/12,'اسعار الخدمات'!PaymentNumber,-'اسعار الخدمات'!MonthlyPayment,LoanAmount)
Name EndingBalance: -FV([0]!InterestRate/12,'اسعار الخدمات '!PaymentNumber,-'اسعار الخدمات '!MonthlyPayment,[0]!LoanAmount)
Name EndingBalance: -FV(InterestRate/12,'تحليل التعادل '!PaymentNumber,-'تحليل التعادل '!MonthlyPayment,LoanAmount)
Name EndingBalance: -FV(InterestRate/12,PaymentNumber,-MonthlyPayment,LoanAmount)
Name Gov_OnOff: #REF!
Name HeaderRow: ROW(#REF!)
Name HeaderRow: ROW(#REF!)
Name InterestAmt: -IPMT(InterestRate/12,'اسعار الخدمات'!PaymentNumber,NumberOfPayments,LoanAmount)
Name InterestAmt: -IPMT([0]!InterestRate/12,'اسعار الخدمات '!PaymentNumber,[0]!NumberOfPayments,[0]!LoanAmount)
Name InterestAmt: -IPMT(InterestRate/12,'تحليل التعادل '!PaymentNumber,NumberOfPayments,LoanAmount)
Name InterestAmt: -IPMT(InterestRate/12,PaymentNumber,NumberOfPayments,LoanAmount)
Name InterestRate: #REF!
Name IQ_CH: 110000
Name IQ_CQ: 5000
Name IQ_CY: 10000
Name IQ_DAILY: 500000
Name IQ_FH: 100000
Name IQ_FQ: 500
Name IQ_FY: 1000
Name IQ_LTM: 2000
Name IQ_MONTH: 15000
Name IQ_NTM: 6000
Name IQ_WEEK: 50000
Name IQ_YTD: 3000
Name LastCol: COUNTA(#REF!)
Name LastCol: COUNTA(#REF!)
Name LastRow: MATCH(9.99E+307,#REF!)
Name LastRow: MATCH(9.99E+307,#REF!)
Name LoanAmount: #REF!
Name LoanIsGood: IF(LoanAmount*InterestRate*LoanYears*LoanStartDate>0,1,0)
Name LoanIsGood: IF([0]!LoanAmount*[0]!InterestRate*[0]!LoanYears*[0]!LoanStartDate>0,1,0)
Name LoanIsGood: IF(LoanAmount*InterestRate*LoanYears*LoanStartDate>0,1,0)
Name LoanIsGood: IF(LoanAmount*InterestRate*LoanYears*LoanStartDate>0,1,0)
Name LoanIsNotPaid: IF('اسعار الخدمات'!PaymentNumber<=NumberOfPayments,1,0)
Name LoanIsNotPaid: IF('اسعار الخدمات '!PaymentNumber<=[0]!NumberOfPayments,1,0)
Name LoanIsNotPaid: IF('تحليل التعادل '!PaymentNumber<=NumberOfPayments,1,0)
Name LoanIsNotPaid: IF(PaymentNumber<=NumberOfPayments,1,0)
Name LoanStartDate: #REF!
Name LoanValue: -FV(InterestRate/12,'اسعار الخدمات'!PaymentNumber-1,-'اسعار الخدمات'!MonthlyPayment,LoanAmount)
Name LoanValue: -FV([0]!InterestRate/12,'اسعار الخدمات '!PaymentNumber-1,-'اسعار الخدمات '!MonthlyPayment,[0]!LoanAmount)
Name LoanValue: -FV(InterestRate/12,'تحليل التعادل '!PaymentNumber-1,-'تحليل التعادل '!MonthlyPayment,LoanAmount)
Name LoanValue: -FV(InterestRate/12,PaymentNumber-1,-MonthlyPayment,LoanAmount)
Name LoanYears: #REF!
Name LU_Debt_type: #REF!

Sheet تحليل التعادل 
P3: الرجوع إلى جدول المحتويات
F7: السنة 1 | G7: السنة 2 | H7: السنة 3 | I7: السنة 4 | J7: السنة 5
D9: الإيرادات | F9: ='قائمة الدخل التقديرية'!D6 -> #VALUE! | G9: ='قائمة الدخل التقديرية'!E6 -> #VALUE! | H9: ='قائمة الدخل التقديرية'!F6 -> #VALUE! | I9: ='قائمة الدخل التقديرية'!G6 -> #VALUE! | J9: ='قائمة الدخل التقديرية'!H6 -> #VALUE!
D10: التكاليف المتغيرة | F10: ='قائمة الدخل التقديرية'!D10 -> 270664.8 | G10: ='قائمة الدخل التقديرية'!E10 -> 276078.1 | H10: ='قائمة الدخل التقديرية'!F10 -> 281599.66 | I10: ='قائمة الدخل التقديرية'!G10 -> 287231.65 | J10: ='قائمة الدخل التقديرية'!H10 -> 292976.28
D11: التكاليف الثابتة | F11: ='قائمة الدخل التقديرية'!D20 -> #REF! | G11: ='قائمة الدخل التقديرية'!E20 -> #REF! | H11: ='قائمة الدخل التقديرية'!F20 -> 18002337 | I11: ='قائمة الدخل التقديرية'!G20 -> 18006297 | J11: ='قائمة الدخل التقديرية'!H20 -> 18010336
D12: نسبة هامش المساهمة | F12: =100%-(F10/F9) -> #VALUE! | G12: =100%-(G10/G9) -> #VALUE! | H12: =100%-(H10/H9) -> #VALUE! | I12: =100%-(I10/I9) -> #VALUE! | J12: =100%-(J10/J9) -> #VALUE!
D13: نقطة التعادل بالقيمة | F13: =F11/F12 -> #REF! | G13: =G11/G12 -> #REF! | H13: =H11/H12 -> #VALUE! | I13: =I11/I12 -> #VALUE! | J13: =J11/J12 -> #VALUE!

Sheet قائمة الدخل التقديرية
C2: قائمة الدخل التقديرية
C4: الإيرادات | D4: السنة 1 | E4: السنة 2 | F4: السنة 3 | G4: السنة 4 | H4: السنة 5
C5: إيرادات خدمات النادي | D5: ='تقدير الإيرادات '!I9 -> #VALUE! | E5: ='تقدير الإيرادات '!F17 -> #VALUE! | F5: ='تقدير الإيرادات '!G17 -> #VALUE! | G5: ='تقدير الإيرادات '!H17 -> #VALUE! | H5: ='تقدير الإيرادات '!I17 -> #VALUE!
C6: إجمالي الإيردات | D6: =SUM(D5:D5) -> #VALUE! | E6: =SUM(E5:E5) -> #VALUE! | F6: =SUM(F5:F5) -> #VALUE! | G6: =SUM(G5:G5) -> #VALUE! | H6: =SUM(H5:H5) -> #VALUE!
C7: يطرح المصاريف المتغيرة
C8: رواتب المشرفين والمدربين | D8: =SUM('الدراسة الفنية '!G7:G9,'الدراسة الفنية '!G11,'الدراسة الفنية '!G15:G17,'الدراسة الفنية '!G19,'الدراسة الفنية '!G23:G25,'الدراسة الفنية '!G27,'الدراسة الفنية '!G31:G33,'الدراسة الفنية '!G35) -> 216000 | E8: =D8*(1+'الدراسة المالية'!$D5) -> 220320 | F8: =E8*(1+'الدراسة المالية'!$D5) -> 224726.4 | G8: =F8*(1+'الدراسة المالية'!$D5) -> 229220.93 | H8: =G8*(1+'الدراسة المالية'!$D5) -> 233805.35
C9: مصاريف تشغيلية متغيرة | D9: ='الدراسة الفنية '!I137 -> 54664.8 | E9: =D9*(1+'الدراسة المالية'!$D5) -> 55758.096 | F9: =E9*(1+'الدراسة المالية'!$D5) -> 56873.258 | G9: =F9*(1+'الدراسة المالية'!$D5) -> 58010.723 | H9: =G9*(1+'الدراسة المالية'!$D5) -> 59170.938
C10: إجمالي تكلفة الإيرادات | D10: =SUM(D8:D9) -> 270664.8 | E10: =SUM(E8:E9) -> 276078.1 | F10: =SUM(F8:F9) -> 281599.66 | G10: =SUM(G8:G9) -> 287231.65 | H10: =SUM(H8:H9) -> 292976.28
C11: مجمل الربح | D11: =D6-D10 -> #VALUE! | E11: =E6-E10 -> #VALUE! | F11: =F6-F10 -> #VALUE! | G11: =G6-G10 -> #VALUE! | H11: =H6-H10 -> #VALUE!
C12: يطرح المصاريف الأخرى الثابتة
C13: رواتب الإداريين | D13: =SUM('الدراسة الفنية '!G6,'الدراسة الفنية '!G10,'الدراسة الفنية '!G14,'الدراسة الفنية '!G18,'الدراسة الفنية '!G22,'الدراسة الفنية '!G26,'الدراسة الفنية '!G30,'الدراسة الفنية '!G34) -> 114000 | E13: =D13*(1+'الدراسة المالية'!$D5) -> 116280 | F13: =E13*(1+'الدراسة المالية'!$D5) -> 118605.6 | G13: =F13*(1+'الدراسة المالية'!$D5) -> 120977.71 | H13: =G13*(1+'الدراسة المالية'!$D5) -> 123397.27
C14: المصاريف التشغيلية الثابتة | D14: ='الدراسة الفنية '!J137 -> 76301.28 | E14: =D14*(1+'الدراسة المالية'!$D5) -> 77827.306 | F14: =E14*(1+'الدراسة المالية'!$D5) -> 79383.852 | G14: =F14*(1+'الدراسة المالية'!$D5) -> 80971.529 | H14: =G14*(1+'الدراسة المالية'!$D5) -> 82590.959
C15: مصاريف الاستهلاك | D15: =SUM('الدراسة الفنية '!I53,'الدراسة الفنية '!I79,'الدراسة الفنية '!I102) -> 14751613 | E15: =D15 -> 14751613 | F15: =E15 -> 14751613 | G15: =F15 -> 14751613 | H15: =G15 -> 14751613
C16: مصاريف الصيانة | D16: =SUM('الدراسة الفنية '!I54,'الدراسة الفنية '!I80,'الدراسة الفنية '!I103) -> 2979534.9 | E16: =D16 -> 2979534.9 | F16: =E16 -> 2979534.9 | G16: =F16 -> 2979534.9 | H16: =G16 -> 2979534.9
C17: مصاريف الايجار | F17: ='الدراسة الفنية '!$H150 -> 73200 | G17: ='الدراسة الفنية '!$H150 -> 73200 | H17: ='الدراسة الفنية '!$H150 -> 73200
C18: المصاريف القانونية | D18: =#REF!/2 -> #REF! | E18: =#REF!/2 -> #REF! | F18: - | G18: - | H18: -
C19: مصاريف الحملة التسويقية | D19: =#REF!/2 -> #REF! | E19: =#REF!/2 -> #REF! | F19: - | G19: - | H19: -
C20: إجمالي المصاريف الأخرى الثابتة | D20: =SUM(D13:D19) -> #REF! | E20: =SUM(E13:E19) -> #REF! | F20: =SUM(F13:F19) -> 18002337 | G20: =SUM(G13:G19) -> 18006297 | H20: =SUM(H13:H19) -> 18010336
C21: صافي الأرباح قبل الضريبة | D21: =D11-D20 -> #VALUE! | E21: =E11-E20 -> #VALUE! | F21: =F11-F20 -> #VALUE! | G21: =G11-G20 -> #VALUE! | H21: =H11-H20 -> #VALUE!
C22: مصروف الضريبة | D22: =D21*'الدراسة المالية'!$D6 -> #VALUE! | E22: =E21*'الدراسة المالية'!$D6 -> #VALUE! | F22: =F21*'الدراسة المالية'!$D6 -> #VALUE! | G22: =G21*'الدراسة المالية'!$D6 -> #VALUE! | H22: =H21*'الدراسة المالية'!$D6 -> #VALUE!
C23: صافي الأرباح النهائية | D23: =H46 -> #VALUE! | E23: =O46 -> #VALUE! | F23: =V46 -> #VALUE! | G23: =AC46 -> #VALUE! | H23: =AJ46 -> #VALUE!
C26: قائمة الدخل التقديرية وفقا لكل قسم | J26: قائمة الدخل التقديرية وفقا لكل قسم | Q26: قائمة الدخل التقديرية وفقا لكل قسم | X26: قائمة الدخل التقديرية وفقا لكل قسم | AE26: قائمة الدخل التقديرية وفقا لكل قسم
C27: السنة 1 | J27: السنة 2 | Q27: السنة 3 | X27: السنة 4 | AE27: السنة 5
C28: الإيرادات | D28: المسبح | E28: البادل | F28: الملعب متعدد الأغراض | G28: الصالة الرياضية | H28: الإجمالي | J28: الإيرادات | K28: المسبح | L28: البادل | M28: الملعب متعدد الأغراض | N28: الصالة الرياضية | O28: الإجمالي | Q28: الإيرادات | R28: المسبح | S28: البادل | T28: الملعب متعدد الأغراض | U28: الصالة الرياضية | V28: الإجمالي | X28: الإيرادات | Y28: المسبح | Z28: البادل | AA28: الملعب متعدد الأغراض | AB28: الصالة الرياضية | AC28: الإجمالي | AE28: الإيرادات | AF28: المسبح | AG28: البادل | AH28: الملعب متعدد الأغراض | AI28: الصالة الرياضية | AJ28: الإجمالي
C29: إيرادات خدمات النادي | D29: ='تقدير الإيرادات '!I5 -> 272700 | E29: ='تقدير الإيرادات '!I6 -> #VALUE! | F29: ='تقدير الإيرادات '!I7 -> 249900 | G29: ='تقدير الإيرادات '!I8 -> 191700 | H29: =SUM(D29:G29) -> #VALUE! | J29: إيرادات خدمات النادي | K29: ='تقدير الإيرادات '!F13 -> 291789 | L29: ='تقدير الإيرادات '!F14 -> #VALUE! | M29: ='تقدير الإيرادات '!F15 -> 267393 | N29: ='تقدير الإيرادات '!F16 -> 205119 | O29: =SUM(K29:N29) -> #VALUE! | Q29: إيرادات خدمات النادي | R29: ='تقدير الإيرادات '!G13 -> 312214.23 | S29: ='تقدير الإيرادات '!G14 -> #VALUE! | T29: ='تقدير الإيرادات '!G15 -> 286110.51 | U29: ='تقدير الإيرادات '!G16 -> 219477.33 | V29: =SUM(R29:U29) -> #VALUE! | X29: إيرادات خدمات النادي | Y29: ='تقدير الإيرادات '!H13 -> 334069.23 | Z29: ='تقدير الإيرادات '!H14 -> #VALUE! | AA29: ='تقدير الإيرادات '!H15 -> 306138.25 | AB29: ='تقدير الإيرادات '!H16 -> 234840.74 | AC29: =SUM(Y29:AB29) -> #VALUE! | AE29: إيرادات خدمات النادي | AF29: ='تقدير الإيرادات '!I13 -> 357454.07 | AG29: ='تقدير الإيرادات '!I14 -> #VALUE! | AH29: ='تقدير الإيرادات '!I15 -> 327567.92 | AI29: ='تقدير الإيرادات '!I16 -> 251279.6 | AJ29: =SUM(AF29:AI29) -> #VALUE!
C30: إجمالي الإيردات | D30: =SUM(D29:D29) -> 272700 | E30: =SUM(E29:E29) -> #VALUE! | F30: =SUM(F29:F29) -> 249900 | G30: =SUM(G29:G29) -> 191700 | H30: =SUM(H29:H29) -> #VALUE! | J30: إجمالي الإيردات | K30: =SUM(K29:K29) -> 291789 | L30: =SUM(L29:L29) -> #VALUE! | M30: =SUM(M29:M29) -> 267393 | N30: =SUM(N29:N29) -> 205119 | O30: =SUM(O29:O29) -> #VALUE! | Q30: إجمالي الإيردات | R30: =SUM(R29:R29) -> 312214.23 | S30: =SUM(S29:S29) -> #VALUE! | T30: =SUM(T29:T29) -> 286110.51 | U30: =SUM(U29:U29) -> 219477.33 | V30: =SUM(V29:V29) -> #VALUE! | X30: إجمالي الإيردات | Y30: =SUM(Y29:Y29) -> 334069.23 | Z30: =SUM(Z29:Z29) -> #VALUE! | AA30: =SUM(AA29:AA29) -> 306138.25 | AB30: =SUM(AB29:AB29) -> 234840.74 | AC30: =SUM(AC29:AC29) -> #VALUE! | AE30: إجمالي الإيردات | AF30: =SUM(AF29:AF29) -> 357454.07 | AG30: =SUM(AG29:AG29) -> #VALUE! | AH30: =SUM(AH29:AH29) -> 327567.92 | AI30: =SUM(AI29:AI29) -> 251279.6 | AJ30: =SUM(AJ29:AJ29) -> #VALUE!
C31: يطرح المصاريف المتغيرة | D31: =D30/$H30 -> #VALUE! | E31: =E30/$H30 -> #VALUE! | F31: =F30/$H30 -> #VALUE! | G31: =G30/$H30 -> #VALUE! | H31: =H30/$H30 -> #VALUE! | J31: يطرح المصاريف المتغيرة | K31: =K30/$H30 -> #VALUE! | L31: =L30/$H30 -> #VALUE! | M31: =M30/$H30 -> #VALUE! | N31: =N30/$H30 -> #VALUE! | O31: =O30/$H30 -> #VALUE! | Q31: يطرح المصاريف المتغيرة | R31: =R30/$H30 -> #VALUE! | S31: =S30/$H30 -> #VALUE! | T31: =T30/$H30 -> #VALUE! | U31: =U30/$H30 -> #VALUE! | V31: =V30/$H30 -> #VALUE! | X31: يطرح المصاريف المتغيرة | Y31: =Y30/$H30 -> #VALUE! | Z31: =Z30/$H30 -> #VALUE! | AA31: =AA30/$H30 -> #VALUE! | AB31: =AB30/$H30 -> #VALUE! | AC31: =AC30/$H30 -> #VALUE! | AE31: يطرح المصاريف المتغيرة | AF31: =AF30/$H30 -> #VALUE! | AG31: =AG30/$H30 -> #VALUE! | AH31: =AH30/$H30 -> #VALUE! | AI31: =AI30/$H30 -> #VALUE! | AJ31: =AJ30/$H30 -> #VALUE!
C32: رواتب المشرفين والمدربين | D32: =SUM('الدراسة الفنية '!G7:G9,'الدراسة الفنية '!G11) -> 54000 | E32: =SUM('الدراسة الفنية '!G15:G17,'الدراسة الفنية '!G19) -> 54000 | F32: =SUM('الدراسة الفنية '!G23:G25,'الدراسة الفنية '!G27) -> 54000 | G32: =SUM('الدراسة الفنية '!G31:G33,'الدراسة الفنية '!G35) -> 54000 | H32: =SUM(D32:G32) -> 216000 | J32: رواتب المشرفين والمدربين | K32: =SUM('الدراسة الفنية '!G7:G9,'الدراسة الفنية '!G11)*(1+'الدراسة المالية'!$D5) -> 55080 | L32: =E32*1.02 -> 55080 | M32: =F32*1.02 -> 55080 | N32: =G32*1.02 -> 55080 | O32: =SUM(K32:N32) -> 220320 | Q32: رواتب المشرفين والمدربين | R32: =K32*1.02 -> 56181.6 | S32: =L32*1.02 -> 56181.6 | T32: =M32*1.02 -> 56181.6 | U32: =N32*1.02 -> 56181.6 | V32: =SUM(R32:U32) -> 224726.4 | X32: رواتب المشرفين والمدربين | Y32: =R32*1.02 -> 57305.232 | Z32: =S32*1.02 -> 57305.232 | AA32: =T32*1.02 -> 57305.232 | AB32: =U32*1.02 -> 57305.232 | AC32: =SUM(Y32:AB32) -> 229220.93 | AE32: رواتب المشرفين والمدربين | AF32: =Y32*1.02 -> 58451.337 | AG32: =Z32*1.02 -> 58451.337 | AH32: =AA32*1.02 -> 58451.337 | AI32: =AB32*1.02 -> 58451.337 | AJ32: =SUM(AF32:AI32) -> 233805.35
C33: مصاريف تشغيلية متغيرة | D33: ='الدراسة الفنية '!$I137/4 -> 13666.2 | E33: ='الدراسة الفنية '!$I137/4 -> 13666.2 | F33: ='الدراسة الفنية '!$I137/4 -> 13666.2 | G33: ='الدراسة الفنية '!$I137/4 -> 13666.2 | H33: =SUM(D33:G33) -> 54664.8 | J33: مصاريف تشغيلية متغيرة | K33: =('الدراسة الفنية '!$I137/4)*(1+'الدراسة المالية'!$D5) -> 13939.524 | L33: =('الدراسة الفنية '!$I137/4)*(1+'الدراسة المالية'!$D5) -> 13939.524 | M33: =('الدراسة الفنية '!$I137/4)*(1+'الدراسة المالية'!$D5) -> 13939.524 | N33: =('الدراسة الفنية '!$I137/4)*(1+'الدراسة المالية'!$D5) -> 13939.524 | O33: =SUM(K33:N33) -> 55758.096 | Q33: مصاريف تشغيلية متغيرة | R33: =K33*1.02 -> 14218.314 | S33: =L33*1.02 -> 14218.314 | T33: =M33*1.02 -> 14218.314 | U33: =N33*1.02 -> 14218.314 | V33: =SUM(R33:U33) -> 56873.258 | X33: مصاريف تشغيلية متغيرة | Y33: =R33*1.02 -> 14502.681 | Z33: =S33*1.02 -> 14502.681 | AA33: =T33*1.02 -> 14502.681 | AB33: =U33*1.02 -> 14502.681 | AC33: =SUM(Y33:AB33) -> 58010.723 | AE33: مصاريف تشغيلية متغيرة | AF33: =Y33*1.02 -> 14792.734 | AG33: =Z33*1.02 -> 14792.734 | AH33: =AA33*1.02 -> 14792.734 | AI33: =AB33*1.02 -> 14792.734 | AJ33: =SUM(AF33:AI33) -> 59170.938
C34: إجمالي تكلفة الإيرادات | D34: =SUM(D32:D33) -> 67666.2 | E34: =SUM(E32:E33) -> 67666.2 | F34: =SUM(F32:F33) -> 67666.2 | G34: =SUM(G32:G33) -> 67666.2 | H34: =SUM(H32:H33) -> 270664.8 | J34: إجمالي تكلفة الإيرادات | K34: =SUM(K32:K33) -> 69019.524 | L34: =SUM(L32:L33) -> 69019.524 | M34: =SUM(M32:M33) -> 69019.524 | N34: =SUM(N32:N33) -> 69019.524 | O34: =SUM(O32:O33) -> 276078.1 | Q34: إجمالي تكلفة الإيرادات | R34: =SUM(R32:R33) -> 70399.914 | S34: =SUM(S32:S33) -> 70399.914 | T34: =SUM(T32:T33) -> 70399.914 | U34: =SUM(U32:U33) -> 70399.914 | V34: =SUM(V32:V33) -> 281599.66 | X34: إجمالي تكلفة الإيرادات | Y34: =SUM(Y32:Y33) -> 71807.913 | Z34: =SUM(Z32:Z33) -> 71807.913 | AA34: =SUM(AA32:AA33) -> 71807.913 | AB34: =SUM(AB32:AB33) -> 71807.913 | AC34: =SUM(AC32:AC33) -> 287231.65 | AE34: إجمالي تكلفة الإيرادات | AF34: =SUM(AF32:AF33) -> 73244.071 | AG34: =SUM(AG32:AG33) -> 73244.071 | AH34: =SUM(AH32:AH33) -> 73244.071 | AI34: =SUM(AI32:AI33) -> 73244.071 | AJ34: =SUM(AJ32:AJ33) -> 292976.28
C35: مجمل الربح | D35: =D30-D34 -> 205033.8 | E35: =E30-E34 -> #VALUE! | F35: =F30-F34 -> 182233.8 | G35: =G30-G34 -> 124033.8 | H35: =H30-H34 -> #VALUE! | J35: مجمل الربح | K35: =K30-K34 -> 222769.48 | L35: =L30-L34 -> #VALUE! | M35: =M30-M34 -> 198373.48 | N35: =N30-N34 -> 136099.48 | O35: =O30-O34 -> #VALUE! | Q35: مجمل الربح | R35: =R30-R34 -> 241814.32 | S35: =S30-S34 -> #VALUE! | T35: =T30-T34 -> 215710.6 | U35: =U30-U34 -> 149077.42 | V35: =V30-V34 -> #VALUE! | X35: مجمل الربح | Y35: =Y30-Y34 -> 262261.31 | Z35: =Z30-Z34 -> #VALUE! | AA35: =AA30-AA34 -> 234330.33 | AB35: =AB30-AB34 -> 163032.83 | AC35: =AC30-AC34 -> #VALUE! | AE35: مجمل الربح | AF35: =AF30-AF34 -> 284210 | AG35: =AG30-AG34 -> #VALUE! | AH35: =AH30-AH34 -> 254323.85 | AI35: =AI30-AI34 -> 178035.52 | AJ35: =AJ30-AJ34 -> #VALUE!
C36: يطرح المصاريف الأخرى الثابتة | J36: يطرح المصاريف الأخرى الثابتة | Q36: يطرح المصاريف الأخرى الثابتة | X36: يطرح المصاريف الأخرى الثابتة | AE36: يطرح المصاريف الأخرى الثابتة
C37: رواتب الإداريين | D37: =SUM('الدراسة الفنية '!G6,'الدراسة الفنية '!G10) -> 24000 | E37: =SUM('الدراسة الفنية '!G14,'الدراسة الفنية '!G18) -> 42000 | F37: =SUM('الدراسة الفنية '!G22,'الدراسة الفنية '!G26) -> 24000 | G37: =SUM('الدراسة الفنية '!G30,'الدراسة الفنية '!G34) -> 24000 | H37: =SUM(D37:G37) -> 114000 | J37: رواتب الإداريين | K37: =SUM('الدراسة الفنية '!G6,'الدراسة الفنية '!G10)*(1+'الدراسة المالية'!D5) -> 24480 | L37: =E37*1.02 -> 42840 | M37: =F37*1.02 -> 24480 | N37: =G37*1.02 -> 24480 | O37: =SUM(K37:N37) -> 116280 | Q37: رواتب الإداريين | R37: =K37*1.02 -> 24969.6 | S37: =L37*1.02 -> 43696.8 | T37: =M37*1.02 -> 24969.6 | U37: =N37*1.02 -> 24969.6 | V37: =SUM(R37:U37) -> 118605.6 | X37: رواتب الإداريين | Y37: =R37*1.02 -> 25468.992 | Z37: =S37*1.02 -> 44570.736 | AA37: =T37*1.02 -> 25468.992 | AB37: =U37*1.02 -> 25468.992 | AC37: =SUM(Y37:AB37) -> 120977.71 | AE37: رواتب الإداريين | AF37: =Y37*1.02 -> 25978.372 | AG37: =Z37*1.02 -> 45462.151 | AH37: =AA37*1.02 -> 25978.372 | AI37: =AB37*1.02 -> 25978.372 | AJ37: =SUM(AF37:AI37) -> 123397.27
C38: المصاريف التشغيلية الثابتة | D38: ='الدراسة الفنية '!$J137/4 -> 19075.32 | E38: ='الدراسة الفنية '!$J137/4 -> 19075.32 | F38: ='الدراسة الفنية '!$J137/4 -> 19075.32 | G38: ='الدراسة الفنية '!$J137/4 -> 19075.32 | H38: =SUM(D38:G38) -> 76301.28 | J38: المصاريف التشغيلية الثابتة | K38: =D38*1.02 -> 19456.826 | L38: =E38*1.02 -> 19456.826 | M38: =F38*1.02 -> 19456.826 | N38: =G38*1.02 -> 19456.826 | O38: =SUM(K38:N38) -> 77827.306 | Q38: المصاريف التشغيلية الثابتة | R38: =K38*1.02 -> 19845.963 | S38: =L38*1.02 -> 19845.963 | T38: =M38*1.02 -> 19845.963 | U38: =N38*1.02 -> 19845.963 | V38: =SUM(R38:U38) -> 79383.852 | X38: المصاريف التشغيلية الثابتة | Y38: =R38*1.02 -> 20242.882 | Z38: =S38*1.02 -> 20242.882 | AA38: =T38*1.02 -> 20242.882 | AB38: =U38*1.02 -> 20242.882 | AC38: =SUM(Y38:AB38) -> 80971.529 | AE38: المصاريف التشغيلية الثابتة | AF38: =Y38*1.02 -> 20647.74 | AG38: =Z38*1.02 -> 20647.74 | AH38: =AA38*1.02 -> 20647.74 | AI38: =AB38*1.02 -> 20647.74 | AJ38: =SUM(AF38:AI38) -> 82590.959
C39: مصاريف الاستهلاك | D39: ='الدراسة الفنية '!R95 -> 0 | E39: ='الدراسة الفنية '!R73 -> 0 | F39: ='الدراسة الفنية '!R117 -> 0 | G39: ='الدراسة الفنية '!R152 -> 0 | H39: =SUM(D39:G39) -> 0 | J39: مصاريف الاستهلاك | K39: =D39 -> 0 | L39: =E39 -> 0 | M39: =F39 -> 0 | N39: =G39 -> 0 | O39: =SUM(K39:N39) -> 0 | Q39: مصاريف الاستهلاك | R39: =K39 -> 0 | S39: =L39 -> 0 | T39: =M39 -> 0 | U39: =N39 -> 0 | V39: =SUM(R39:U39) -> 0 | X39: مصاريف الاستهلاك | Y39: =R39 -> 0 | Z39: =S39 -> 0 | AA39: =T39 -> 0 | AB39: =U39 -> 0 | AC39: =SUM(Y39:AB39) -> 0 | AE39: مصاريف الاستهلاك | AF39: =Y39 -> 0 | AG39: =Z39 -> 0 | AH39: =AA39 -> 0 | AI39: =AB39 -> 0 | AJ39: =SUM(AF39:AI39) -> 0
C40: مصاريف الصيانة | D40: ='الدراسة الفنية '!R96 -> 0 | E40: ='الدراسة الفنية '!R74 -> 0 | F40: ='الدراسة الفنية '!R118 -> 0 | G40: ='الدراسة الفنية '!R153 -> 0 | H40: =SUM(D40:G40) -> 0 | J40: مصاريف الصيانة | K40: =D40 -> 0 | L40: =E40 -> 0 | M40: =F40 -> 0 | N40: =G40 -> 0 | O40: =SUM(K40:N40) -> 0 | Q40: مصاريف الصيانة | R40: =K40 -> 0 | S40: =L40 -> 0 | T40: =M40 -> 0 | U40: =N40 -> 0 | V40: =SUM(R40:U40) -> 0 | X40: مصاريف الصيانة | Y40: =R40 -> 0 | Z40: =S40 -> 0 | AA40: =T40 -> 0 | AB40: =U40 -> 0 | AC40: =SUM(Y40:AB40) -> 0 | AE40: مصاريف الصيانة | AF40: =Y40 -> 0 | AG40: =Z40 -> 0 | AH40: =AA40 -> 0 | AI40: =AB40 -> 0 | AJ40: =SUM(AF40:AI40) -> 0
C41: المصاريف القانونية | D41: =(#REF!/2)/4 -> #REF! | E41: =(#REF!/2)/4 -> #REF! | F41: =(#REF!/2)/4 -> #REF! | G41: =(#REF!/2)/4 -> #REF! | H41: =SUM(D41:G41) -> #REF! | J41: المصاريف القانونية | K41: =(#REF!/2)/4 -> #REF! | L41: =(#REF!/2)/4 -> #REF! | M41: =(#REF!/2)/4 -> #REF! | N41: =(#REF!/2)/4 -> #REF! | O41: =SUM(K41:N41) -> #REF! | Q41: مصاريف الايجار | R41: ='الدراسة الفنية '!$H144 -> 54000 | S41: ='الدراسة الفنية '!$H145 -> 19200 | T41: ='الدراسة الفنية '!$H146 -> 25000 | U41: ='الدراسة الفنية '!$H147 -> 34300 | V41: =SUM(R41:U41) -> 132500 | X41: مصاريف الايجار | Y41: ='الدراسة الفنية '!$H144 -> 54000 | Z41: ='الدراسة الفنية '!$H145 -> 19200 | AA41: ='الدراسة الفنية '!$H146 -> 25000 | AB41: ='الدراسة الفنية '!$H147 -> 34300 | AC41: =SUM(Y41:AB41) -> 132500 | AE41: مصاريف الايجار | AF41: =Y41 -> 54000 | AG41: =Z41 -> 19200 | AH41: =AA41 -> 25000 | AI41: =AB41 -> 34300 | AJ41: =SUM(AF41:AI41) -> 132500
C42: مصاريف الحملة التسويقية | D42: =#REF!/2/4 -> #REF! | E42: =#REF!/2/4 -> #REF! | F42: =#REF!/2/4 -> #REF! | G42: =#REF!/2/4 -> #REF! | H42: =SUM(D42:G42) -> #REF! | J42: مصاريف الحملة التسويقية | K42: =#REF!/2/4 -> #REF! | L42: =#REF!/2/4 -> #REF! | M42: =#REF!/2/4 -> #REF! | N42: =#REF!/2/4 -> #REF! | O42: =SUM(K42:N42) -> #REF! | Q42: 0 | V42: =SUM(R42:U42) -> 0 | X42: 0 | AC42: =SUM(Y42:AB42) -> 0 | AE42: 0 | AJ42: =SUM(AF42:AI42) -> 0
C43: إجمالي المصاريف الأخرى الثابتة | D43: =SUM(D37:D42) -> #REF! | E43: =SUM(E37:E42) -> #REF! | F43: =SUM(F37:F42) -> #REF! | G43: =SUM(G37:G42) -> #REF! | H43: =SUM(H37:H42) -> #REF! | J43: إجمالي المصاريف الأخرى الثابتة | K43: =SUM(K37:K42) -> #REF! | L43: =SUM(L37:L42) -> #REF! | M43: =SUM(M37:M42) -> #REF! | N43: =SUM(N37:N42) -> #REF! | O43: =SUM(O37:O42) -> #REF! | Q43: إجمالي المصاريف الأخرى الثابتة | R43: =SUM(R37:R42) -> 98815.563 | S43: =SUM(S37:S42) -> 82742.763 | T43: =SUM(T37:T42) -> 69815.563 | U43: =SUM(U37:U42) -> 79115.563 | V43: =SUM(V37:V42) -> 330489.45 | X43: إجمالي المصاريف الأخرى الثابتة | Y43: =SUM(Y37:Y42) -> 99711.874 | Z43: =SUM(Z37:Z42) -> 84013.618 | AA43: =SUM(AA37:AA42) -> 70711.874 | AB43: =SUM(AB37:AB42) -> 80011.874 | AC43: =SUM(AC37:AC42) -> 334449.24 | AE43: إجمالي المصاريف الأخرى الثابتة | AF43: =SUM(AF37:AF42) -> 100626.11 | AG43: =SUM(AG37:AG42) -> 85309.891 | AH43: =SUM(AH37:AH42) -> 71626.112 | AI43: =SUM(AI37:AI42) -> 80926.112 | AJ43: =SUM(AJ37:AJ42) -> 338488.23
C44: صافي الأرباح قبل الضريبة | D44: =D35-D43 -> #REF! | E44: =E35-E43 -> #VALUE! | F44: =F35-F43 -> #REF! | G44: =G35-G43 -> #REF! | H44: =H35-H43 -> #VALUE! | J44: صافي الأرباح قبل الضريبة | K44: =K35-K43 -> #REF! | L44: =L35-L43 -> #VALUE! | M44: =M35-M43 -> #REF! | N44: =N35-N43 -> #REF! | O44: =O35-O43 -> #VALUE! | Q44: صافي الأرباح قبل الضريبة | R44: =R35-R43 -> 142998.75 | S44: =S35-S43 -> #VALUE! | T44: =T35-T43 -> 145895.03 | U44: =U35-U43 -> 69961.853 | V44: =V35-V43 -> #VALUE! | X44: صافي الأرباح قبل الضريبة | Y44: =Y35-Y43 -> 162549.44 | Z44: =Z35-Z43 -> #VALUE! | AA44: =AA35-AA43 -> 163618.46 | AB44: =AB35-AB43 -> 83020.956 | AC44: =AC35-AC43 -> #VALUE! | AE44: صافي الأرباح قبل الضريبة | AF44: =AF35-AF43 -> 183583.89 | AG44: =AG35-AG43 -> #VALUE! | AH44: =AH35-AH43 -> 182697.74 | AI44: =AI35-AI43 -> 97109.412 | AJ44: =AJ35-AJ43 -> #VALUE!
...

Sheet مؤشرات التقييم المسبح
B2: معدل الخصم | E2: ='الدراسة المالية'!D7 -> 0.05
B4: السنوات | D4: صافي الربح | E4: يضاف الاستهلاك | F4: صافي التدفقات النقدية | H4: القيمة الحالية للتدفقات النقدية
A5: 0 | B5: 0 | F5: =-'الدراسة المالية'!G27 -> #REF! | G5: =F5 -> #REF! | H5: =F5 -> #REF!
A6: 1 | B6: السنة 1 | D6: ='قائمة الدخل التقديرية'!D46 -> #REF! | E6: ='قائمة الدخل التقديرية'!D$39 -> 0 | F6: =E6+D6 -> #REF! | G6: =G5+F6 -> #REF! | H6: =(F6*(1/((1+E$2)^A6))) -> #REF!
A7: 2 | B7: السنة 2 | D7: ='قائمة الدخل التقديرية'!K46 -> #REF! | E7: ='قائمة الدخل التقديرية'!D$39 -> 0 | F7: =E7+D7 -> #REF! | G7: =G6+F7 -> #REF! | H7: =(F7*(1/((1+E$2)^A7))) -> #REF!
A8: 3 | B8: السنة 3 | D8: ='قائمة الدخل التقديرية'!R46 -> 121548.94 | E8: ='قائمة الدخل التقديرية'!D$39 -> 0 | F8: =E8+D8 -> 121548.94 | G8: =G7+F8 -> #REF! | H8: =(F8*(1/((1+E$2)^A8))) -> 104998.54
A9: 4 | B9: السنة 4 | D9: ='قائمة الدخل التقديرية'!Y46 -> 138167.02 | E9: ='قائمة الدخل التقديرية'!D$39 -> 0 | F9: =E9+D9 -> 138167.02 | G9: =G8+F9 -> #REF! | H9: =(F9*(1/((1+E$2)^A9))) -> 113670.35
A10: 5 | B10: السنة 5 | D10: ='قائمة الدخل التقديرية'!AF46 -> 156046.31 | E10: ='قائمة الدخل التقديرية'!D$39 -> 0 | F10: =E10+D10 -> 156046.31 | G10: =G9+F10 -> #REF! | H10: =(F10*(1/((1+E$2)^A10))) -> 122266.36
E11: صافي القيمة الحالية NPV | H11: =H5+NPV(E2,F6:F10) -> #REF!
E12: معدل العائد الداخلي IRR | H12: =IRR(F5:F10) -> #VALUE!
E13: فترة الاسترداد Payback | H13: =LOOKUP(0,G5:G10,(A5:A10)-(G5:G10/(F6:F10))) -> #N/A
D14: فترة الاسترداد
D16: # | E16: التدفقات النقدية الخارجة | F16: التدفقات النقدية الداخلة
D17: 0 | E17: =-F5 -> #REF! | F17: 0
D18: 1 | E18: =E17 -> #REF! | F18: =F6 -> #REF!
D19: 2 | E19: =E18 -> #REF! | F19: =F18+F7 -> #REF!
D20: 3 | E20: =E19 -> #REF! | F20: =F19+F8 -> #REF!
D21: 4 | E21: =E20 -> #REF! | F21: =F20+F9 -> #REF!
D22: 5 | E22: =E21 -> #REF! | F22: =F21+F10 -> #REF!

Sheet مؤشرات التقييم البادل
B2: معدل الخصم | E2: ='الدراسة المالية'!D7 -> 0.05
B4: السنوات | D4: صافي الربح | E4: يضاف الاستهلاك | F4: صافي التدفقات النقدية | H4: القيمة الحالية للتدفقات النقدية
A5: 0 | B5: 0 | F5: =-'الدراسة المالية'!H27 -> #REF! | G5: =F5 -> #REF! | H5: =F5 -> #REF!
A6: 1 | B6: السنة 1 | D6: ='قائمة الدخل التقديرية'!E46 -> #VALUE! | E6: ='قائمة الدخل التقديرية'!E$39 -> 0 | F6: =E6+D6 -> #VALUE! | G6: =G5+F6 -> #REF! | H6: =(F6*(1/((1+E$2)^A6))) -> #VALUE!
A7: 2 | B7: السنة 2 | D7: ='قائمة الدخل التقديرية'!L46 -> #VALUE! | E7: ='قائمة الدخل التقديرية'!E$39 -> 0 | F7: =E7+D7 -> #VALUE! | G7: =G6+F7 -> #REF! | H7: =(F7*(1/((1+E$2)^A7))) -> #VALUE!
A8: 3 | B8: السنة 3 | D8: ='قائمة الدخل التقديرية'!S46 -> #VALUE! | E8: ='قائمة الدخل التقديرية'!E$39 -> 0 | F8: =E8+D8 -> #VALUE! | G8: =G7+F8 -> #REF! | H8: =(F8*(1/((1+E$2)^A8))) -> #VALUE!
A9: 4 | B9: السنة 4 | D9: ='قائمة الدخل التقديرية'!Z46 -> #VALUE! | E9: ='قائمة الدخل التقديرية'!E$39 -> 0 | F9: =E9+D9 -> #VALUE! | G9: =G8+F9 -> #REF! | H9: =(F9*(1/((1+E$2)^A9))) -> #VALUE!
A10: 5 | B10: السنة 5 | D10: ='قائمة الدخل التقديرية'!AG46 -> #VALUE! | E10: ='قائمة الدخل التقديرية'!E$39 -> 0 | F10: =E10+D10 -> #VALUE! | G10: =G9+F10 -> #REF! | H10: =(F10*(1/((1+E$2)^A10))) -> #VALUE!
E11: صافي القيمة الحالية NPV | H11: =H5+NPV(E2,F6:F10) -> #REF!
E12: معدل العائد الداخلي IRR | H12: =IRR(F5:F10) -> #VALUE!
E13: فترة الاسترداد Payback | H13: {=LOOKUP(0,G5:G10,(A5:A10)-(G5:G10/(F6:F10)))} -> #N/A
D14: فترة الاسترداد
D16: # | E16: التدفقات النقدية الخارجة | F16: التدفقات النقدية الداخلة
D17: 0 | E17: =-F5 -> #REF! | F17: 0
D18: 1 | E18: =E17 -> #REF! | F18: =F6 -> #VALUE!
D19: 2 | E19: =E18 -> #REF! | F19: =F18+F7 -> #VALUE!
D20: 3 | E20: =E19 -> #REF! | F20: =F19+F8 -> #VALUE!
D21: 4 | E21: =E20 -> #REF! | F21: =F20+F9 -> #VALUE!
D22: 5 | E22: =E21 -> #REF! | F22: =F21+F10 -> #VALUE!

Sheet مؤشرات التقييم الملعب
B2: معدل الخصم | E2: ='الدراسة المالية'!D7 -> 0.05
B4: السنوات | D4: صافي الربح | E4: يضاف الاستهلاك | F4: صافي التدفقات النقدية | H4: القيمة الحالية للتدفقات النقدية
A5: 0 | B5: 0 | F5: =-'الدراسة المالية'!I27 -> #REF! | G5: =F5 -> #REF! | H5: =F5 -> #REF!
A6: 1 | B6: السنة 1 | D6: ='قائمة الدخل التقديرية'!F46 -> #REF! | E6: ='قائمة الدخل التقديرية'!F$39 -> 0 | F6: =E6+D6 -> #REF! | G6: =G5+F6 -> #REF! | H6: =(F6*(1/((1+E$2)^A6))) -> #REF!
A7: 2 | B7: السنة 2 | D7: ='قائمة الدخل التقديرية'!M46 -> #REF! | E7: ='قائمة الدخل التقديرية'!F$39 -> 0 | F7: =E7+D7 -> #REF! | G7: =G6+F7 -> #REF! | H7: =(F7*(1/((1+E$2)^A7))) -> #REF!
A8: 3 | B8: السنة 3 | D8: ='قائمة الدخل التقديرية'!T46 -> 124010.78 | E8: ='قائمة الدخل التقديرية'!F$39 -> 0 | F8: =E8+D8 -> 124010.78 | G8: =G7+F8 -> #REF! | H8: =(F8*(1/((1+E$2)^A8))) -> 107125.17
A9: 4 | B9: السنة 4 | D9: ='قائمة الدخل التقديرية'!AA46 -> 139075.69 | E9: ='قائمة الدخل التقديرية'!F$39 -> 0 | F9: =E9+D9 -> 139075.69 | G9: =G8+F9 -> #REF! | H9: =(F9*(1/((1+E$2)^A9))) -> 114417.91
A10: 5 | B10: السنة 5 | D10: ='قائمة الدخل التقديرية'!AH46 -> 155293.08 | E10: ='قائمة الدخل التقديرية'!F$39 -> 0 | F10: =E10+D10 -> 155293.08 | G10: =G9+F10 -> #REF! | H10: =(F10*(1/((1+E$2)^A10))) -> 121676.19
E11: صافي القيمة الحالية NPV | H11: =H5+NPV(E2,F6:F10) -> #REF!
E12: معدل العائد الداخلي IRR | H12: =IRR(F5:F10) -> #VALUE!
E13: فترة الاسترداد Payback | H13: =LOOKUP(0,G5:G10,(A5:A10)-(G5:G10/(F6:F10))) -> #N/A
D14: فترة الاسترداد
D16: # | E16: التدفقات النقدية الخارجة | F16: التدفقات النقدية الداخلة
D17: 0 | E17: =-F5 -> #REF! | F17: 0
D18: 1 | E18: =E17 -> #REF! | F18: =F6 -> #REF!
D19: 2 | E19: =E18 -> #REF! | F19: =F18+F7 -> #REF!
D20: 3 | E20: =E19 -> #REF! | F20: =F19+F8 -> #REF!
D21: 4 | E21: =E20 -> #REF! | F21: =F20+F9 -> #REF!
D22: 5 | E22: =E21 -> #REF! | F22: =F21+F10 -> #REF!

Sheet مؤشرات التقييم الصالة الرياضية
B2: معدل الخصم | E2: ='الدراسة المالية'!D7 -> 0.05
B4: السنوات | D4: صافي الربح | E4: يضاف الاستهلاك | F4: صافي التدفقات النقدية | H4: القيمة الحالية للتدفقات النقدية
A5: 0 | B5: 0 | F5: =-'الدراسة المالية'!J27 -> #REF! | G5: =F5 -> #REF! | H5: =F5 -> #REF!
A6: 1 | B6: السنة 1 | D6: ='قائمة الدخل التقديرية'!G46 -> #REF! | E6: ='قائمة الدخل التقديرية'!G$39 -> 0 | F6: =E6+D6 -> #REF! | G6: =G5+F6 -> #REF! | H6: =(F6*(1/((1+E$2)^A6))) -> #REF!
A7: 2 | B7: السنة 2 | D7: ='قائمة الدخل التقديرية'!N46 -> #REF! | E7: ='قائمة الدخل التقديرية'!G$39 -> 0 | F7: =E7+D7 -> #REF! | G7: =G6+F7 -> #REF! | H7: =(F7*(1/((1+E$2)^A7))) -> #REF!
A8: 3 | B8: السنة 3 | D8: ='قائمة الدخل التقديرية'!U46 -> 59467.575 | E8: ='قائمة الدخل التقديرية'!G$39 -> 0 | F8: =E8+D8 -> 59467.575 | G8: =G7+F8 -> #REF! | H8: =(F8*(1/((1+E$2)^A8))) -> 51370.327
A9: 4 | B9: السنة 4 | D9: ='قائمة الدخل التقديرية'!AB46 -> 70567.813 | E9: ='قائمة الدخل التقديرية'!G$39 -> 0 | F9: =E9+D9 -> 70567.813 | G9: =G8+F9 -> #REF! | H9: =(F9*(1/((1+E$2)^A9))) -> 58056.314
A10: 5 | B10: السنة 5 | D10: ='قائمة الدخل التقديرية'!AI46 -> 82543.001 | E10: ='قائمة الدخل التقديرية'!G$39 -> 0 | F10: =E10+D10 -> 82543.001 | G10: =G9+F10 -> #REF! | H10: =(F10*(1/((1+E$2)^A10))) -> 64674.601
E11: صافي القيمة الحالية NPV | H11: =H5+NPV(E2,F6:F10) -> #REF!
E12: معدل العائد الداخلي IRR | H12: =IRR(F5:F10) -> #VALUE!
E13: فترة الاسترداد Payback | H13: =LOOKUP(0,G5:G10,(A5:A10)-(G5:G10/(F6:F10))) -> #N/A
D14: فترة الاسترداد
D16: # | E16: التدفقات النقدية الخارجة | F16: التدفقات النقدية الداخلة
D17: 0 | E17: =-F5 -> #REF! | F17: 0
D18: 1 | E18: =E17 -> #REF! | F18: =F6 -> #REF!
D19: 2 | E19: =E18 -> #REF! | F19: =F18+F7 -> #REF!
D20: 3 | E20: =E19 -> #REF! | F20: =F19+F8 -> #REF!
D21: 4 | E21: =E20 -> #REF! | F21: =F20+F9 -> #REF!
D22: 5 | E22: =E21 -> #REF! | F22: =F21+F10 -> #REF!

Sheet فترة الاسترداد
B3: فترة الاسترداد
B6: # | C6: التدفقات النقدية الخارجة | D6: التدفقات النقدية الداخلة
B7: 0 | C7: ='الدراسة المالية'!G17 -> #REF! | D7: 0
B8: 1 | C8: =C7 -> #REF! | D8: ='مؤشرات تقييم المشروع '!F6 -> #VALUE!
B9: 2 | C9: =C8 -> #REF! | D9: =D8+'مؤشرات تقييم المشروع '!F7 -> #VALUE!
B10: 3 | C10: =C9 -> #REF! | D10: =D9+'مؤشرات تقييم المشروع '!F8 -> #VALUE!
B11: 4 | C11: =C10 -> #REF! | D11: =D10+'مؤشرات تقييم المشروع '!F9 -> #VALUE!
B12: 5 | C12: =C11 -> #REF! | D12: =D11+'مؤشرات تقييم المشروع '!F10 -> #VALUE!

Sheet مؤشرات تقييم المشروع 
B2: معدل الخصم | E2: ='الدراسة المالية'!D7 -> 0.05
B4: السنوات | D4: صافي الربح | E4: يضاف الاستهلاك | F4: صافي التدفقات النقدية | H4: القيمة الحالية للتدفقات النقدية
A5: 0 | B5: 0 | F5: =-'الدراسة المالية'!G17 -> #REF! | G5: =F5 -> #REF! | H5: =F5 -> #REF!
A6: 1 | B6: السنة 1 | D6: ='قائمة الدخل التقديرية'!D23 -> #VALUE! | E6: ='قائمة الدخل التقديرية'!D15 -> 14751613 | F6: =E6+D6 -> #VALUE! | G6: =G5+F6 -> #REF! | H6: =(F6*(1/((1+E$2)^A6))) -> #VALUE!
A7: 2 | B7: السنة 2 | D7: ='قائمة الدخل التقديرية'!E23 -> #VALUE! | E7: ='قائمة الدخل التقديرية'!E15 -> 14751613 | F7: =E7+D7 -> #VALUE! | G7: =G6+F7 -> #REF! | H7: =(F7*(1/((1+E$2)^A7))) -> #VALUE!
A8: 3 | B8: السنة 3 | D8: ='قائمة الدخل التقديرية'!F23 -> #VALUE! | E8: ='قائمة الدخل التقديرية'!F15 -> 14751613 | F8: =E8+D8 -> #VALUE! | G8: =G7+F8 -> #REF! | H8: =(F8*(1/((1+E$2)^A8))) -> #VALUE!
A9: 4 | B9: السنة 4 | D9: ='قائمة الدخل التقديرية'!G23 -> #VALUE! | E9: ='قائمة الدخل التقديرية'!G15 -> 14751613 | F9: =E9+D9 -> #VALUE! | G9: =G8+F9 -> #REF! | H9: =(F9*(1/((1+E$2)^A9))) -> #VALUE!
A10: 5 | B10: السنة 5 | D10: ='قائمة الدخل التقديرية'!H23 -> #VALUE! | E10: ='قائمة الدخل التقديرية'!H15 -> 14751613 | F10: =E10+D10 -> #VALUE! | G10: =G9+F10 -> #REF! | H10: =(F10*(1/((1+E$2)^A10))) -> #VALUE!
E11: صافي القيمة الحالية NPV | H11: =H5+NPV(E2,F6:F10) -> #REF!
E12: معدل العائد الداخلي IRR | H12: =IRR(F5:F10) -> #VALUE!
E13: فترة الاسترداد Payback | H13: =LOOKUP(0,G5:G10,(A5:A10)-(G5:G10/(F6:F10))) -> #N/A

Sheet اسعار الخدمات 
C3: الخدمات المقدمة من ماك بلاش وتوصيفها
B4: # | C4: البند | D4: الوصف | E4: القيمة | F4: لماذا تم اختيار القيمة ؟ | G4: التكلفة | H4: كيف تم احتساب التكلفة ؟ | I4: الربح المتوقع بالريال | J4: الفئة
B5: 1 | C5: البند | D5: الوصف | E5: القيمة (سعر البيع) | F5: لماذا تم اختيار القيمة؟ | G5: التكلفة | H5: كيف تم احتساب التكلفة؟ | I5: الربح المتوقع (ريال) | J5: الأفراد
B6: =1+B5 -> 2 | C6: اشتراكات مميزة (Premium) | D6: مزايا إضافية مثل محتوى حصري وإزالة إعلانات | E6: 30 ريال/شهر | F6: منافس لخدمات عالمية مثل Spotify Gaming | G6: 10 ريال/مستخدم | H6: استضافة + صيانة + دعم فني | I6: 20 ريال/مستخدم
B7: =1+B6 -> 3 | C7: شراء عناصر رقمية | D7: Skins وأدوات وبطاقات داخل الألعاب | E7: 20 – 100 ريال | F7: مشابه لأسعار Fortnite وPUBG | G7: 5 – 20 ريال | H7: رسوم تطوير/ترخيص | I7: 15 – 80 ريال
B8: =1+B7 -> 4 | C8: رسوم بطولات إلكترونية | D8: مشاركة في بطولات بجوائز | E8: 100 ريال/مشارك | F8: سعر متوسط للبطولات المحلية | G8: 40 ريال | H8: تنظيم + جوائز | I8: 60 ريال/مشارك
B9: =1+B8 -> 5 | C9: بطاقات شحن الألعاب | D9: بطاقات بلايستيشن، إكس بوكس، ستيم | E9: 50 – 300 ريال | F9: مطابق لأسعار السوق | G9: 45 – 280 ريال | H9: شراء جملة من الموردين | I9: 5 – 20 ريال
B10: =1+B9 -> 6 | C10: متجر ألعاب رقمي | D10: شراء ألعاب مباشرة عبر المنصة | E10: 100 – 300 ريال | F10: مشابه لـ Steam وEpic | G10: 80 – 250 ريال | H10: تراخيص توزيع الألعاب | I10: 20 – 50 ريال
B11: =1+B10 -> 7 | C11: لعبة الشهر | D11: اشتراك يمنح لعبة كل شهر | E11: 40 ريال/شهر | F11: مثل Xbox Game Pass مصغر | G11: 20 ريال | H11: تراخيص ألعاب | I11: 20 ريال
B12: =1+B11 -> 8 | C12: تأجير حسابات ألعاب | D12: استئجار حسابات لتجربة ألعاب مميزة | E12: 25 ريال/يوم | F12: سعر جذاب للهواة | G12: 10 ريال | H12: صيانة الحساب + تراخيص | I12: 15 ريال
B13: =1+B12 -> 9 | C13: تدريب شخصي (Coaching) | D13: جلسة مع لاعب محترف | E13: 150 ريال/ساعة | F13: سعر قريب من سوق التدريب المحلي | G13: 70 ريال | H13: أتعاب المدرب | I13: 80 ريال
B14: =1+B13 -> 10 | C14: ورش عمل مجتمعية | D14: ورش تعليم صناعة الألعاب أو البث | E14: 200 ريال/ورشة | F14: مقبول كورش قصيرة | G14: 100 ريال | H14: منصة + مدرب | I14: 100 ريال
B15: =1+B14 -> 11 | C15: مسابقات أسبوعية | D15: تحديات بجوائز رمزية | E15: 20 ريال/مشارك | F15: لجذب التفاعل | G15: 10 ريال | H15: جوائز + استضافة | I15: 10 ريال
B16: =1+B15 -> 12 | C16: خدمة إعادة البث (Replay) | D16: حفظ وإعادة لقطات اللعب | E16: 15 ريال/شهر | F16: مشابه لخدمات Twitch Replay | G16: 5 ريال | H16: سيرفر + تخزين | I16: 10 ريال
B17: =1+B16 -> 13 | C17: عضوية عائلية | D17: اشتراك لعدة مستخدمين (Family Pack) | E17: 100 ريال/شهر | F17: مشابه لخدمات Netflix Family | G17: 40 ريال | H17: استضافة + دعم | I17: 60 ريال
... B25: =1+B24 -> 21 | C25: نظام الولاء والنقاط | D25: نقاط تستبدل بمكافآت | E25: 20 ريال/اشتراك | F25: يزيد التفاعل | G25: 5 ريال | H25: تطوير + إدارة | I25: 15 ريال
B26: =1+B25 -> 22 | C26: إدارة الحملات التسويقية | D26: تنظيم حملات المؤثر مع الشركات | E26: 20,000 – 100,000 ريال/حملة | F26: منافس لسوق إدارة المؤثرين | G26: 10,000 – 50,000 ريال | H26: فريق إدارة + إعلانات | I26: 10,000 – 50,000 ريال | J26: للمؤثرين
B27: =1+B26 -> 23 | C27: إنتاج فيديوهات مخصصة | D27: مونتاج فيديوهات ترويجية للبثوص | E27: 5,000 – 15,000 ريال/فيديو | F27: سعر سوقي لإنتاج المحتوى | G27: 3,000 – 7,000 ريال | H27: تصوير + مونتاج | I27: 2,000 – 8,000 ريال
B28: =1+B27 -> 24 | C28: تصميم الهوية البصرية | D28: شعار + بانر + ثيمات للبث | E28: 3,000 – 8,000 ريال | F28: متوافق مع أسعار المصممين | G28: 1,500 – 4,000 ريال | H28: تصميم + مراجعات | I28: 1,500 – 4,000 ريال
B29: =1+B28 -> 25 | C29: استوديو تصوير مؤقت | D29: تأجير استوديو مع معدات | E29: 2,500 – 7,500 ريال/يوم | F29: مثل أسعار استوديوهات جدة/الرياض | G29: 1,000 – 4,000 ريال | H29: تأجير معدات + مساحة | I29: 1,500 – 3,500 ريال
B30: =1+B29 -> 26 | C30: خدمة البث المباشر الاحترافي | D30: إعداد وإدارة بث مباشر | E30: 10,000 – 25,000 ريال/فعالية | F30: مشابه لشركات البث | G30: 5,000 – 12,000 ريال | H30: معدات + تقنيين | I30: 5,000 – 13,000 ريال
B31: =1+B30 -> 27 | C31: إدارة حسابات التواصل | D31: جدولة المحتوى + الردود | E31: 3,000 – 10,000 ريال/شهر | F31: سعر السوق لإدارة الحسابات | G31: 1,500 – 4,000 ريال | H31: مدير حساب + أدوات | I31: 1,500 – 6,000 ريال
B32: =1+B31 -> 28 | C32: تحليلات أداء المحتوى | D32: تقارير أداء وتفاعل الجمهور | E32: 2,000 – 5,000 ريال/تقرير | F32: قيمة عادلة مقابل البيانات | G32: 800 – 2,000 ريال | H32: أدوات تحليل | I32: 1,200 – 3,000 ريال
B33: =1+B32 -> 29 | C33: عقود رعاية وشراكات | D33: صياغة عقود قانونية للمؤثرين | E33: 4,000 – 12,000 ريال/عقد | F33: متوافق مع مكاتب المحاماة | G33: 2,000 – 5,000 ريال | H33: استشارات قانونية | I33: 2,000 – 7,000 ريال
B34: =1+B33 -> 30 | C34: تدريب المؤثرين | D34: ورش تدريب على تحسين البث | E34: 1,500 – 3,000 ريال/ورشة | F34: أسعار دورات تطوير المهارات | G34: 700 – 1,500 ريال | H34: مدرب + منصة | I34: 800 – 1,500 ريال
B35: =1+B34 -> 31 | C35: متجر إلكتروني شخصي | D35: إنشاء متجر لبيع منتجات المؤثر | E35: 8,000 – 20,000 ريال | F35: سعر شبيه بـ Shopify Solutions | G35: 3,000 – 8,000 ريال | H35: تطوير متجر + تصميم | I35: 5,000 – 12,000 ريال
B36: =1+B35 -> 32 | C36: ربط مع شركات رعاية | D36: تقديم المؤثر لشركات مناسبة | E36: 5,000 ريال/صفقة | F36: قيمة بسيطة لتحفيز الرعايات | G36: 1,500 ريال | H36: علاقات + إدارة | I36: 3,500 ريال
B37: =1+B36 -> 33 | C37: خدمة الإنتاج الصوتي | D37: تسجيل وتعليق صوتي احترافي | E37: 1,500 – 4,000 ريال | F37: مطابق لسوق الإنتاج الصوتي | G37: 700 – 1,800 ريال | H37: استوديو + معدات | I37: 800 – 2,200 ريال
B38: =1+B37 -> 34 | C38: إدارة حقوق المحتوى | D38: حماية الفيديوهات من السرقة | E38: 4,000 – 10,000 ريال/شهر | F38: متوافق مع خدمات حماية المحتوى | G38: 2,000 – 4,000 ريال | H38: نظام حماية + متابعة | I38: 2,000 – 6,000 ريال
... B45: =1+B44 -> 41 | C45: On-Demand Merch 2-Hour | D45: متجر مرش سريع بالطباعة عند الطلب خلال ساعتين | E45: 50 – 200 ريال/منتج | F45: منتج فوري يعزز المبيعات | G45: 25 – 80 ريال | H45: طباعة محلية + لوجستيات | I45: 25 – 120 ريال
B46: =1+B45 -> 42 | C46: إعلانات ورعايات داخل المنصة | D46: حجز مساحات إعلانية داخل المنصة أو أثناء البث | E46: 100,000 – 500,000 ريال/حملة | F46: منافس لمنصات مثل Twitch وYouTube Gaming | G46: 50,000 – 150,000 ريال | H46: إنتاج محتوى + إدارة الحملة | I46: 50,000 – 350,000 ريال | J46: لشركات التجارية
B47: =1+B46 -> 43 | C47: رعاية البطولات الإلكترونية | D47: شراكة مع ماك بلاش لرعاية الفعاليات | E47: 150,000 – 600,000 ريال/بطولة | F47: متوافق مع السوق السعودي (Gamers8) | G47: 80,000 – 250,000 ريال | H47: تنظيم البطولة + الجوائز | I47: 70,000 – 350,000 ريال
B48: =1+B47 -> 44 | C48: إنتاج محتوى دعائي للشركات | D48: فيديوهات تسويقية للألعاب أو المنتجات | E48: 30,000 – 80,000 ريال/فيديو | F48: سعر السوق للإنتاج الإعلامي | G48: 15,000 – 40,000 ريال | H48: تصوير + إخراج + مونتاج | I48: 15,000 – 40,000 ريال
B49: =1+B48 -> 45 | C49: منصة إطلاق المنتجات (Product Launch) | D49: بث وإعلان عن منتجات جديدة عبر ماك بلاش | E49: 50,000 – 200,000 ريال | F49: مشابه لسوق الإطلاقات الرقمية | G49: 25,000 – 80,000 ريال | H49: تجهيز منصة + حملات | I49: 25,000 – 120,000 ريال
B50: =1+B49 -> 46 | C50: متجر إلكتروني مخصص | D50: إنشاء متجر للشركات لبيع منتجات ألعاب أو إكسسوارات | E50: 40,000 – 120,000 ريال | F50: أسعار مقاربة لتصميم متاجر Shopify | G50: 20,000 – 50,000 ريال | H50: تطوير + تصميم | I50: 20,000 – 70,000 ريال
B51: =1+B50 -> 47 | C51: استضافة بثوث الشركات | D51: بث فعاليات ومؤتمرات الشركات عبر المنصة | E51: 25,000 – 100,000 ريال/فعالية | F51: أسعار مقاربة لخدمات البث المحترفة | G51: 10,000 – 40,000 ريال | H51: معدات + سيرفرات | I51: 15,000 – 60,000 ريال
B52: =1+B51 -> 48 | C52: تقارير تحليل اللاعبين (Analytics) | D52: تقارير عن سلوك اللاعبين لصالح الشركات | E52: 20,000 – 50,000 ريال/تقرير | F52: قيمة سوقية للبيانات الضخمة | G52: 8,000 – 20,000 ريال | H52: أدوات BI + فريق تحليل | I52: 12,000 – 30,000 ريال
B53: =1+B52 -> 49 | C53: إدارة حملات تسويق رقمية | D53: حملات تسويقية موجهة لجمهور اللاعبين | E53: 30,000 – 150,000 ريال | F53: أسعار مشابهة لشركات التسويق الكبرى | G53: 15,000 – 70,000 ريال | H53: إعلانات ممولة + إدارة | I53: 15,000 – 80,000 ريال
B54: =1+B53 -> 50 | C54: تطوير ألعاب للشركات (Advergames) | D54: ألعاب مصممة خصيصًا للتسويق | E54: 120,000 – 400,000 ريال | F54: أسعار السوق الإقليمي للألعاب التفاعلية | G54: 70,000 – 200,000 ريال | H54: برمجة + تصميم + اختبار | I54: 50,000 – 200,000 ريال
B55: =1+B54 -> 51 | C55: تنظيم فعاليات ألعاب للشركات | D55: فعاليات ترفيهية أو تسويقية عبر الألعاب | E55: 80,000 – 300,000 ريال | F55: متوافق مع السوق السعودي | G55: 40,000 – 120,000 ريال | H55: تنظيم + تجهيز + محتوى | I55: 40,000 – 180,000 ريال
...

Sheet الدراسة المالية
C4: البيان | D4: الافتراض | F4: رأس المال العامل الأولي | G4: عدد الأشهر | H4: التكلفة الشهرية (ريال) | I4: التكلفة السنوية (ريال)
C5: معدل التضخم في الأسعار | D5: 0.02 | F5: المصاريف التشغيلية | G5: 3 | H5: ='الدراسة الفنية '!G137 -> 130966.08 | I5: =H5*G5 -> 392898.24
C6: معدل الضريبة | D6: 0.15 | F6: الرواتب والأجور | G6: 3 | H6: ='الدراسة الفنية '!G38/12 -> 27500 | I6: =H6*G6 -> 82500
C7: معدل الخصم السائد | D7: 0.05 | F7: راس المال العامل الأولي المطلوب | I7: =SUM(I5:I6) -> 475398.24
F10: ملخص التكاليف الرأسمالية | G10: التكلفة ريال | H10: نسبة من الإجمالي | I10: المرجع
F11: التجهيزات والأعمال الأنشائية | G11: ='الدراسة الفنية '!I52 -> 2.9794299e+08 | H11: =G11/G$17 -> #REF! | I11: الدراسة الفنية
F12: الأجهزة والمعدات الرياضية | G12: ='الدراسة الفنية '!I78 -> 0 | H12: =G12/G$17 -> #REF! | I12: الدراسة الفنية
F13: أجهزة الحاسوب والأثاث | G13: ='الدراسة الفنية '!I101 -> 10504 | H13: =G13/G$17 -> #REF! | I13: الدراسة الفنية
F14: مصاريف التأسيس القانونية | G14: =#REF! -> #REF! | H14: =G14/G$17 -> #REF! | I14: الدراسة القانوينة
F15: مصاريف الحملة التسويقية | G15: =#REF! -> #REF! | H15: =G15/G$17 -> #REF! | I15: الدراسة التسويقية
F16: رأس المال العامل الأولي | G16: =I7 -> 475398.24 | H16: =G16/G$17 -> #REF! | I16: الدراسة المالية
F17: إجمالي التكاليف الرأسمالية | G17: =SUM(G11:G16) -> #REF! | H17: =G17/G$17 -> #REF!
F20: ملخص التكاليف الرأسمالية | G20: المسبح | H20: البادل | I20: الملعب المتعدد الأغراض | J20: الصالة الرياضية | K20: الإجمالي
F21: التجهيزات والأعمال الأنشائية | G21: ='الدراسة الفنية '!I46 -> 283091.67 | H21: ='الدراسة الفنية '!I47 -> 79963.333 | I21: ='الدراسة الفنية '!I48 -> 0 | J21: ='الدراسة الفنية '!I49 -> 2.9463e+08 | K21: =SUM(G21:J21) -> 2.9499305e+08
F22: الأجهزة والمعدات الرياضية | G22: =SUM('الدراسة الفنية '!R83:R86)+SUM('الدراسة الفنية '!R91:R92) -> 0 | H22: =SUM('الدراسة الفنية '!R61:R64)*1.01 -> 0 | I22: =SUM('الدراسة الفنية '!R105:R108)*1.01 -> 0 | J22: =SUM('الدراسة الفنية '!R142:R145)*1.01 -> 0 | K22: =SUM(G22:J22) -> 0
F23: أجهزة الحاسوب والأثاث | G23: =SUM('الدراسة الفنية '!R87:R90)*1.01 -> 0 | H23: =SUM('الدراسة الفنية '!R65:R68)*1.01 -> 0 | I23: =SUM('الدراسة الفنية '!R109:R112)*1.01 -> 0 | J23: =SUM('الدراسة الفنية '!R146:R149)*1.01 -> 0 | K23: =SUM(G23:J23) -> 0
F24: مصاريف التأسيس القانونية | G24: =$G14/4 -> #REF! | H24: =$G14/4 -> #REF! | I24: =$G14/4 -> #REF! | J24: =$G14/4 -> #REF! | K24: =SUM(G24:J24) -> #REF!
F25: مصاريف الحملة التسويقية | G25: =$G15/4 -> #REF! | H25: =$G15/4 -> #REF! | I25: =$G15/4 -> #REF! | J25: =$G15/4 -> #REF! | K25: =SUM(G25:J25) -> #REF!
F26: رأس المال العامل الأولي | G26: =$I7/4 -> 118849.56 | H26: =$I7/4 -> 118849.56 | I26: =$I7/4 -> 118849.56 | J26: =$I7/4 -> 118849.56 | K26: =SUM(G26:J26) -> 475398.24
F27: إجمالي التكاليف الرأسمالية | G27: =SUM(G21:G26) -> #REF! | H27: =SUM(H21:H26) -> #REF! | I27: =SUM(I21:I26) -> #REF! | J27: =SUM(J21:J26) -> #REF! | K27: =SUM(K21:K26) -> #REF!

Sheet الدراسة الفنية 
D3: معدل التضخم السنوي | E3: 0.02
C5: # | D5: نوع الوظيفة | E5: العدد | F5: الراتب المتوقع | G5: الإجمالي للسنة 1
C6: المسبح | D6: مدير المسبح و مشرف السباحة | E6: 1 | F6: 2000 | G6: =F6*E6*12 -> 24000
D7: مستقبل العملاء ومحاسب | E7: 1 | F7: 1500 | G7: =F7*E7*12 -> 18000
D8: موظف صيانة ونظافة | E8: 1 | F8: 1500 | G8: =F8*E8*12 -> 18000
D9: موظف مبيعات وتسويق | E9: 1 | F9: 1500 | G9: =F9*E9*12 -> 18000
D12: إجمالي رواتب المسبح | G12: =SUM(G6:G11) -> 78000
C13: # | D13: نوع الوظيفة | E13: العدد | F13: الراتب المتوقع | G13: الإجمالي للسنة 1
C14: البادل | D14: مدير الموقع و مشرف الموقع | E14: 1 | F14: 2000 | G14: =F14*E14*12 -> 24000
D15: مدرب ومشرف الموقع | E15: 1 | F15: 1500 | G15: =F15*E15*12 -> 18000
D16: مستقبل العملاء ومحاسب | E16: 1 | F16: 1500 | G16: =F16*E16*12 -> 18000
D17: موظف صيانة ونظافة | E17: 1 | F17: 1500 | G17: =F17*E17*12 -> 18000
D18: موظف مبيعات وتسويق | E18: 1 | F18: 1500 | G18: =F18*E18*12 -> 18000
D20: إجمالي رواتب البادل | G20: =SUM(G14:G19) -> 96000
C21: # | D21: نوع الوظيفة | E21: العدد | F21: الراتب المتوقع | G21: الإجمالي للسنة 1
C22: ملعب متعدد الأغراض | D22: مدير الملعب ومشرف على الموقع | E22: 1 | F22: 2000 | G22: =F22*E22*12 -> 24000
D23: مستقبل العملاء ومحاسب | E23: 1 | F23: 1500 | G23: =F23*E23*12 -> 18000
D24: موظف مبيعات وتسويق | E24: 1 | F24: 1500 | G24: =F24*E24*12 -> 18000
D25: موظف صيانة ونظافة | E25: 1 | F25: 1500 | G25: =F25*E25*12 -> 18000
D28: إجمالي رواتب الملعب | G28: =SUM(G22:G27) -> 78000
C29: # | D29: نوع الوظيفة | E29: العدد | F29: الراتب المتوقع | G29: الإجمالي للسنة 1
C30: الصالة الرياضية | D30: مدير الصالة الرياضية ومشرف على الموقع | E30: 1 | F30: 2000 | G30: =F30*E30*12 -> 24000
D31: مستقبل العملاء ومحاسب | E31: 1 | F31: 1500 | G31: =F31*E31*12 -> 18000
D32: موظف مبيعات وتسويق | E32: 1 | F32: 1500 | G32: =F32*E32*12 -> 18000
D33: موظف صيانة ونظافة | E33: 1 | F33: 1500 | G33: =F33*E33*12 -> 18000
D36: إجمالي رواتب الصالة الرياضية | G36: =SUM(G30:G35) -> 78000
D38: إجمالي رواتب النادي للسنة الأولى | G38: =SUM(G36,G28,G20,G12) -> 330000
C44: # | D44: البيان | E44: الغرض | F44: المساحة متر/مربع | G44: تكلفة المتر/ريال | H44: % الاستهلاك | I44: إجمالي التكلفة /ريال
C46: 1 | D46: مساحة المسبح | E46: تكلفة التشطيب | F46: 700 | G46: ='دراسة الموارد التقنية '!F61 -> 404.41667 | H46: 0.05 | I46: =G46*F46 -> 283091.67
C47: 2 | D47: مساحة البادل | E47: تكلفة التشطيب | F47: 700 | G47: ='دراسة الموارد التقنية '!F81 -> 114.23333 | H47: 0.05 | I47: =G47*F47 -> 79963.333
C48: 3 | D48: مساحة الملعب متعدد الأغراض | E48: تكلفة التشطيب | F48: 1000 | G48: ='دراسة الموارد التقنية '!F42 -> 0 | H48: 0.05 | I48: =G48*F48 -> 0
C49: 4 | D49: مساحة الصالة الرياضة | E49: تكلفة التشطيب | F49: 300 | G49: ='دراسة الموارد التقنية '!F24 -> 982100 | H49: 0.05 | I49: =G49*F49 -> 2.9463e+08
I50: =G50*F50 -> 0
C51: تكاليف غير منظورة | G51: % | H51: 0.01 | I51: =SUM(I46:I50)*H51 -> 2949930.5
C52: إجمالي تكاليف المباني والإنشاءات | I52: =SUM(I46:I51) -> 2.9794299e+08
C53: إجمالي م استهلاك المباني والإنشاءات | I53: =SUMPRODUCT(H46:H49,I46:I49) -> 14749653
C54: إجمالي الصيانة السنوية المباني والإنشاءات | G54: % | H54: 0.01 | I54: =H54*I52 -> 2979429.9
C58: # | D58: البيان | E58: القسم | F58: العدد | G58: التكلفة/ريال | H58: % الاستهلاك | I58: إجمالي التكلفة /ريال
C60: 1 | D60: مضخة لتدوير المياه | E60: المسبح | F60: 1 | G60: =P83 -> 0 | H60: 0.15 | I60: =G60*F60 -> 0
C61: 2 | D61: الأرضية الصناعية شبكة و أعمدة البادل | E61: البادل | F61: 1 | G61: =P61 -> 0 | H61: 0.15 | I61: =G61*F61 -> 0
...

Sheet تقدير الإيرادات 
D4: الخدمات | F4: اعداد العملاء المتوقع | G4: معدل النمو السنوي | H4: متوسط أسعار الخدمات | I4: السنة 1
D5: المنصة | E5: شهري | F5: 300 | G5: 0.07 | H5: ='اسعار الخدمات'!I183 -> 75.75 | I5: =H5*F5*12 -> 272700
D6: الإعلامي | E6: شهري | F6: 100 | G6: 0.1 | H6: ='اسعار الخدمات'!I5 -> الربح المتوقع (ريال) | I6: =H6*F6*12 -> #VALUE!
D7: الاستديو | E7: شهري | F7: 105 | G7: 0.07 | H7: ='اسعار الخدمات'!I160 -> 198.33333 | I7: =H7*F7*12 -> 249900
D8: أخرى | E8: شهري | F8: 90 | G8: 0.07 | H8: ='اسعار الخدمات'!I172 -> 177.5 | I8: =H8*F8*12 -> 191700
I9: =SUM(I5:I8) -> #VALUE!
D12: الخدمات | F12: السنة 2 | G12: السنة 3 | H12: السنة 4 | I12: السنة 5
D13: المنصة | F13: =I5*(1+G5) -> 291789 | G13: =F13*(1+$G5) -> 312214.23 | H13: =G13*(1+$G5) -> 334069.23 | I13: =H13*(1+$G5) -> 357454.07
D14: الإعلامي | F14: =I6*(1+G6) -> #VALUE! | G14: =F14*(1+$G6) -> #VALUE! | H14: =G14*(1+$G6) -> #VALUE! | I14: =H14*(1+$G6) -> #VALUE!
D15: الاستديو | F15: =I7*(1+G7) -> 267393 | G15: =F15*(1+$G7) -> 286110.51 | H15: =G15*(1+$G7) -> 306138.25 | I15: =H15*(1+$G7) -> 327567.92
D16: أخرى | F16: =I8*(1+G8) -> 205119 | G16: =F16*(1+$G8) -> 219477.33 | H16: =G16*(1+$G8) -> 234840.74 | I16: =H16*(1+$G8) -> 251279.6
F17: =SUM(F13:F16) -> #VALUE! | G17: =SUM(G13:G16) -> #VALUE! | H17: =SUM(H13:H16) -> #VALUE! | I17: =SUM(I13:I16) -> #VALUE!

Sheet اسعار الخدمات
C3: الخدمات المقدمة من ماك بلاش وتوصيفها
B4: # | C4: البند | D4: الوصف | E4: القيمة | F4: لماذا تم اختيار القيمة ؟ | G4: التكلفة | H4: كيف تم احتساب التكلفة ؟ | I4: الربح المتوقع بالريال | J4: الفئة
C5: البند | D5: الوصف | E5: القيمة (سعر البيع) | F5: لماذا تم اختيار القيمة؟ | G5: التكلفة | H5: كيف تم احتساب التكلفة؟ | I5: الربح المتوقع (ريال) | J5: الأفراد
C6: اشتراكات مميزة (Premium) | D6: مزايا إضافية مثل محتوى حصري وإزالة إعلانات | E6: 30 ريال/شهر | F6: منافس لخدمات عالمية مثل Spotify Gaming | G6: 10 ريال/مستخدم | H6: استضافة + صيانة + دعم فني | I6: 20 ريال/مستخدم
C7: شراء عناصر رقمية | D7: Skins وأدوات وبطاقات داخل الألعاب | E7: 20 – 100 ريال | F7: مشابه لأسعار Fortnite وPUBG | G7: 5 – 20 ريال | H7: رسوم تطوير/ترخيص | I7: 15 – 80 ريال
C8: رسوم بطولات إلكترونية | D8: مشاركة في بطولات بجوائز | E8: 100 ريال/مشارك | F8: سعر متوسط للبطولات المحلية | G8: 40 ريال | H8: تنظيم + جوائز | I8: 60 ريال/مشارك
C9: بطاقات شحن الألعاب | D9: بطاقات بلايستيشن، إكس بوكس، ستيم | E9: 50 – 300 ريال | F9: مطابق لأسعار السوق | G9: 45 – 280 ريال | H9: شراء جملة من الموردين | I9: 5 – 20 ريال
C10: متجر ألعاب رقمي | D10: شراء ألعاب مباشرة عبر المنصة | E10: 100 – 300 ريال | F10: مشابه لـ Steam وEpic | G10: 80 – 250 ريال | H10: تراخيص توزيع الألعاب | I10: 20 – 50 ريال
C11: لعبة الشهر | D11: اشتراك يمنح لعبة كل شهر | E11: 40 ريال/شهر | F11: مثل Xbox Game Pass مصغر | G11: 20 ريال | H11: تراخيص ألعاب | I11: 20 ريال
C12: تأجير حسابات ألعاب | D12: استئجار حسابات لتجربة ألعاب مميزة | E12: 25 ريال/يوم | F12: سعر جذاب للهواة | G12: 10 ريال | H12: صيانة الحساب + تراخيص | I12: 15 ريال
C13: تدريب شخصي (Coaching) | D13: جلسة مع لاعب محترف | E13: 150 ريال/ساعة | F13: سعر قريب من سوق التدريب المحلي | G13: 70 ريال | H13: أتعاب المدرب | I13: 80 ريال
C14: ورش عمل مجتمعية | D14: ورش تعليم صناعة الألعاب أو البث | E14: 200 ريال/ورشة | F14: مقبول كورش قصيرة | G14: 100 ريال | H14: منصة + مدرب | I14: 100 ريال
C15: مسابقات أسبوعية | D15: تحديات بجوائز رمزية | E15: 20 ريال/مشارك | F15: لجذب التفاعل | G15: 10 ريال | H15: جوائز + استضافة | I15: 10 ريال
C16: خدمة إعادة البث (Replay) | D16: حفظ وإعادة لقطات اللعب | E16: 15 ريال/شهر | F16: مشابه لخدمات Twitch Replay | G16: 5 ريال | H16: سيرفر + تخزين | I16: 10 ريال
C17: عضوية عائلية | D17: اشتراك لعدة مستخدمين (Family Pack) | E17: 100 ريال/شهر | F17: مشابه لخدمات Netflix Family | G17: 40 ريال | H17: استضافة + دعم | I17: 60 ريال
... C25: نظام الولاء والنقاط | D25: نقاط تستبدل بمكافآت | E25: 20 ريال/اشتراك | F25: يزيد التفاعل | G25: 5 ريال | H25: تطوير + إدارة | I25: 15 ريال
C26: إدارة الحملات التسويقية | D26: تنظيم حملات المؤثر مع الشركات | E26: 20,000 – 100,000 ريال/حملة | F26: منافس لسوق إدارة المؤثرين | G26: 10,000 – 50,000 ريال | H26: فريق إدارة + إعلانات | I26: 10,000 – 50,000 ريال | J26: للمؤثرين
C27: إنتاج فيديوهات مخصصة | D27: مونتاج فيديوهات ترويجية للبثوص | E27: 5,000 – 15,000 ريال/فيديو | F27: سعر سوقي لإنتاج المحتوى | G27: 3,000 – 7,000 ريال | H27: تصوير + مونتاج | I27: 2,000 – 8,000 ريال
C28: تصميم الهوية البصرية | D28: شعار + بانر + ثيمات للبث | E28: 3,000 – 8,000 ريال | F28: متوافق مع أسعار المصممين | G28: 1,500 – 4,000 ريال | H28: تصميم + مراجعات | I28: 1,500 – 4,000 ريال
C29: استوديو تصوير مؤقت | D29: تأجير استوديو مع معدات | E29: 2,500 – 7,500 ريال/يوم | F29: مثل أسعار استوديوهات جدة/الرياض | G29: 1,000 – 4,000 ريال | H29: تأجير معدات + مساحة | I29: 1,500 – 3,500 ريال
C30: خدمة البث المباشر الاحترافي | D30: إعداد وإدارة بث مباشر | E30: 10,000 – 25,000 ريال/فعالية | F30: مشابه لشركات البث | G30: 5,000 – 12,000 ريال | H30: معدات + تقنيين | I30: 5,000 – 13,000 ريال
C31: إدارة حسابات التواصل | D31: جدولة المحتوى + الردود | E31: 3,000 – 10,000 ريال/شهر | F31: سعر السوق لإدارة الحسابات | G31: 1,500 – 4,000 ريال | H31: مدير حساب + أدوات | I31: 1,500 – 6,000 ريال
C32: تحليلات أداء المحتوى | D32: تقارير أداء وتفاعل الجمهور | E32: 2,000 – 5,000 ريال/تقرير | F32: قيمة عادلة مقابل البيانات | G32: 800 – 2,000 ريال | H32: أدوات تحليل | I32: 1,200 – 3,000 ريال
C33: عقود رعاية وشراكات | D33: صياغة عقود قانونية للمؤثرين | E33: 4,000 – 12,000 ريال/عقد | F33: متوافق مع مكاتب المحاماة | G33: 2,000 – 5,000 ريال | H33: استشارات قانونية | I33: 2,000 – 7,000 ريال
C34: تدريب المؤثرين | D34: ورش تدريب على تحسين البث | E34: 1,500 – 3,000 ريال/ورشة | F34: أسعار دورات تطوير المهارات | G34: 700 – 1,500 ريال | H34: مدرب + منصة | I34: 800 – 1,500 ريال
C35: متجر إلكتروني شخصي | D35: إنشاء متجر لبيع منتجات المؤثر | E35: 8,000 – 20,000 ريال | F35: سعر شبيه بـ Shopify Solutions | G35: 3,000 – 8,000 ريال | H35: تطوير متجر + تصميم | I35: 5,000 – 12,000 ريال
C36: ربط مع شركات رعاية | D36: تقديم المؤثر لشركات مناسبة | E36: 5,000 ريال/صفقة | F36: قيمة بسيطة لتحفيز الرعايات | G36: 1,500 ريال | H36: علاقات + إدارة | I36: 3,500 ريال
C37: خدمة الإنتاج الصوتي | D37: تسجيل وتعليق صوتي احترافي | E37: 1,500 – 4,000 ريال | F37: مطابق لسوق الإنتاج الصوتي | G37: 700 – 1,800 ريال | H37: استوديو + معدات | I37: 800 – 2,200 ريال
C38: إدارة حقوق المحتوى | D38: حماية الفيديوهات من السرقة | E38: 4,000 – 10,000 ريال/شهر | F38: متوافق مع خدمات حماية المحتوى | G38: 2,000 – 4,000 ريال | H38: نظام حماية + متابعة | I38: 2,000 – 6,000 ريال
... C45: On-Demand Merch 2-Hour | D45: متجر مرش سريع بالطباعة عند الطلب خلال ساعتين | E45: 50 – 200 ريال/منتج | F45: منتج فوري يعزز المبيعات | G45: 25 – 80 ريال | H45: طباعة محلية + لوجستيات | I45: 25 – 120 ريال
C46: إعلانات ورعايات داخل المنصة | D46: حجز مساحات إعلانية داخل المنصة أو أثناء البث | E46: 100,000 – 500,000 ريال/حملة | F46: منافس لمنصات مثل Twitch وYouTube Gaming | G46: 50,000 – 150,000 ريال | H46: إنتاج محتوى + إدارة الحملة | I46: 50,000 – 350,000 ريال | J46: لشركات التجارية
C47: رعاية البطولات الإلكترونية | D47: شراكة مع ماك بلاش لرعاية الفعاليات | E47: 150,000 – 600,000 ريال/بطولة | F47: متوافق مع السوق السعودي (Gamers8) | G47: 80,000 – 250,000 ريال | H47: تنظيم البطولة + الجوائز | I47: 70,000 – 350,000 ريال
C48: إنتاج محتوى دعائي للشركات | D48: فيديوهات تسويقية للألعاب أو المنتجات | E48: 30,000 – 80,000 ريال/فيديو | F48: سعر السوق للإنتاج الإعلامي | G48: 15,000 – 40,000 ريال | H48: تصوير + إخراج + مونتاج | I48: 15,000 – 40,000 ريال
C49: منصة إطلاق المنتجات (Product Launch) | D49: بث وإعلان عن منتجات جديدة عبر ماك بلاش | E49: 50,000 – 200,000 ريال | F49: مشابه لسوق الإطلاقات الرقمية | G49: 25,000 – 80,000 ريال | H49: تجهيز منصة + حملات | I49: 25,000 – 120,000 ريال
C50: متجر إلكتروني مخصص | D50: إنشاء متجر للشركات لبيع منتجات ألعاب أو إكسسوارات | E50: 40,000 – 120,000 ريال | F50: أسعار مقاربة لتصميم متاجر Shopify | G50: 20,000 – 50,000 ريال | H50: تطوير + تصميم | I50: 20,000 – 70,000 ريال
C51: استضافة بثوث الشركات | D51: بث فعاليات ومؤتمرات الشركات عبر المنصة | E51: 25,000 – 100,000 ريال/فعالية | F51: أسعار مقاربة لخدمات البث المحترفة | G51: 10,000 – 40,000 ريال | H51: معدات + سيرفرات | I51: 15,000 – 60,000 ريال
C52: تقارير تحليل اللاعبين (Analytics) | D52: تقارير عن سلوك اللاعبين لصالح الشركات | E52: 20,000 – 50,000 ريال/تقرير | F52: قيمة سوقية للبيانات الضخمة | G52: 8,000 – 20,000 ريال | H52: أدوات BI + فريق تحليل | I52: 12,000 – 30,000 ريال
C53: إدارة حملات تسويق رقمية | D53: حملات تسويقية موجهة لجمهور اللاعبين | E53: 30,000 – 150,000 ريال | F53: أسعار مشابهة لشركات التسويق الكبرى | G53: 15,000 – 70,000 ريال | H53: إعلانات ممولة + إدارة | I53: 15,000 – 80,000 ريال
C54: تطوير ألعاب للشركات (Advergames) | D54: ألعاب مصممة خصيصًا للتسويق | E54: 120,000 – 400,000 ريال | F54: أسعار السوق الإقليمي للألعاب التفاعلية | G54: 70,000 – 200,000 ريال | H54: برمجة + تصميم + اختبار | I54: 50,000 – 200,000 ريال
C55: تنظيم فعاليات ألعاب للشركات | D55: فعاليات ترفيهية أو تسويقية عبر الألعاب | E55: 80,000 – 300,000 ريال | F55: متوافق مع السوق السعودي | G55: 40,000 – 120,000 ريال | H55: تنظيم + تجهيز + محتوى | I55: 40,000 – 180,000 ريال
...

Sheet الدراسة القانونية 
C3: التشطيب
B4: # | C4: البند | D4: الكمية | E4: السعر | F4: الإجمالي | G4: الملاحضات
B5: المنصة | C5: أتعاب استشارات قانونية سنوية | D5: 12 | E5: 6000 | F5: =E5*D5 -> 72000 | G5: تشمل خدمات مكتب محاماة متخصص لتغطية صياغة عقود الرعايات، الشراكات، عقود الاستثمار، حماية الملكية الفكرية، مراجعة عقود المؤثرين، وتقديم استشارات قانونية دورية.
C6: رسوم تراخيص إعلامية (معلن/إعلامي) | D6: 3 | E6: 3000 | F6: =E6*D6 -> 9000 | G6: استخراج التراخيص الإعلامية والإعلانية من وزارة الإعلام والجهات المختصة لضمان استمرار النشاط وحمايته من الإيقاف.
C7: مصاريف استخراج سجل تجاري | D7: 1 | E7: 2000 | F7: =E7*D7 -> 2000 | G7: تسجيل الشركة بشكل رسمي في وزارة التجارة مع إمكانية توقيع العقود والتعاملات الرسمية مع الجهات الحكومية والخاصة.
C8: تسجيل العلامة التجارية | D8: 1 | E8: 10000 | F8: =E8*D8 -> 10000 | G8: تسجيل وحماية اسم وهوية مشروع ماك بلاش لدى الهيئة السعودية للملكية الفكرية ضد التقليد أو السرقة.
C9: اعداد اللوائح والإجراءات وأفضل الممارسات والمعايير | D9: 1 | E9: 20000 | F9: =E9*D9 -> 20000 | G9: إعداد لوائح داخلية تحدد الحقوق والواجبات، صياغة إجراءات تشغيلية يومية، وضع أفضل الممارسات (Best Practices) وضبط المعايير المحلية والعالمية لضمان الجودة والامتثال.
C10: رسوم التسجيل في الغرفة التجارية | D10: 1 | E10: 5000 | F10: =E10*D10 -> 5000 | G10: اشتراك سنوي إلزامي لجميع الشركات السعودية يتيح الدخول في المناقصات والتعاملات الرسمية.
C11: سياسة حماية البيانات والخصوصية (GDPR/PDPL) | D11: 1 | E11: 15000 | F11: =E11*D11 -> 15000 | G11: صياغة وتنفيذ سياسات حماية البيانات بما يتوافق مع نظام حماية البيانات الشخصية السعودي (PDPL) ومعايير GDPR الدولية.
C12: عقود عمل الموظفين واللائحة الداخلية | D12: 1 | E12: 10000 | F12: =E12*D12 -> 10000 | G12: صياغة عقود عمل قانونية لجميع الموظفين، إعداد لائحة تنظيم العمل معتمدة من وزارة الموارد البشرية، وتسجيل الشركة في البرامج الحكومية (مدد – اعتماد).
C13: إجراءات الامتثال الضريبي (ZATCA) | D13: 4 | E13: 500 | F13: =E13*D13 -> 2000 | G13: تسجيل ضريبة القيمة المضافة (VAT).وإعداد نظام للفوترة الإلكترونية وفق متطلبات هيئة الزكاة.
C14: إجمالي التكاليف الإنشائية | F14: =SUM(F5:F13) -> 145000
C15: إجمالي تكاليف المتر الواحد | F15: =F14/300 -> 483.33333
C16: تكاليف غير مذكورة 15% | F16: =F15*1.15 -> 555.83333
C18: التشطيب | F18: =SUM(F14:F17) -> 146039.17
B19: # | C19: الموارد | D19: العدد | E19: القيمة | F19: الإجمالي
C32: إجمالي التكاليف الإنشائية | F32: =SUM(F20:F31) -> 0
C33: إجمالي تكاليف المتر الواحد | F33: =F32/300 -> 0
C34: تكاليف غير مذكورة 15% | F34: =F33*1.15 -> 0
C37: التشطيب
B38: # | C38: الموارد | D38: العدد | E38: القيمة | F38: الإجمالي
C51: إجمالي التكاليف الإنشائية | F51: =SUM(F39:F50) -> 0
C52: إجمالي تكاليف المتر الواحد | F52: =F51/300 -> 0
C53: تكاليف غير مذكورة 15% | F53: =F52*1.15 -> 0
C57: التشطيب
B58: # | C58: الموارد | D58: العدد | E58: القيمة | F58: الإجمالي
D59: 1 | E59: 300 | F59: =E59*D59 -> 300
D60: 1 | E60: 1000 | F60: =E60*D60 -> 1000
D61: 6 | E61: 1000 | F61: =E61*D61 -> 6000
D62: 1 | E62: 3000 | F62: =E62*D62 -> 3000
D63: 50 | E63: 40 | F63: =E63*D63 -> 2000
D64: 100 | E64: 50 | F64: =E64*D64 -> 5000
D65: 1 | E65: 1500 | F65: =E65*D65 -> 1500
D66: 200 | E66: 15 | F66: =E66*D66 -> 3000
D67: 1 | E67: 2000 | F67: =E67*D67 -> 2000
D68: 150 | E68: 40 | F68: =E68*D68 -> 6000
C71: إجمالي التكاليف الإنشائية | F71: =SUM(F59:F70) -> 29800
C72: إجمالي تكاليف المتر الواحد | F72: =F71/300 -> 99.333333
C73: تكاليف غير مذكورة 15% | F73: =F72*1.15 -> 114.23333

Sheet دراسة الموارد البشرية 
C3: الرواتب المتوقعة بعد الاستقرار | H3: الرواتب المتوقعة في بداية العمل
B4: # | C4: المنصب | D4: العدد | E4: الشهور | F4: الراتب الشهري | G4: الإجمالي | H4: الراتب الشهري | I4: الإجمالي
B5: المنصة | C5: مدير العمليات والتشغيل | D5: 1 | E5: 12 | F5: 15000 | G5: =F5*E5*D5 -> 180000 | H5: =F5/3 -> 5000 | I5: =H5*E5*D5 -> 60000
C6: مدير الإعلام والعلاقات | D6: 1 | E6: 12 | F6: 12000 | G6: =F6*E6*D6 -> 144000 | H6: =F6/3 -> 4000 | I6: =H6*E6*D6 -> 48000
