Workbook

Sheet HOME
A1: HOME

Sheet القيود
B3: تحليل المرتبات .... لشهر فبراير 2019
D4: المدين | F4: الدائن
C5: الأسم | D5: الراتب | E5: مصروف التأمينات | F5: المستحق للموظف | G5: استحقاق التأمينات | H5: استحقاق الضرائب | I5: السلف | J5: الجزاءات
B6: 1 | C6: ='PAYRROLL- الشرائح'!$B6 -> موظف 1 | D6: ='PAYRROLL- الشرائح'!M6 -> 5677 | E6: ='PAYRROLL- الشرائح'!P6 -> 182 | F6: ='PAYRROLL- الشرائح'!AD6 -> 5677 | G6: =('PAYRROLL- الشرائح'!P6+'PAYRROLL- الشرائح'!T6) -> 182 | H6: ='PAYRROLL- الشرائح'!Z6 -> 0 | I6: ='PAYRROLL- الشرائح'!F6 -> 0 | J6: ='PAYRROLL- الشرائح'!G6 -> 0 | X6: التامينات دروسوس | Y6: مرتبات دروسوس
B7: 2 | C7: ='PAYRROLL- الشرائح'!$B7 -> موظف 2 | D7: ='PAYRROLL- الشرائح'!M7 -> 4280 | E7: ='PAYRROLL- الشرائح'!P7 -> 162.5 | F7: ='PAYRROLL- الشرائح'!AD7 -> 4280 | G7: =('PAYRROLL- الشرائح'!P7+'PAYRROLL- الشرائح'!T7) -> 162.5 | H7: ='PAYRROLL- الشرائح'!Z7 -> 0 | I7: ='PAYRROLL- الشرائح'!F7 -> 0 | J7: ='PAYRROLL- الشرائح'!G7 -> 0 | AD7: 127.5 | AE7: 4500
B8: 3 | C8: ='PAYRROLL- الشرائح'!$B8 -> موظف 3 | D8: ='PAYRROLL- الشرائح'!M8 -> 4280 | E8: ='PAYRROLL- الشرائح'!P8 -> 162.5 | F8: ='PAYRROLL- الشرائح'!AD8 -> 4280 | G8: =('PAYRROLL- الشرائح'!P8+'PAYRROLL- الشرائح'!T8) -> 162.5 | H8: ='PAYRROLL- الشرائح'!Z8 -> 0 | I8: ='PAYRROLL- الشرائح'!F8 -> 0 | J8: ='PAYRROLL- الشرائح'!G8 -> 0 | X8: 127.5 | Y8: 4500 | AD8: 654 | AE8: 12038.09
B9: 4 | C9: ='PAYRROLL- الشرائح'!$B9 -> 0 | D9: ='PAYRROLL- الشرائح'!M9 -> 0 | E9: ='PAYRROLL- الشرائح'!P9 -> 0 | F9: ='PAYRROLL- الشرائح'!AD9 -> 0 | G9: =('PAYRROLL- الشرائح'!P9+'PAYRROLL- الشرائح'!T9) -> 0 | H9: ='PAYRROLL- الشرائح'!Z9 -> 0 | I9: ='PAYRROLL- الشرائح'!F9 -> 0 | J9: ='PAYRROLL- الشرائح'!G9 -> 0 | X9: 654 | Y9: 12038.09 | AD9: 358.82 | AE9: 3500
B10: 5 | C10: ='PAYRROLL- الشرائح'!$B10 -> 0 | D10: ='PAYRROLL- الشرائح'!M10 -> 0 | E10: ='PAYRROLL- الشرائح'!P10 -> 0 | F10: ='PAYRROLL- الشرائح'!AD10 -> 0 | G10: =('PAYRROLL- الشرائح'!P10+'PAYRROLL- الشرائح'!T10) -> 0 | H10: ='PAYRROLL- الشرائح'!Z10 -> 0 | I10: ='PAYRROLL- الشرائح'!F10 -> 0 | J10: ='PAYRROLL- الشرائح'!G10 -> 0 | X10: 357 | Y10: 3493 | AD10: 512.6 | AE10: 4200
B11: 6 | C11: ='PAYRROLL- الشرائح'!$B11 -> 0 | D11: ='PAYRROLL- الشرائح'!M11 -> 0 | E11: ='PAYRROLL- الشرائح'!P11 -> 0 | F11: ='PAYRROLL- الشرائح'!AD11 -> 0 | G11: =('PAYRROLL- الشرائح'!P11+'PAYRROLL- الشرائح'!T11) -> 0 | H11: ='PAYRROLL- الشرائح'!Z11 -> 0 | I11: ='PAYRROLL- الشرائح'!F11 -> 0 | J11: ='PAYRROLL- الشرائح'!G11 -> 0 | X11: 510 | Y11: 4190.67 | AD11: 512.6 | AE11: 3663.56
B12: 7 | C12: ='PAYRROLL- الشرائح'!$B12 -> 0 | D12: ='PAYRROLL- الشرائح'!M12 -> 0 | E12: ='PAYRROLL- الشرائح'!P12 -> 0 | F12: ='PAYRROLL- الشرائح'!AD12 -> 0 | G12: =('PAYRROLL- الشرائح'!P12+'PAYRROLL- الشرائح'!T12) -> 0 | H12: ='PAYRROLL- الشرائح'!Z12 -> 0 | I12: ='PAYRROLL- الشرائح'!F12 -> 0 | J12: ='PAYRROLL- الشرائح'!G12 -> 0 | X12: 510 | Y12: 3656.56 | AE12: 0
B13: 8 | C13: ='PAYRROLL- الشرائح'!$B13 -> 0 | D13: ='PAYRROLL- الشرائح'!M13 -> 0 | E13: ='PAYRROLL- الشرائح'!P13 -> 0 | F13: ='PAYRROLL- الشرائح'!AD13 -> 0 | G13: =('PAYRROLL- الشرائح'!P13+'PAYRROLL- الشرائح'!T13) -> 0 | H13: ='PAYRROLL- الشرائح'!Z13 -> 0 | I13: ='PAYRROLL- الشرائح'!F13 -> 0 | J13: ='PAYRROLL- الشرائح'!G13 -> 0
B14: 9 | C14: ='PAYRROLL- الشرائح'!$B14 -> 0 | D14: ='PAYRROLL- الشرائح'!M14 -> 0 | E14: ='PAYRROLL- الشرائح'!P14 -> 0 | F14: ='PAYRROLL- الشرائح'!AD14 -> 0 | G14: =('PAYRROLL- الشرائح'!P14+'PAYRROLL- الشرائح'!T14) -> 0 | H14: ='PAYRROLL- الشرائح'!Z14 -> 0 | I14: ='PAYRROLL- الشرائح'!F14 -> 0 | J14: ='PAYRROLL- الشرائح'!G14 -> 0
B15: 10 | C15: ='PAYRROLL- الشرائح'!$B15 -> 0 | D15: ='PAYRROLL- الشرائح'!M15 -> 0 | E15: ='PAYRROLL- الشرائح'!P15 -> 0 | F15: ='PAYRROLL- الشرائح'!AD15 -> 0 | G15: =('PAYRROLL- الشرائح'!P15+'PAYRROLL- الشرائح'!T15) -> 0 | H15: ='PAYRROLL- الشرائح'!Z15 -> 0 | I15: ='PAYRROLL- الشرائح'!F15 -> 0 | J15: ='PAYRROLL- الشرائح'!G15 -> 0
B16: 11 | C16: ='PAYRROLL- الشرائح'!$B16 -> 0 | D16: ='PAYRROLL- الشرائح'!M16 -> 0 | E16: ='PAYRROLL- الشرائح'!P16 -> 0 | F16: ='PAYRROLL- الشرائح'!AD16 -> 0 | G16: =('PAYRROLL- الشرائح'!P16+'PAYRROLL- الشرائح'!T16) -> 0 | H16: ='PAYRROLL- الشرائح'!Z16 -> 0 | I16: ='PAYRROLL- الشرائح'!F16 -> 0 | J16: ='PAYRROLL- الشرائح'!G16 -> 0
B17: 12 | C17: ='PAYRROLL- الشرائح'!$B17 -> 0 | D17: ='PAYRROLL- الشرائح'!M17 -> 0 | E17: ='PAYRROLL- الشرائح'!P17 -> 0 | F17: ='PAYRROLL- الشرائح'!AD17 -> 0 | G17: =('PAYRROLL- الشرائح'!P17+'PAYRROLL- الشرائح'!T17) -> 0 | H17: ='PAYRROLL- الشرائح'!Z17 -> 0 | I17: ='PAYRROLL- الشرائح'!F17 -> 0 | J17: ='PAYRROLL- الشرائح'!G17 -> 0
B18: 13 | C18: ='PAYRROLL- الشرائح'!$B18 -> 0 | D18: ='PAYRROLL- الشرائح'!M18 -> 0 | E18: ='PAYRROLL- الشرائح'!P18 -> 0 | F18: ='PAYRROLL- الشرائح'!AD18 -> 0 | G18: =('PAYRROLL- الشرائح'!P18+'PAYRROLL- الشرائح'!T18) -> 0 | H18: ='PAYRROLL- الشرائح'!Z18 -> 0 | I18: ='PAYRROLL- الشرائح'!F18 -> 0 | J18: ='PAYRROLL- الشرائح'!G18 -> 0
B19: 14 | C19: ='PAYRROLL- الشرائح'!$B19 -> 0 | D19: ='PAYRROLL- الشرائح'!M19 -> 0 | E19: ='PAYRROLL- الشرائح'!P19 -> 0 | F19: ='PAYRROLL- الشرائح'!AD19 -> 0 | G19: =('PAYRROLL- الشرائح'!P19+'PAYRROLL- الشرائح'!T19) -> 0 | H19: ='PAYRROLL- الشرائح'!Z19 -> 0 | I19: ='PAYRROLL- الشرائح'!F19 -> 0 | J19: ='PAYRROLL- الشرائح'!G19 -> 0
B20: 15 | C20: ='PAYRROLL- الشرائح'!$B20 -> 0 | D20: ='PAYRROLL- الشرائح'!M20 -> 0 | E20: ='PAYRROLL- الشرائح'!P20 -> 0 | F20: ='PAYRROLL- الشرائح'!AD20 -> 0 | G20: =('PAYRROLL- الشرائح'!P20+'PAYRROLL- الشرائح'!T20) -> 0 | H20: ='PAYRROLL- الشرائح'!Z20 -> 0 | I20: ='PAYRROLL- الشرائح'!F20 -> 0 | J20: ='PAYRROLL- الشرائح'!G20 -> 0
B21: 16 | C21: ='PAYRROLL- الشرائح'!$B21 -> 0 | D21: ='PAYRROLL- الشرائح'!M21 -> 0 | E21: ='PAYRROLL- الشرائح'!P21 -> 0 | F21: ='PAYRROLL- الشرائح'!AD21 -> 0 | G21: =('PAYRROLL- الشرائح'!P21+'PAYRROLL- الشرائح'!T21) -> 0 | H21: ='PAYRROLL- الشرائح'!Z21 -> 0 | I21: ='PAYRROLL- الشرائح'!F21 -> 0 | J21: ='PAYRROLL- الشرائح'!G21 -> 0
B22: 17 | C22: ='PAYRROLL- الشرائح'!$B22 -> 0 | D22: ='PAYRROLL- الشرائح'!M22 -> 0 | E22: ='PAYRROLL- الشرائح'!P22 -> 0 | F22: ='PAYRROLL- الشرائح'!AD22 -> 0 | G22: =('PAYRROLL- الشرائح'!P22+'PAYRROLL- الشرائح'!T22) -> 0 | H22: ='PAYRROLL- الشرائح'!Z22 -> 0 | I22: ='PAYRROLL- الشرائح'!F22 -> 0 | J22: ='PAYRROLL- الشرائح'!G22 -> 0
B23: 18 | C23: ='PAYRROLL- الشرائح'!$B23 -> 0 | D23: ='PAYRROLL- الشرائح'!M23 -> 0 | E23: ='PAYRROLL- الشرائح'!P23 -> 0 | F23: ='PAYRROLL- الشرائح'!AD23 -> 0 | G23: =('PAYRROLL- الشرائح'!P23+'PAYRROLL- الشرائح'!T23) -> 0 | H23: ='PAYRROLL- الشرائح'!Z23 -> 0 | I23: ='PAYRROLL- الشرائح'!F23 -> 0 | J23: ='PAYRROLL- الشرائح'!G23 -> 0
B24: 19 | C24: ='PAYRROLL- الشرائح'!$B24 -> 0 | D24: ='PAYRROLL- الشرائح'!M24 -> 0 | E24: ='PAYRROLL- الشرائح'!P24 -> 0 | F24: ='PAYRROLL- الشرائح'!AD24 -> 0 | G24: =('PAYRROLL- الشرائح'!P24+'PAYRROLL- الشرائح'!T24) -> 0 | H24: ='PAYRROLL- الشرائح'!Z24 -> 0 | I24: ='PAYRROLL- الشرائح'!F24 -> 0 | J24: ='PAYRROLL- الشرائح'!G24 -> 0
... B39: 34 | C39: ='PAYRROLL- الشرائح'!$B39 -> 0 | D39: ='PAYRROLL- الشرائح'!M39 -> 0 | E39: ='PAYRROLL- الشرائح'!P39 -> 0 | F39: ='PAYRROLL- الشرائح'!AD39 -> 0 | G39: =('PAYRROLL- الشرائح'!P39+'PAYRROLL- الشرائح'!T39) -> 0 | H39: ='PAYRROLL- الشرائح'!Z39 -> 0 | I39: ='PAYRROLL- الشرائح'!F39 -> 0 | J39: ='PAYRROLL- الشرائح'!G39 -> 0
B40: 35 | C40: ='PAYRROLL- الشرائح'!$B40 -> 0 | D40: ='PAYRROLL- الشرائح'!M40 -> 0 | E40: ='PAYRROLL- الشرائح'!P40 -> 0 | F40: ='PAYRROLL- الشرائح'!AD40 -> 0 | G40: =('PAYRROLL- الشرائح'!P40+'PAYRROLL- الشرائح'!T40) -> 0 | H40: ='PAYRROLL- الشرائح'!Z40 -> 0 | I40: ='PAYRROLL- الشرائح'!F40 -> 0 | J40: ='PAYRROLL- الشرائح'!G40 -> 0 | AE40: 0
B41: 36 | C41: ='PAYRROLL- الشرائح'!$B41 -> 0 | D41: ='PAYRROLL- الشرائح'!M41 -> 0 | E41: ='PAYRROLL- الشرائح'!P41 -> 0 | F41: ='PAYRROLL- الشرائح'!AD41 -> 0 | G41: =('PAYRROLL- الشرائح'!P41+'PAYRROLL- الشرائح'!T41) -> 0 | H41: ='PAYRROLL- الشرائح'!Z41 -> 0 | I41: ='PAYRROLL- الشرائح'!F41 -> 0 | J41: ='PAYRROLL- الشرائح'!G41 -> 0
B42: 37 | C42: ='PAYRROLL- الشرائح'!$B42 -> 0 | D42: ='PAYRROLL- الشرائح'!M42 -> 0 | E42: ='PAYRROLL- الشرائح'!P42 -> 0 | F42: ='PAYRROLL- الشرائح'!AD42 -> 0 | G42: =('PAYRROLL- الشرائح'!P42+'PAYRROLL- الشرائح'!T42) -> 0 | H42: ='PAYRROLL- الشرائح'!Z42 -> 0 | I42: ='PAYRROLL- الشرائح'!F42 -> 0 | J42: ='PAYRROLL- الشرائح'!G42 -> 0
B43: 38 | C43: ='PAYRROLL- الشرائح'!$B43 -> 0 | D43: ='PAYRROLL- الشرائح'!M43 -> 0 | E43: ='PAYRROLL- الشرائح'!P43 -> 0 | F43: ='PAYRROLL- الشرائح'!AD43 -> 0 | G43: =('PAYRROLL- الشرائح'!P43+'PAYRROLL- الشرائح'!T43) -> 0 | H43: ='PAYRROLL- الشرائح'!Z43 -> 0 | I43: ='PAYRROLL- الشرائح'!F43 -> 0 | J43: ='PAYRROLL- الشرائح'!G43 -> 0
B44: 39 | C44: ='PAYRROLL- الشرائح'!$B44 -> 0 | D44: ='PAYRROLL- الشرائح'!M44 -> 0 | E44: ='PAYRROLL- الشرائح'!P44 -> 0 | F44: ='PAYRROLL- الشرائح'!AD44 -> 0 | G44: =('PAYRROLL- الشرائح'!P44+'PAYRROLL- الشرائح'!T44) -> 0 | H44: ='PAYRROLL- الشرائح'!Z44 -> 0 | I44: ='PAYRROLL- الشرائح'!F44 -> 0 | J44: ='PAYRROLL- الشرائح'!G44 -> 0
B45: 40 | C45: ='PAYRROLL- الشرائح'!$B45 -> 0 | D45: ='PAYRROLL- الشرائح'!M45 -> 0 | E45: ='PAYRROLL- الشرائح'!P45 -> 0 | F45: ='PAYRROLL- الشرائح'!AD45 -> 0 | G45: =('PAYRROLL- الشرائح'!P45+'PAYRROLL- الشرائح'!T45) -> 0 | H45: ='PAYRROLL- الشرائح'!Z45 -> 0 | I45: ='PAYRROLL- الشرائح'!F45 -> 0 | J45: ='PAYRROLL- الشرائح'!G45 -> 0
B46: 41 | C46: ='PAYRROLL- الشرائح'!$B46 -> 0 | D46: ='PAYRROLL- الشرائح'!M46 -> 0 | E46: ='PAYRROLL- الشرائح'!P46 -> 0 | F46: ='PAYRROLL- الشرائح'!AD46 -> 0 | G46: =('PAYRROLL- الشرائح'!P46+'PAYRROLL- الشرائح'!T46) -> 0 | H46: ='PAYRROLL- الشرائح'!Z46 -> 0 | I46: ='PAYRROLL- الشرائح'!F46 -> 0 | J46: ='PAYRROLL- الشرائح'!G46 -> 0
B47: 42 | C47: ='PAYRROLL- الشرائح'!$B47 -> 0 | D47: ='PAYRROLL- الشرائح'!M47 -> 0 | E47: ='PAYRROLL- الشرائح'!P47 -> 0 | F47: ='PAYRROLL- الشرائح'!AD47 -> 0 | G47: =('PAYRROLL- الشرائح'!P47+'PAYRROLL- الشرائح'!T47) -> 0 | H47: ='PAYRROLL- الشرائح'!Z47 -> 0 | I47: ='PAYRROLL- الشرائح'!F47 -> 0 | J47: ='PAYRROLL- الشرائح'!G47 -> 0
B48: 43 | C48: ='PAYRROLL- الشرائح'!$B48 -> 0 | D48: ='PAYRROLL- الشرائح'!M48 -> 0 | E48: ='PAYRROLL- الشرائح'!P48 -> 0 | F48: ='PAYRROLL- الشرائح'!AD48 -> 0 | G48: =('PAYRROLL- الشرائح'!P48+'PAYRROLL- الشرائح'!T48) -> 0 | H48: ='PAYRROLL- الشرائح'!Z48 -> 0 | I48: ='PAYRROLL- الشرائح'!F48 -> 0 | J48: ='PAYRROLL- الشرائح'!G48 -> 0
B49: 44 | C49: ='PAYRROLL- الشرائح'!$B49 -> 0 | D49: ='PAYRROLL- الشرائح'!M49 -> 0 | E49: ='PAYRROLL- الشرائح'!P49 -> 0 | F49: ='PAYRROLL- الشرائح'!AD49 -> 0 | G49: =('PAYRROLL- الشرائح'!P49+'PAYRROLL- الشرائح'!T49) -> 0 | H49: ='PAYRROLL- الشرائح'!Z49 -> 0 | I49: ='PAYRROLL- الشرائح'!F49 -> 0 | J49: ='PAYRROLL- الشرائح'!G49 -> 0
B50: 45 | C50: ='PAYRROLL- الشرائح'!$B50 -> 0 | D50: ='PAYRROLL- الشرائح'!M50 -> 0 | E50: ='PAYRROLL- الشرائح'!P50 -> 0 | F50: ='PAYRROLL- الشرائح'!AD50 -> 0 | G50: =('PAYRROLL- الشرائح'!P50+'PAYRROLL- الشرائح'!T50) -> 0 | H50: ='PAYRROLL- الشرائح'!Z50 -> 0 | I50: ='PAYRROLL- الشرائح'!F50 -> 0 | J50: ='PAYRROLL- الشرائح'!G50 -> 0
B51: 46 | C51: ='PAYRROLL- الشرائح'!$B51 -> 0 | D51: ='PAYRROLL- الشرائح'!M51 -> 0 | E51: ='PAYRROLL- الشرائح'!P51 -> 0 | F51: ='PAYRROLL- الشرائح'!AD51 -> 0 | G51: =('PAYRROLL- الشرائح'!P51+'PAYRROLL- الشرائح'!T51) -> 0 | H51: ='PAYRROLL- الشرائح'!Z51 -> 0 | I51: ='PAYRROLL- الشرائح'!F51 -> 0 | J51: ='PAYRROLL- الشرائح'!G51 -> 0
B52: 47 | C52: ='PAYRROLL- الشرائح'!$B52 -> 0 | D52: ='PAYRROLL- الشرائح'!M52 -> 0 | E52: ='PAYRROLL- الشرائح'!P52 -> 0 | F52: ='PAYRROLL- الشرائح'!AD52 -> 0 | G52: =('PAYRROLL- الشرائح'!P52+'PAYRROLL- الشرائح'!T52) -> 0 | H52: ='PAYRROLL- الشرائح'!Z52 -> 0 | I52: ='PAYRROLL- الشرائح'!F52 -> 0 | J52: ='PAYRROLL- الشرائح'!G52 -> 0
B53: 48 | C53: ='PAYRROLL- الشرائح'!$B53 -> 0 | D53: ='PAYRROLL- الشرائح'!M53 -> 0 | E53: ='PAYRROLL- الشرائح'!P53 -> 0 | F53: ='PAYRROLL- الشرائح'!AD53 -> 0 | G53: =('PAYRROLL- الشرائح'!P53+'PAYRROLL- الشرائح'!T53) -> 0 | H53: ='PAYRROLL- الشرائح'!Z53 -> 0 | I53: ='PAYRROLL- الشرائح'!F53 -> 0 | J53: ='PAYRROLL- الشرائح'!G53 -> 0
B54: 49 | C54: ='PAYRROLL- الشرائح'!$B54 -> 0 | D54: ='PAYRROLL- الشرائح'!M54 -> 0 | E54: ='PAYRROLL- الشرائح'!P54 -> 0 | F54: ='PAYRROLL- الشرائح'!AD54 -> 0 | G54: =('PAYRROLL- الشرائح'!P54+'PAYRROLL- الشرائح'!T54) -> 0 | H54: ='PAYRROLL- الشرائح'!Z54 -> 0 | I54: ='PAYRROLL- الشرائح'!F54 -> 0 | J54: ='PAYRROLL- الشرائح'!G54 -> 0 | AE54: 0
B55: 50 | C55: ='PAYRROLL- الشرائح'!$B55 -> 0 | D55: ='PAYRROLL- الشرائح'!M55 -> 0 | E55: ='PAYRROLL- الشرائح'!P55 -> 0 | F55: ='PAYRROLL- الشرائح'!AD55 -> 0 | G55: =('PAYRROLL- الشرائح'!P55+'PAYRROLL- الشرائح'!T55) -> 0 | H55: ='PAYRROLL- الشرائح'!Z55 -> 0 | I55: ='PAYRROLL- الشرائح'!F55 -> 0 | J55: ='PAYRROLL- الشرائح'!G55 -> 0 | AE55: 0
B56: إجمالي الشرائح | D56: =SUM(D6:D55) -> 14237 | E56: =SUM(E6:E55) -> 507 | F56: =SUM(F6:F55) -> 14237 | G56: =SUM(G6:G55) -> 507 | H56: =SUM(H6:H55) -> 0 | I56: =SUM(I6:I55) -> 0 | J56: =SUM(J6:J55) -> 0 | AE56: 0
...

Sheet PAYRROLL- الشرائح
J2: كشف حساب مرتبات العاملين - 2019
AA3: =Z9*0.3 -> 0
A4: كود | B4: اسم الموظف | C4: الرقم التأميني | D4: الوظيفة | E4: عدد أيام العمل الشهرية | F4: الأستقطاعات | H4: الراتب الشهري | M4: المستحق خلال الشهر | N4: حصة الشركة بالتأمينات | Q4: أجمالي ما تتحملة الشركة | R4: التامينات - حصة العامل | U4: صافي الوعاء | V4: يحول لسنوي وخصم كسر 10ج | W4: الأعفاءات | X4: وعاء الضريبه السنوي | Y4: ضريبة كسب العمل السنوية | Z4: الضريبة الشهرية المستحقة | AA4: الشريحه التى يقع فيها الموظف | AB4: نسبة الخصم | AC4: أجمالي المستقطع | AD4: صافي الراتب
F5: السلف | G5: جزاءات | H5: أضافي (خارج مبلغ التأمين) مبلغ بأجمالي الشهر | I5: بدلات (خارج مبلغ التامين) | J5: أساسي | K5: متغير | L5: الأجمالي | N5: أساسي | O5: متغير | P5: أجمالي التامينات | T5: الأجمالي
A6: 1 | B6: موظف 1 | C6: 123 | D6: مدير | E6: 30 | I6: 4977 | J6: 700 | L6: =K6+J6+I6+H6 -> 5677 | M6: =ROUND((((K6+J6+I6)/30)*E6)+H6,2) -> 5677 | N6: =J6*0.26 -> 182 | O6: =K6*0.24 -> 0 | P6: =N6+O6 -> 182 | Q6: =M6 -> 5677 | T6: =R6+S6 -> 0 | U6: =ROUND(M6-T6,2) -> 5677 | V6: =(U6*12)-MOD((U6*12),10) -> 68120 | X6: =IF(V6-W6<=0,0,V6-W6) -> 68120 | Z6: =IFERROR(Y6/12,0) -> 0 | AA6: =IF(AND(X6=0,M6>0),"الأولى",IF(AND(V6>0,(V6-7000)<=22000),"الثانية",IF(AND((V6-7000)>22000,(V6-7000)<=37000),"الثالثة",IF(AND(V6>37000,(V6-7000)<=192000),"الرابعة",IF(AND((V6-7000)>192000),"الخامسة",0))))) -> الرابعة | AB6: =IF(AA6="الثانية",85%,IF(AA6="الثالثة",45%,IF(AA6="الرابعة",7.5%,IF(AA6="الخامسة",0%,IF(AA6="الأولى",0%,""))))) -> 0.075 | AC6: =SUM(Z6,T6,G6,F6) -> 0 | AD6: =M6-AC6 -> 5677 | AM6: =Z6*0.75 -> 0 | AN6: =Z6*0.25 -> 0
A7: 2 | B7: موظف 2 | C7: 456 | D7: مشرف مواقع | E7: 30 | I7: 3655 | J7: 625 | L7: =K7+J7+I7+H7 -> 4280 | M7: =ROUND((((K7+J7+I7)/30)*E7)+H7,2) -> 4280 | N7: =J7*0.26 -> 162.5 | O7: =K7*0.24 -> 0 | P7: =N7+O7 -> 162.5 | Q7: =M7 -> 4280 | T7: =R7+S7 -> 0 | U7: =ROUND(M7-T7,2) -> 4280 | V7: =(U7*12)-MOD((U7*12),10) -> 51360 | X7: =IF(V7-W7<=0,0,V7-W7) -> 51360 | Z7: =IFERROR(Y7/12,0) -> 0 | AA7: =IF(AND(X7=0,M7>0),"الأولى",IF(AND(V7>0,(V7-7000)<=22000),"الثانية",IF(AND((V7-7000)>22000,(V7-7000)<=37000),"الثالثة",IF(AND(V7>37000,(V7-7000)<=192000),"الرابعة",IF(AND((V7-7000)>192000),"الخامسة",0))))) -> الرابعة | AB7: =IF(AA7="الثانية",85%,IF(AA7="الثالثة",45%,IF(AA7="الرابعة",7.5%,IF(AA7="الخامسة",0%,IF(AA7="الأولى",0%,""))))) -> 0.075 | AC7: =SUM(Z7,T7,G7,F7) -> 0 | AD7: =M7-AC7 -> 4280 | AN7: =Z7 -> 0
A8: 3 | B8: موظف 3 | C8: 789 | D8: أمين صندوق | E8: 30 | I8: 3655 | J8: 625 | L8: =K8+J8+I8+H8 -> 4280 | M8: =ROUND((((K8+J8+I8)/30)*E8)+H8,2) -> 4280 | N8: =J8*0.26 -> 162.5 | O8: =K8*0.24 -> 0 | P8: =N8+O8 -> 162.5 | Q8: =M8 -> 4280 | T8: =R8+S8 -> 0 | U8: =ROUND(M8-T8,2) -> 4280 | V8: =(U8*12)-MOD((U8*12),10) -> 51360 | X8: =IF(V8-W8<=0,0,V8-W8) -> 51360 | Z8: =IFERROR(Y8/12,0) -> 0 | AA8: =IF(AND(X8=0,M8>0),"الأولى",IF(AND(V8>0,(V8-7000)<=22000),"الثانية",IF(AND((V8-7000)>22000,(V8-7000)<=37000),"الثالثة",IF(AND(V8>37000,(V8-7000)<=192000),"الرابعة",IF(AND((V8-7000)>192000),"الخامسة",0))))) -> الرابعة | AB8: =IF(AA8="الثانية",85%,IF(AA8="الثالثة",45%,IF(AA8="الرابعة",7.5%,IF(AA8="الخامسة",0%,IF(AA8="الأولى",0%,""))))) -> 0.075 | AC8: =SUM(Z8,T8,G8,F8) -> 0 | AD8: =M8-AC8 -> 4280 | AM8: =Z8*0.3 -> 0 | AN8: =Z8*0.7 -> 0
A9: 4 | L9: =K9+J9+I9+H9 -> 0 | M9: =ROUND((((K9+J9+I9)/30)*E9)+H9,2) -> 0 | N9: =J9*0.26 -> 0 | O9: =K9*0.24 -> 0 | P9: =N9+O9 -> 0 | Q9: =M9 -> 0 | T9: =R9+S9 -> 0 | U9: =ROUND(M9-T9,2) -> 0 | V9: =(U9*12)-MOD((U9*12),10) -> 0 | X9: =IF(V9-W9<=0,0,V9-W9) -> 0 | Z9: =IFERROR(Y9/12,0) -> 0 | AA9: =IF(AND(X9=0,M9>0),"الأولى",IF(AND(V9>0,(V9-7000)<=22000),"الثانية",IF(AND((V9-7000)>22000,(V9-7000)<=37000),"الثالثة",IF(AND(V9>37000,(V9-7000)<=192000),"الرابعة",IF(AND((V9-7000)>192000),"الخامسة",0))))) -> 0 | AB9: =IF(AA9="الثانية",85%,IF(AA9="الثالثة",45%,IF(AA9="الرابعة",7.5%,IF(AA9="الخامسة",0%,IF(AA9="الأولى",0%,""))))) | AC9: =SUM(Z9,T9,G9,F9) -> 0 | AD9: =M9-AC9 -> 0 | AN9: =Z9 -> 0
A10: 5 | L10: =K10+J10+I10+H10 -> 0 | M10: =ROUND((((K10+J10+I10)/30)*E10)+H10,2) -> 0 | N10: =J10*0.26 -> 0 | O10: =K10*0.24 -> 0 | P10: =N10+O10 -> 0 | Q10: =M10 -> 0 | T10: =R10+S10 -> 0 | U10: =ROUND(M10-T10,2) -> 0 | V10: =(U10*12)-MOD((U10*12),10) -> 0 | X10: =IF(V10-W10<=0,0,V10-W10) -> 0 | Z10: =IFERROR(Y10/12,0) -> 0 | AA10: =IF(AND(X10=0,M10>0),"الأولى",IF(AND(V10>0,(V10-7000)<=22000),"الثانية",IF(AND((V10-7000)>22000,(V10-7000)<=37000),"الثالثة",IF(AND(V10>37000,(V10-7000)<=192000),"الرابعة",IF(AND((V10-7000)>192000),"الخامسة",0))))) -> 0 | AB10: =IF(AA10="الثانية",85%,IF(AA10="الثالثة",45%,IF(AA10="الرابعة",7.5%,IF(AA10="الخامسة",0%,IF(AA10="الأولى",0%,""))))) | AC10: =SUM(Z10,T10,G10,F10) -> 0 | AD10: =M10-AC10 -> 0 | AN10: =Z10 -> 0
A11: 6 | L11: =K11+J11+I11+H11 -> 0 | M11: =ROUND((((K11+J11+I11)/30)*E11)+H11,2) -> 0 | N11: =J11*0.26 -> 0 | O11: =K11*0.24 -> 0 | P11: =N11+O11 -> 0 | Q11: =M11 -> 0 | T11: =R11+S11 -> 0 | U11: =ROUND(M11-T11,2) -> 0 | V11: =(U11*12)-MOD((U11*12),10) -> 0 | X11: =IF(V11-W11<=0,0,V11-W11) -> 0 | Z11: =IFERROR(Y11/12,0) -> 0 | AA11: =IF(AND(X11=0,M11>0),"الأولى",IF(AND(V11>0,(V11-7000)<=22000),"الثانية",IF(AND((V11-7000)>22000,(V11-7000)<=37000),"الثالثة",IF(AND(V11>37000,(V11-7000)<=192000),"الرابعة",IF(AND((V11-7000)>192000),"الخامسة",0))))) -> 0 | AB11: =IF(AA11="الثانية",85%,IF(AA11="الثالثة",45%,IF(AA11="الرابعة",7.5%,IF(AA11="الخامسة",0%,IF(AA11="الأولى",0%,""))))) | AC11: =SUM(Z11,T11,G11,F11) -> 0 | AD11: =M11-AC11 -> 0
A12: 7 | L12: =K12+J12+I12+H12 -> 0 | M12: =ROUND((((K12+J12+I12)/30)*E12)+H12,2) -> 0 | N12: =J12*0.26 -> 0 | O12: =K12*0.24 -> 0 | P12: =N12+O12 -> 0 | Q12: =M12 -> 0 | T12: =R12+S12 -> 0 | U12: =ROUND(M12-T12,2) -> 0 | V12: =(U12*12)-MOD((U12*12),10) -> 0 | X12: =IF(V12-W12<=0,0,V12-W12) -> 0 | Z12: =IFERROR(Y12/12,0) -> 0 | AA12: =IF(AND(X12=0,M12>0),"الأولى",IF(AND(V12>0,(V12-7000)<=22000),"الثانية",IF(AND((V12-7000)>22000,(V12-7000)<=37000),"الثالثة",IF(AND(V12>37000,(V12-7000)<=192000),"الرابعة",IF(AND((V12-7000)>192000),"الخامسة",0))))) -> 0 | AB12: =IF(AA12="الثانية",85%,IF(AA12="الثالثة",45%,IF(AA12="الرابعة",7.5%,IF(AA12="الخامسة",0%,IF(AA12="الأولى",0%,""))))) | AC12: =SUM(Z12,T12,G12,F12) -> 0 | AD12: =M12-AC12 -> 0
A13: 8 | L13: =K13+J13+I13+H13 -> 0 | M13: =ROUND((((K13+J13+I13)/30)*E13)+H13,2) -> 0 | N13: =J13*0.26 -> 0 | O13: =K13*0.24 -> 0 | P13: =N13+O13 -> 0 | Q13: =M13 -> 0 | T13: =R13+S13 -> 0 | U13: =ROUND(M13-T13,2) -> 0 | V13: =(U13*12)-MOD((U13*12),10) -> 0 | X13: =IF(V13-W13<=0,0,V13-W13) -> 0 | Z13: =IFERROR(Y13/12,0) -> 0 | AA13: =IF(AND(X13=0,M13>0),"الأولى",IF(AND(V13>0,(V13-7000)<=22000),"الثانية",IF(AND((V13-7000)>22000,(V13-7000)<=37000),"الثالثة",IF(AND(V13>37000,(V13-7000)<=192000),"الرابعة",IF(AND((V13-7000)>192000),"الخامسة",0))))) -> 0 | AB13: =IF(AA13="الثانية",85%,IF(AA13="الثالثة",45%,IF(AA13="الرابعة",7.5%,IF(AA13="الخامسة",0%,IF(AA13="الأولى",0%,""))))) | AC13: =SUM(Z13,T13,G13,F13) -> 0 | AD13: =M13-AC13 -> 0
A14: 9 | L14: =K14+J14+I14+H14 -> 0 | M14: =ROUND((((K14+J14+I14)/30)*E14)+H14,2) -> 0 | N14: =J14*0.26 -> 0 | O14: =K14*0.24 -> 0 | P14: =N14+O14 -> 0 | Q14: =M14 -> 0 | T14: =R14+S14 -> 0 | U14: =ROUND(M14-T14,2) -> 0 | V14: =(U14*12)-MOD((U14*12),10) -> 0 | X14: =IF(V14-W14<=0,0,V14-W14) -> 0 | Z14: =IFERROR(Y14/12,0) -> 0 | AA14: =IF(AND(X14=0,M14>0),"الأولى",IF(AND(V14>0,(V14-7000)<=22000),"الثانية",IF(AND((V14-7000)>22000,(V14-7000)<=37000),"الثالثة",IF(AND(V14>37000,(V14-7000)<=192000),"الرابعة",IF(AND((V14-7000)>192000),"الخامسة",0))))) -> 0 | AB14: =IF(AA14="الثانية",85%,IF(AA14="الثالثة",45%,IF(AA14="الرابعة",7.5%,IF(AA14="الخامسة",0%,IF(AA14="الأولى",0%,""))))) | AC14: =SUM(Z14,T14,G14,F14) -> 0 | AD14: =M14-AC14 -> 0
A15: 10 | L15: =K15+J15+I15+H15 -> 0 | M15: =ROUND((((K15+J15+I15)/30)*E15)+H15,2) -> 0 | N15: =J15*0.26 -> 0 | O15: =K15*0.24 -> 0 | P15: =N15+O15 -> 0 | Q15: =M15 -> 0 | T15: =R15+S15 -> 0 | U15: =ROUND(M15-T15,2) -> 0 | V15: =(U15*12)-MOD((U15*12),10) -> 0 | X15: =IF(V15-W15<=0,0,V15-W15) -> 0 | Z15: =IFERROR(Y15/12,0) -> 0 | AA15: =IF(AND(X15=0,M15>0),"الأولى",IF(AND(V15>0,(V15-7000)<=22000),"الثانية",IF(AND((V15-7000)>22000,(V15-7000)<=37000),"الثالثة",IF(AND(V15>37000,(V15-7000)<=192000),"الرابعة",IF(AND((V15-7000)>192000),"الخامسة",0))))) -> 0 | AB15: =IF(AA15="الثانية",85%,IF(AA15="الثالثة",45%,IF(AA15="الرابعة",7.5%,IF(AA15="الخامسة",0%,IF(AA15="الأولى",0%,""))))) | AC15: =SUM(Z15,T15,G15,F15) -> 0 | AD15: =M15-AC15 -> 0
A16: 11 | L16: =K16+J16+I16+H16 -> 0 | M16: =ROUND((((K16+J16+I16)/30)*E16)+H16,2) -> 0 | N16: =J16*0.26 -> 0 | O16: =K16*0.24 -> 0 | P16: =N16+O16 -> 0 | Q16: =M16 -> 0 | T16: =R16+S16 -> 0 | U16: =ROUND(M16-T16,2) -> 0 | V16: =(U16*12)-MOD((U16*12),10) -> 0 | X16: =IF(V16-W16<=0,0,V16-W16) -> 0 | Z16: =IFERROR(Y16/12,0) -> 0 | AA16: =IF(AND(X16=0,M16>0),"الأولى",IF(AND(V16>0,(V16-7000)<=22000),"الثانية",IF(AND((V16-7000)>22000,(V16-7000)<=37000),"الثالثة",IF(AND(V16>37000,(V16-7000)<=192000),"الرابعة",IF(AND((V16-7000)>192000),"الخامسة",0))))) -> 0 | AB16: =IF(AA16="الثانية",85%,IF(AA16="الثالثة",45%,IF(AA16="الرابعة",7.5%,IF(AA16="الخامسة",0%,IF(AA16="الأولى",0%,""))))) | AC16: =SUM(Z16,T16,G16,F16) -> 0 | AD16: =M16-AC16 -> 0
A17: 12 | L17: =K17+J17+I17+H17 -> 0 | M17: =ROUND((((K17+J17+I17)/30)*E17)+H17,2) -> 0 | N17: =J17*0.26 -> 0 | O17: =K17*0.24 -> 0 | P17: =N17+O17 -> 0 | Q17: =M17 -> 0 | T17: =R17+S17 -> 0 | U17: =ROUND(M17-T17,2) -> 0 | V17: =(U17*12)-MOD((U17*12),10) -> 0 | X17: =IF(V17-W17<=0,0,V17-W17) -> 0 | Z17: =IFERROR(Y17/12,0) -> 0 | AA17: =IF(AND(X17=0,M17>0),"الأولى",IF(AND(V17>0,(V17-7000)<=22000),"الثانية",IF(AND((V17-7000)>22000,(V17-7000)<=37000),"الثالثة",IF(AND(V17>37000,(V17-7000)<=192000),"الرابعة",IF(AND((V17-7000)>192000),"الخامسة",0))))) -> 0 | AB17: =IF(AA17="الثانية",85%,IF(AA17="الثالثة",45%,IF(AA17="الرابعة",7.5%,IF(AA17="الخامسة",0%,IF(AA17="الأولى",0%,""))))) | AC17: =SUM(Z17,T17,G17,F17) -> 0 | AD17: =M17-AC17 -> 0
A18: 13 | L18: =K18+J18+I18+H18 -> 0 | M18: =ROUND((((K18+J18+I18)/30)*E18)+H18,2) -> 0 | N18: =J18*0.26 -> 0 | O18: =K18*0.24 -> 0 | P18: =N18+O18 -> 0 | Q18: =M18 -> 0 | T18: =R18+S18 -> 0 | U18: =ROUND(M18-T18,2) -> 0 | V18: =(U18*12)-MOD((U18*12),10) -> 0 | X18: =IF(V18-W18<=0,0,V18-W18) -> 0 | Z18: =IFERROR(Y18/12,0) -> 0 | AA18: =IF(AND(X18=0,M18>0),"الأولى",IF(AND(V18>0,(V18-7000)<=22000),"الثانية",IF(AND((V18-7000)>22000,(V18-7000)<=37000),"الثالثة",IF(AND(V18>37000,(V18-7000)<=192000),"الرابعة",IF(AND((V18-7000)>192000),"الخامسة",0))))) -> 0 | AB18: =IF(AA18="الثانية",85%,IF(AA18="الثالثة",45%,IF(AA18="الرابعة",7.5%,IF(AA18="الخامسة",0%,IF(AA18="الأولى",0%,""))))) | AC18: =SUM(Z18,T18,G18,F18) -> 0 | AD18: =M18-AC18 -> 0
A19: 14 | L19: =K19+J19+I19+H19 -> 0 | M19: =ROUND((((K19+J19+I19)/30)*E19)+H19,2) -> 0 | N19: =J19*0.26 -> 0 | O19: =K19*0.24 -> 0 | P19: =N19+O19 -> 0 | Q19: =M19 -> 0 | T19: =R19+S19 -> 0 | U19: =ROUND(M19-T19,2) -> 0 | V19: =(U19*12)-MOD((U19*12),10) -> 0 | X19: =IF(V19-W19<=0,0,V19-W19) -> 0 | Z19: =IFERROR(Y19/12,0) -> 0 | AA19: =IF(AND(X19=0,M19>0),"الأولى",IF(AND(V19>0,(V19-7000)<=22000),"الثانية",IF(AND((V19-7000)>22000,(V19-7000)<=37000),"الثالثة",IF(AND(V19>37000,(V19-7000)<=192000),"الرابعة",IF(AND((V19-7000)>192000),"الخامسة",0))))) -> 0 | AB19: =IF(AA19="الثانية",85%,IF(AA19="الثالثة",45%,IF(AA19="الرابعة",7.5%,IF(AA19="الخامسة",0%,IF(AA19="الأولى",0%,""))))) | AC19: =SUM(Z19,T19,G19,F19) -> 0 | AD19: =M19-AC19 -> 0
A20: 15 | L20: =K20+J20+I20+H20 -> 0 | M20: =ROUND((((K20+J20+I20)/30)*E20)+H20,2) -> 0 | N20: =J20*0.26 -> 0 | O20: =K20*0.24 -> 0 | P20: =N20+O20 -> 0 | Q20: =M20 -> 0 | T20: =R20+S20 -> 0 | U20: =ROUND(M20-T20,2) -> 0 | V20: =(U20*12)-MOD((U20*12),10) -> 0 | X20: =IF(V20-W20<=0,0,V20-W20) -> 0 | Z20: =IFERROR(Y20/12,0) -> 0 | AA20: =IF(AND(X20=0,M20>0),"الأولى",IF(AND(V20>0,(V20-7000)<=22000),"الثانية",IF(AND((V20-7000)>22000,(V20-7000)<=37000),"الثالثة",IF(AND(V20>37000,(V20-7000)<=192000),"الرابعة",IF(AND((V20-7000)>192000),"الخامسة",0))))) -> 0 | AB20: =IF(AA20="الثانية",85%,IF(AA20="الثالثة",45%,IF(AA20="الرابعة",7.5%,IF(AA20="الخامسة",0%,IF(AA20="الأولى",0%,""))))) | AC20: =SUM(Z20,T20,G20,F20) -> 0 | AD20: =M20-AC20 -> 0
A21: 16 | L21: =K21+J21+I21+H21 -> 0 | M21: =ROUND((((K21+J21+I21)/30)*E21)+H21,2) -> 0 | N21: =J21*0.26 -> 0 | O21: =K21*0.24 -> 0 | P21: =N21+O21 -> 0 | Q21: =M21 -> 0 | T21: =R21+S21 -> 0 | U21: =ROUND(M21-T21,2) -> 0 | V21: =(U21*12)-MOD((U21*12),10) -> 0 | X21: =IF(V21-W21<=0,0,V21-W21) -> 0 | Z21: =IFERROR(Y21/12,0) -> 0 | AA21: =IF(AND(X21=0,M21>0),"الأولى",IF(AND(V21>0,(V21-7000)<=22000),"الثانية",IF(AND((V21-7000)>22000,(V21-7000)<=37000),"الثالثة",IF(AND(V21>37000,(V21-7000)<=192000),"الرابعة",IF(AND((V21-7000)>192000),"الخامسة",0))))) -> 0 | AB21: =IF(AA21="الثانية",85%,IF(AA21="الثالثة",45%,IF(AA21="الرابعة",7.5%,IF(AA21="الخامسة",0%,IF(AA21="الأولى",0%,""))))) | AC21: =SUM(Z21,T21,G21,F21) -> 0 | AD21: =M21-AC21 -> 0
A22: 17 | L22: =K22+J22+I22+H22 -> 0 | M22: =ROUND((((K22+J22+I22)/30)*E22)+H22,2) -> 0 | N22: =J22*0.26 -> 0 | O22: =K22*0.24 -> 0 | P22: =N22+O22 -> 0 | Q22: =M22 -> 0 | T22: =R22+S22 -> 0 | U22: =ROUND(M22-T22,2) -> 0 | V22: =(U22*12)-MOD((U22*12),10) -> 0 | X22: =IF(V22-W22<=0,0,V22-W22) -> 0 | Z22: =IFERROR(Y22/12,0) -> 0 | AA22: =IF(AND(X22=0,M22>0),"الأولى",IF(AND(V22>0,(V22-7000)<=22000),"الثانية",IF(AND((V22-7000)>22000,(V22-7000)<=37000),"الثالثة",IF(AND(V22>37000,(V22-7000)<=192000),"الرابعة",IF(AND((V22-7000)>192000),"الخامسة",0))))) -> 0 | AB22: =IF(AA22="الثانية",85%,IF(AA22="الثالثة",45%,IF(AA22="الرابعة",7.5%,IF(AA22="الخامسة",0%,IF(AA22="الأولى",0%,""))))) | AC22: =SUM(Z22,T22,G22,F22) -> 0 | AD22: =M22-AC22 -> 0
... A55: 50 | L55: =K55+J55+I55+H55 -> 0 | M55: =ROUND((((K55+J55+I55)/30)*E55)+H55,2) -> 0 | N55: =J55*0.26 -> 0 | O55: =K55*0.24 -> 0 | P55: =N55+O55 -> 0 | Q55: =M55 -> 0 | T55: =R55+S55 -> 0 | U55: =ROUND(M55-T55,2) -> 0 | V55: =(U55*12)-MOD((U55*12),10) -> 0 | X55: =IF(V55-W55<=0,0,V55-W55) -> 0 | Z55: =IFERROR(Y55/12,0) -> 0 | AA55: =IF(AND(X55=0,M55>0),"الأولى",IF(AND(V55>0,(V55-7000)<=22000),"الثانية",IF(AND((V55-7000)>22000,(V55-7000)<=37000),"الثالثة",IF(AND(V55>37000,(V55-7000)<=192000),"الرابعة",IF(AND((V55-7000)>192000),"الخامسة",0))))) -> 0 | AB55: =IF(AA55="الثانية",85%,IF(AA55="الثالثة",45%,IF(AA55="الرابعة",7.5%,IF(AA55="الخامسة",0%,IF(AA55="الأولى",0%,""))))) | AC55: =SUM(Z55,T55,G55,F55) -> 0 | AD55: =M55-AC55 -> 0
F56: =SUM(F6:F55) -> 0 | G56: =SUM(G6:G55) -> 0 | H56: =SUM(H6:H55) -> 0 | I56: =SUM(I6:I55) -> 12287 | J56: =SUM(J6:J55) -> 1950 | K56: =SUM(K6:K55) -> 0 | L56: =SUM(L6:L55) -> 14237 | M56: =SUM(M6:M55) -> 14237 | ... Z56: =SUM(Z6:Z55) -> 0 | AC56: =SUM(AC6:AC55) -> 0 | AD56: =SUM(AD6:AD55) -> 14237 | AM56: =SUM(AM6:AM55) -> 0 | AN56: =SUM(AN6:AN55) -> 0

Sheet طباعه الكشف للموظف
B3: شركة ارابيان للمقاولات العامة الإدارة المالية
B5: كشف الراتب لشهر فبراير - 2019
B7: كود | C7: 1
B8: اسم الموظف | C8: =VLOOKUP(C7,'PAYRROLL- الشرائح'!A6:B55,2,FALSE) -> موظف 1
C10: الراتب الشهري | D10: عدد ايام العمل | E10: {=INDEX('PAYRROLL- الشرائح'!E6:E55,MATCH($C$7,'PAYRROLL- الشرائح'!$A$6:$A$55,0),1)} -> 30
D11: الأساسي | E11: {=INDEX('PAYRROLL- الشرائح'!$F$6:$AD$55,MATCH($C$7,'PAYRROLL- الشرائح'!$A$6:$A$55,0),5)} -> 700
D12: المتغير | E12: {=INDEX('PAYRROLL- الشرائح'!$F$6:$AD$55,MATCH($C$7,'PAYRROLL- الشرائح'!$A$6:$A$55,0),6)} -> 0
D13: بدلات | E13: {=INDEX('PAYRROLL- الشرائح'!$F$6:$AD$55,MATCH($C$7,'PAYRROLL- الشرائح'!$A$6:$A$55,0),4)} -> 4977
C14: الأجمالي | E14: =SUM(E11:E13) -> 5677
C15: المستحق خلال الشهر | E15: {=INDEX('PAYRROLL- الشرائح'!$F$6:$AD$55,MATCH($C$7,'PAYRROLL- الشرائح'!$A$6:$A$55,0),12)} -> 5677
C17: التأمينات ( حصة العامل ) | D17: الأساسي | E17: {=INDEX('PAYRROLL- الشرائح'!$F$6:$AD$55,MATCH($C$7,'PAYRROLL- الشرائح'!$A$6:$A$55,0),13)} -> 0
D18: المتغير | E18: {=INDEX('PAYRROLL- الشرائح'!$F$6:$AD$55,MATCH($C$7,'PAYRROLL- الشرائح'!$A$6:$A$55,0),14)} -> 0
C19: الأجمالي | E19: =E17+E18 -> 0
C21: جزاءات وتأخيرات | E21: {=INDEX('PAYRROLL- الشرائح'!$F$6:$AD$55,MATCH($C$7,'PAYRROLL- الشرائح'!$A$6:$A$55,0),1)} -> 0
C22: سلف | E22: {=INDEX('PAYRROLL- الشرائح'!$F$6:$AD$55,MATCH($C$7,'PAYRROLL- الشرائح'!$A$6:$A$55,0),2)} -> 0
C23: الأجمالي | E23: =SUM(E21:E22) -> 0
C25: الضريبة الشهرية | E25: {=INDEX('PAYRROLL- الشرائح'!$F$6:$AD$55,MATCH($C$7,'PAYRROLL- الشرائح'!$A$6:$A$55,0),21)} -> 0
C27: أجمالي المستقطع | E27: =SUM(E19,E23,E25) -> 0
C29: صافي الراتب الشهري | E29: =E15-E27 -> 5677
B31: أستلمت انا / ................................... الراتب المستحق لشهر فبراير 2019
C33: التاريخ : ..../..../..........
