Workbook

Sheet الصفحة الرئيسية
R19: HR Specialist
Q20: Medhat Elsawy

Sheet برنامج الاجازات 
B1: عودة
N2: الرصــــــــــــــــيد السنوى | S2: أجازات خارج الرصيد السنوي | W2: اغسطس | AC2: سبتمبر | AI2: اكتوبر | AO2: نوفمبر | AU2: دبسمبر | BA2: يناير | BG2: فبراير | BM2: مارس | BS2: ابريل | BY2: مايو | CE2: يونيه | CK2: يوليو
A4: رقم الموظف | B4: الاسم | C4: الوظيفة | D4: الادارة / المشروع | E4: تاريخ الميلاد | F4: العمر | G4: المدة التأمينية | H4: تاريخ التعيين | I4: عدد شهور العمل | J4: هل يستحق اجازة ؟ | K4: تاريخ الاستحقاق | L4: الرصيد السنوى | N4: الاعتيادى | O4: العارضة | P4: المجموع | Q4: باقي الرصيد | S4: مرضي | T4: بدل راحة | U4: بدون أجر | W4: إعتيادى | X4: عارضة | Y4: مرضي | Z4: بدل راحة | AA4: بدون أجر | AC4: إعتيادى | AD4: عارضة | AE4: مرضي | AF4: بدل راحة | AG4: بدون أجر | AI4: إعتيادى | AJ4: عارضة | AK4: مرضي | AL4: بدل راحة | AM4: بدون أجر | AO4: إعتيادى | AP4: عارضة | AQ4: مرضي | AR4: بدل راحة | AS4: بدون أجر | AU4: إعتيادى | AV4: عارضة | AW4: مرضي | AX4: بدل راحة | AY4: بدون أجر | BA4: إعتيادى | BB4: عارضة | BC4: مرضي | BD4: بدل راحة | BE4: بدون أجر | BG4: إعتيادى | BH4: عارضة | BI4: مرضي | BJ4: بدل راحة | BK4: بدون أجر | BM4: إعتيادى | BN4: عارضة | BO4: مرضي | BP4: بدل راحة | BQ4: بدون أجر | BS4: إعتيادى | BT4: عارضة | BU4: مرضي | BV4: بدل راحة | BW4: بدون أجر | BY4: إعتيادى | BZ4: عارضة | CA4: مرضي | CB4: بدل راحة | CC4: بدون أجر | CE4: إعتيادى | CF4: عارضة | CG4: مرضي | CH4: بدل راحة | CI4: بدون أجر | CK4: إعتيادى | CL4: عارضة | CM4: مرضي | CN4: بدل راحة | CO4: بدون أجر
C5: مراقب مخازن | D5: الادارة / المشروع | E5: 35411 | F5: =DATEDIF(E5,TODAY(),"Y") -> 25 | G5: 2 | H5: 43522 | I5: =DATEDIF(H5,TODAY(),"M") -> 36 | J5: =IF(I5>6,"يستحق","لايستحق") -> يستحق | K5: =180+H5 -> 43702 | L5: 21 | N5: =W5+AC5+AI5+AO5+AU5+BA5+BG5+BM5+BS5+BY5+CE5+CK5 -> 0 | O5: =X5+AD5+AJ5+AP5+AV5+BB5+BH5+BN5+BT5+BZ5+CF5+CL5 -> 0 | P5: =N5+O5 -> 0 | Q5: =L5-P5 -> 21 | S5: =Y5+AE5+AK5+AQ5+AW5+BC5+BI5+BO5+BU5+CA5+CG5+CM5 -> 0 | T5: =Z5+AF5+AL5+AR5+AX5+BD5+BJ5+BP5+BV5+CB5+CH5+CN5 -> 0 | U5: =AA5+AG5+AM5+AS5+AY5+BE5+BK5+BQ5+BW5+CC5+CI5+CO5 -> 0
C6: محاسبة | D6: الادارة / المشروع | E6: 35263 | F6: =DATEDIF(E6,TODAY(),"Y") -> 25 | G6: 2 | H6: 43522 | I6: =DATEDIF(H6,TODAY(),"M") -> 36 | J6: =IF(I6>6,"يستحق","لايستحق") -> يستحق | K6: =180+H6 -> 43702 | L6: 21 | N6: =W6+AC6+AI6+AO6+AU6+BA6+BG6+BM6+BS6+BY6+CE6+CK6 -> 0 | O6: =X6+AD6+AJ6+AP6+AV6+BB6+BH6+BN6+BT6+BZ6+CF6+CL6 -> 0 | P6: =N6+O6 -> 0 | Q6: =L6-P6 -> 21 | S6: =Y6+AE6+AK6+AQ6+AW6+BC6+BI6+BO6+BU6+CA6+CG6+CM6 -> 0 | T6: =Z6+AF6+AL6+AR6+AX6+BD6+BJ6+BP6+BV6+CB6+CH6+CN6 -> 0 | U6: =AA6+AG6+AM6+AS6+AY6+BE6+BK6+BQ6+BW6+CC6+CI6+CO6 -> 0
C7: مندوب | D7: الادارة / المشروع | E7: 43654 | F7: =DATEDIF(E7,TODAY(),"Y") -> 2 | G7: 2 | H7: 43522 | I7: =DATEDIF(H7,TODAY(),"M") -> 36 | J7: =IF(I7>6,"يستحق","لايستحق") -> يستحق | K7: =180+H7 -> 43702 | L7: 21 | N7: =W7+AC7+AI7+AO7+AU7+BA7+BG7+BM7+BS7+BY7+CE7+CK7 -> 0 | O7: =X7+AD7+AJ7+AP7+AV7+BB7+BH7+BN7+BT7+BZ7+CF7+CL7 -> 0 | P7: =N7+O7 -> 0 | Q7: =L7-P7 -> 21 | S7: =Y7+AE7+AK7+AQ7+AW7+BC7+BI7+BO7+BU7+CA7+CG7+CM7 -> 0 | T7: =Z7+AF7+AL7+AR7+AX7+BD7+BJ7+BP7+BV7+CB7+CH7+CN7 -> 0 | U7: =AA7+AG7+AM7+AS7+AY7+BE7+BK7+BQ7+BW7+CC7+CI7+CO7 -> 0
C8: مساعد | D8: الانتاج | E8: 43971 | F8: =DATEDIF(E8,TODAY(),"Y") -> 1 | G8: 4 | H8: 43971 | I8: =DATEDIF(H8,TODAY(),"M") -> 21 | J8: =IF(I8>6,"يستحق","لايستحق") -> يستحق | K8: =180+H8 -> 44151 | L8: 21 | N8: =W8+AC8+AI8+AO8+AU8+BA8+BG8+BM8+BS8+BY8+CE8+CK8 -> 0 | O8: =X8+AD8+AJ8+AP8+AV8+BB8+BH8+BN8+BT8+BZ8+CF8+CL8 -> 0 | P8: =N8+O8 -> 0 | Q8: =L8-P8 -> 21 | S8: =Y8+AE8+AK8+AQ8+AW8+BC8+BI8+BO8+BU8+CA8+CG8+CM8 -> 0 | T8: =Z8+AF8+AL8+AR8+AX8+BD8+BJ8+BP8+BV8+CB8+CH8+CN8 -> 0 | U8: =AA8+AG8+AM8+AS8+AY8+BE8+BK8+BQ8+BW8+CC8+CI8+CO8 -> 0
C9: مدير انتاج | D9: الانتاج | E9: 27386 | F9: =DATEDIF(E9,TODAY(),"Y") -> 47 | G9: 11 | H9: 37622 | I9: =DATEDIF(H9,TODAY(),"M") -> 230 | J9: =IF(I9>6,"يستحق","لايستحق") -> يستحق | K9: =180+H9 -> 37802 | L9: 21 | N9: =W9+AC9+AI9+AO9+AU9+BA9+BG9+BM9+BS9+BY9+CE9+CK9 -> 0 | O9: =X9+AD9+AJ9+AP9+AV9+BB9+BH9+BN9+BT9+BZ9+CF9+CL9 -> 0 | P9: =N9+O9 -> 0 | Q9: =L9-P9 -> 21 | S9: =Y9+AE9+AK9+AQ9+AW9+BC9+BI9+BO9+BU9+CA9+CG9+CM9 -> 0 | T9: =Z9+AF9+AL9+AR9+AX9+BD9+BJ9+BP9+BV9+CB9+CH9+CN9 -> 0 | U9: =AA9+AG9+AM9+AS9+AY9+BE9+BK9+BQ9+BW9+CC9+CI9+CO9 -> 0
C10: رئيس قسم القص | D10: الانتاج | E10: 19711 | F10: =DATEDIF(E10,TODAY(),"Y") -> 68 | G10: 0 | H10: 33970 | I10: =DATEDIF(H10,TODAY(),"M") -> 350 | J10: =IF(I10>6,"يستحق","لايستحق") -> يستحق | K10: =180+H10 -> 34150 | L10: 21 | N10: =W10+AC10+AI10+AO10+AU10+BA10+BG10+BM10+BS10+BY10+CE10+CK10 -> 0 | O10: =X10+AD10+AJ10+AP10+AV10+BB10+BH10+BN10+BT10+BZ10+CF10+CL10 -> 0 | P10: =N10+O10 -> 0 | Q10: =L10-P10 -> 21 | S10: =Y10+AE10+AK10+AQ10+AW10+BC10+BI10+BO10+BU10+CA10+CG10+CM10 -> 0 | T10: =Z10+AF10+AL10+AR10+AX10+BD10+BJ10+BP10+BV10+CB10+CH10+CN10 -> 0 | U10: =AA10+AG10+AM10+AS10+AY10+BE10+BK10+BQ10+BW10+CC10+CI10+CO10 -> 0
C11: مشرف سائقين | D11: الحركة | E11: 28584 | F11: =DATEDIF(E11,TODAY(),"Y") -> 43 | G11: 11 | H11: 40496 | I11: =DATEDIF(H11,TODAY(),"M") -> 135 | J11: =IF(I11>6,"يستحق","لايستحق") -> يستحق | K11: =180+H11 -> 40676 | L11: 21 | N11: =W11+AC11+AI11+AO11+AU11+BA11+BG11+BM11+BS11+BY11+CE11+CK11 -> 0 | O11: =X11+AD11+AJ11+AP11+AV11+BB11+BH11+BN11+BT11+BZ11+CF11+CL11 -> 0 | P11: =N11+O11 -> 0 | Q11: =L11-P11 -> 21 | S11: =Y11+AE11+AK11+AQ11+AW11+BC11+BI11+BO11+BU11+CA11+CG11+CM11 -> 0 | T11: =Z11+AF11+AL11+AR11+AX11+BD11+BJ11+BP11+BV11+CB11+CH11+CN11 -> 0 | U11: =AA11+AG11+AM11+AS11+AY11+BE11+BK11+BQ11+BW11+CC11+CI11+CO11 -> 0
C12: سائق | D12: الحركة | E12: 28128 | F12: =DATEDIF(E12,TODAY(),"Y") -> 45 | G12: 11 | H12: 40179 | I12: =DATEDIF(H12,TODAY(),"M") -> 146 | J12: =IF(I12>6,"يستحق","لايستحق") -> يستحق | K12: =180+H12 -> 40359 | L12: 21 | N12: =W12+AC12+AI12+AO12+AU12+BA12+BG12+BM12+BS12+BY12+CE12+CK12 -> 0 | O12: =X12+AD12+AJ12+AP12+AV12+BB12+BH12+BN12+BT12+BZ12+CF12+CL12 -> 0 | P12: =N12+O12 -> 0 | Q12: =L12-P12 -> 21 | S12: =Y12+AE12+AK12+AQ12+AW12+BC12+BI12+BO12+BU12+CA12+CG12+CM12 -> 0 | T12: =Z12+AF12+AL12+AR12+AX12+BD12+BJ12+BP12+BV12+CB12+CH12+CN12 -> 0 | U12: =AA12+AG12+AM12+AS12+AY12+BE12+BK12+BQ12+BW12+CC12+CI12+CO12 -> 0
C13: سائق | D13: الحركة | E13: 33071 | F13: =DATEDIF(E13,TODAY(),"Y") -> 31 | G13: 5 | H13: 42618 | I13: =DATEDIF(H13,TODAY(),"M") -> 65 | J13: =IF(I13>6,"يستحق","لايستحق") -> يستحق | K13: =180+H13 -> 42798 | L13: 21 | N13: =W13+AC13+AI13+AO13+AU13+BA13+BG13+BM13+BS13+BY13+CE13+CK13 -> 0 | O13: =X13+AD13+AJ13+AP13+AV13+BB13+BH13+BN13+BT13+BZ13+CF13+CL13 -> 0 | P13: =N13+O13 -> 0 | Q13: =L13-P13 -> 21 | S13: =Y13+AE13+AK13+AQ13+AW13+BC13+BI13+BO13+BU13+CA13+CG13+CM13 -> 0 | T13: =Z13+AF13+AL13+AR13+AX13+BD13+BJ13+BP13+BV13+CB13+CH13+CN13 -> 0 | U13: =AA13+AG13+AM13+AS13+AY13+BE13+BK13+BQ13+BW13+CC13+CI13+CO13 -> 0
C14: عامل مكبس | D14: الانتاج | E14: 25867 | F14: =DATEDIF(E14,TODAY(),"Y") -> 51 | G14: 10 | H14: 40911 | I14: =DATEDIF(H14,TODAY(),"M") -> 121 | J14: =IF(I14>6,"يستحق","لايستحق") -> يستحق | K14: =180+H14 -> 41091 | L14: 21 | N14: =W14+AC14+AI14+AO14+AU14+BA14+BG14+BM14+BS14+BY14+CE14+CK14 -> 0 | O14: =X14+AD14+AJ14+AP14+AV14+BB14+BH14+BN14+BT14+BZ14+CF14+CL14 -> 0 | P14: =N14+O14 -> 0 | Q14: =L14-P14 -> 21 | S14: =Y14+AE14+AK14+AQ14+AW14+BC14+BI14+BO14+BU14+CA14+CG14+CM14 -> 0 | T14: =Z14+AF14+AL14+AR14+AX14+BD14+BJ14+BP14+BV14+CB14+CH14+CN14 -> 0 | U14: =AA14+AG14+AM14+AS14+AY14+BE14+BK14+BQ14+BW14+CC14+CI14+CO14 -> 0
C15: خدمات | D15: الادارة / المشروع | E15: 29302 | F15: =DATEDIF(E15,TODAY(),"Y") -> 41 | G15: 7 | H15: 42381 | I15: =DATEDIF(H15,TODAY(),"M") -> 73 | J15: =IF(I15>6,"يستحق","لايستحق") -> يستحق | K15: =180+H15 -> 42561 | L15: 21 | N15: =W15+AC15+AI15+AO15+AU15+BA15+BG15+BM15+BS15+BY15+CE15+CK15 -> 0 | O15: =X15+AD15+AJ15+AP15+AV15+BB15+BH15+BN15+BT15+BZ15+CF15+CL15 -> 0 | P15: =N15+O15 -> 0 | Q15: =L15-P15 -> 21 | S15: =Y15+AE15+AK15+AQ15+AW15+BC15+BI15+BO15+BU15+CA15+CG15+CM15 -> 0 | T15: =Z15+AF15+AL15+AR15+AX15+BD15+BJ15+BP15+BV15+CB15+CH15+CN15 -> 0 | U15: =AA15+AG15+AM15+AS15+AY15+BE15+BK15+BQ15+BW15+CC15+CI15+CO15 -> 0
C16: فني تكسير | D16: الانتاج | E16: 24098 | F16: =DATEDIF(E16,TODAY(),"Y") -> 56 | G16: 11 | H16: 40911 | I16: =DATEDIF(H16,TODAY(),"M") -> 121 | J16: =IF(I16>6,"يستحق","لايستحق") -> يستحق | K16: =180+H16 -> 41091 | L16: 21 | N16: =W16+AC16+AI16+AO16+AU16+BA16+BG16+BM16+BS16+BY16+CE16+CK16 -> 0 | O16: =X16+AD16+AJ16+AP16+AV16+BB16+BH16+BN16+BT16+BZ16+CF16+CL16 -> 0 | P16: =N16+O16 -> 0 | Q16: =L16-P16 -> 21 | S16: =Y16+AE16+AK16+AQ16+AW16+BC16+BI16+BO16+BU16+CA16+CG16+CM16 -> 0 | T16: =Z16+AF16+AL16+AR16+AX16+BD16+BJ16+BP16+BV16+CB16+CH16+CN16 -> 0 | U16: =AA16+AG16+AM16+AS16+AY16+BE16+BK16+BQ16+BW16+CC16+CI16+CO16 -> 0
... C27: مساعد اول تجليد | D27: الانتاج | E27: 23782 | F27: =DATEDIF(E27,TODAY(),"Y") -> 57 | G27: 6 | H27: 40817 | I27: =DATEDIF(H27,TODAY(),"M") -> 125 | J27: =IF(I27>6,"يستحق","لايستحق") -> يستحق | K27: =180+H27 -> 40997 | L27: 21 | N27: =W27+AC27+AI27+AO27+AU27+BA27+BG27+BM27+BS27+BY27+CE27+CK27 -> 0 | O27: =X27+AD27+AJ27+AP27+AV27+BB27+BH27+BN27+BT27+BZ27+CF27+CL27 -> 0 | P27: =N27+O27 -> 0 | Q27: =L27-P27 -> 21 | S27: =Y27+AE27+AK27+AQ27+AW27+BC27+BI27+BO27+BU27+CA27+CG27+CM27 -> 0 | T27: =Z27+AF27+AL27+AR27+AX27+BD27+BJ27+BP27+BV27+CB27+CH27+CN27 -> 0 | U27: =AA27+AG27+AM27+AS27+AY27+BE27+BK27+BQ27+BW27+CC27+CI27+CO27 -> 0
C28: امين مخزن | D28: الانتاج | F28: =DATEDIF(E28,TODAY(),"Y") -> 122 | H28: 40969 | I28: =DATEDIF(H28,TODAY(),"M") -> 120 | J28: =IF(I28>6,"يستحق","لايستحق") -> يستحق | K28: =180+H28 -> 41149 | L28: 21 | N28: =W28+AC28+AI28+AO28+AU28+BA28+BG28+BM28+BS28+BY28+CE28+CK28 -> 0 | O28: =X28+AD28+AJ28+AP28+AV28+BB28+BH28+BN28+BT28+BZ28+CF28+CL28 -> 0 | P28: =N28+O28 -> 0 | Q28: =L28-P28 -> 21 | S28: =Y28+AE28+AK28+AQ28+AW28+BC28+BI28+BO28+BU28+CA28+CG28+CM28 -> 0 | T28: =Z28+AF28+AL28+AR28+AX28+BD28+BJ28+BP28+BV28+CB28+CH28+CN28 -> 0 | U28: =AA28+AG28+AM28+AS28+AY28+BE28+BK28+BQ28+BW28+CC28+CI28+CO28 -> 0
C29: مساعد اول تكسير | D29: الانتاج | E29: 27794 | F29: =DATEDIF(E29,TODAY(),"Y") -> 46 | G29: 8 | H29: 40911 | I29: =DATEDIF(H29,TODAY(),"M") -> 121 | J29: =IF(I29>6,"يستحق","لايستحق") -> يستحق | K29: =180+H29 -> 41091 | L29: 21 | N29: =W29+AC29+AI29+AO29+AU29+BA29+BG29+BM29+BS29+BY29+CE29+CK29 -> 0 | O29: =X29+AD29+AJ29+AP29+AV29+BB29+BH29+BN29+BT29+BZ29+CF29+CL29 -> 0 | P29: =N29+O29 -> 0 | Q29: =L29-P29 -> 21 | S29: =Y29+AE29+AK29+AQ29+AW29+BC29+BI29+BO29+BU29+CA29+CG29+CM29 -> 0 | T29: =Z29+AF29+AL29+AR29+AX29+BD29+BJ29+BP29+BV29+CB29+CH29+CN29 -> 0 | U29: =AA29+AG29+AM29+AS29+AY29+BE29+BK29+BQ29+BW29+CC29+CI29+CO29 -> 0
C30: فني طباعة | D30: الانتاج | E30: 33470 | F30: =DATEDIF(E30,TODAY(),"Y") -> 30 | G30: 9 | H30: 40969 | I30: =DATEDIF(H30,TODAY(),"M") -> 120 | J30: =IF(I30>6,"يستحق","لايستحق") -> يستحق | K30: =180+H30 -> 41149 | L30: 21 | N30: =W30+AC30+AI30+AO30+AU30+BA30+BG30+BM30+BS30+BY30+CE30+CK30 -> 0 | O30: =X30+AD30+AJ30+AP30+AV30+BB30+BH30+BN30+BT30+BZ30+CF30+CL30 -> 0 | P30: =N30+O30 -> 0 | Q30: =L30-P30 -> 21 | S30: =Y30+AE30+AK30+AQ30+AW30+BC30+BI30+BO30+BU30+CA30+CG30+CM30 -> 0 | T30: =Z30+AF30+AL30+AR30+AX30+BD30+BJ30+BP30+BV30+CB30+CH30+CN30 -> 0 | U30: =AA30+AG30+AM30+AS30+AY30+BE30+BK30+BQ30+BW30+CC30+CI30+CO30 -> 0
C31: فني تجليد | D31: الانتاج | E31: 26529 | F31: =DATEDIF(E31,TODAY(),"Y") -> 49 | G31: 9 | H31: 42375 | I31: =DATEDIF(H31,TODAY(),"M") -> 73 | J31: =IF(I31>6,"يستحق","لايستحق") -> يستحق | K31: =180+H31 -> 42555 | L31: 21 | N31: =W31+AC31+AI31+AO31+AU31+BA31+BG31+BM31+BS31+BY31+CE31+CK31 -> 0 | O31: =X31+AD31+AJ31+AP31+AV31+BB31+BH31+BN31+BT31+BZ31+CF31+CL31 -> 0 | P31: =N31+O31 -> 0 | Q31: =L31-P31 -> 21 | S31: =Y31+AE31+AK31+AQ31+AW31+BC31+BI31+BO31+BU31+CA31+CG31+CM31 -> 0 | T31: =Z31+AF31+AL31+AR31+AX31+BD31+BJ31+BP31+BV31+CB31+CH31+CN31 -> 0 | U31: =AA31+AG31+AM31+AS31+AY31+BE31+BK31+BQ31+BW31+CC31+CI31+CO31 -> 0
C32: فني تجليد | D32: الانتاج | E32: 31395 | F32: =DATEDIF(E32,TODAY(),"Y") -> 36 | G32: 6 | H32: 40817 | I32: =DATEDIF(H32,TODAY(),"M") -> 125 | J32: =IF(I32>6,"يستحق","لايستحق") -> يستحق | K32: =180+H32 -> 40997 | L32: 21 | N32: =W32+AC32+AI32+AO32+AU32+BA32+BG32+BM32+BS32+BY32+CE32+CK32 -> 0 | O32: =X32+AD32+AJ32+AP32+AV32+BB32+BH32+BN32+BT32+BZ32+CF32+CL32 -> 0 | P32: =N32+O32 -> 0 | Q32: =L32-P32 -> 21 | S32: =Y32+AE32+AK32+AQ32+AW32+BC32+BI32+BO32+BU32+CA32+CG32+CM32 -> 0 | T32: =Z32+AF32+AL32+AR32+AX32+BD32+BJ32+BP32+BV32+CB32+CH32+CN32 -> 0 | U32: =AA32+AG32+AM32+AS32+AY32+BE32+BK32+BQ32+BW32+CC32+CI32+CO32 -> 0
C33: امين مخزن | D33: الانتاج | E33: 31846 | F33: =DATEDIF(E33,TODAY(),"Y") -> 34 | G33: 6 | H33: 40179 | I33: =DATEDIF(H33,TODAY(),"M") -> 146 | J33: =IF(I33>6,"يستحق","لايستحق") -> يستحق | K33: =180+H33 -> 40359 | L33: 21 | N33: =W33+AC33+AI33+AO33+AU33+BA33+BG33+BM33+BS33+BY33+CE33+CK33 -> 0 | O33: =X33+AD33+AJ33+AP33+AV33+BB33+BH33+BN33+BT33+BZ33+CF33+CL33 -> 0 | P33: =N33+O33 -> 0 | Q33: =L33-P33 -> 21 | S33: =Y33+AE33+AK33+AQ33+AW33+BC33+BI33+BO33+BU33+CA33+CG33+CM33 -> 0 | T33: =Z33+AF33+AL33+AR33+AX33+BD33+BJ33+BP33+BV33+CB33+CH33+CN33 -> 0 | U33: =AA33+AG33+AM33+AS33+AY33+BE33+BK33+BQ33+BW33+CC33+CI33+CO33 -> 0
C34: فني قص | D34: الانتاج | E34: 27744 | F34: =DATEDIF(E34,TODAY(),"Y") -> 46 | G34: 8 | H34: 40179 | I34: =DATEDIF(H34,TODAY(),"M") -> 146 | J34: =IF(I34>6,"يستحق","لايستحق") -> يستحق | K34: =180+H34 -> 40359 | L34: 21 | N34: =W34+AC34+AI34+AO34+AU34+BA34+BG34+BM34+BS34+BY34+CE34+CK34 -> 0 | O34: =X34+AD34+AJ34+AP34+AV34+BB34+BH34+BN34+BT34+BZ34+CF34+CL34 -> 0 | P34: =N34+O34 -> 0 | Q34: =L34-P34 -> 21 | S34: =Y34+AE34+AK34+AQ34+AW34+BC34+BI34+BO34+BU34+CA34+CG34+CM34 -> 0 | T34: =Z34+AF34+AL34+AR34+AX34+BD34+BJ34+BP34+BV34+CB34+CH34+CN34 -> 0 | U34: =AA34+AG34+AM34+AS34+AY34+BE34+BK34+BQ34+BW34+CC34+CI34+CO34 -> 0
C35: مساعد تجليد | D35: الانتاج | E35: 32295 | F35: =DATEDIF(E35,TODAY(),"Y") -> 33 | G35: 4 | H35: 40969 | I35: =DATEDIF(H35,TODAY(),"M") -> 120 | J35: =IF(I35>6,"يستحق","لايستحق") -> يستحق | K35: =180+H35 -> 41149 | L35: 21 | N35: =W35+AC35+AI35+AO35+AU35+BA35+BG35+BM35+BS35+BY35+CE35+CK35 -> 0 | O35: =X35+AD35+AJ35+AP35+AV35+BB35+BH35+BN35+BT35+BZ35+CF35+CL35 -> 0 | P35: =N35+O35 -> 0 | Q35: =L35-P35 -> 21 | S35: =Y35+AE35+AK35+AQ35+AW35+BC35+BI35+BO35+BU35+CA35+CG35+CM35 -> 0 | T35: =Z35+AF35+AL35+AR35+AX35+BD35+BJ35+BP35+BV35+CB35+CH35+CN35 -> 0 | U35: =AA35+AG35+AM35+AS35+AY35+BE35+BK35+BQ35+BW35+CC35+CI35+CO35 -> 0
C36: مساعد اول طباعة | D36: الانتاج | E36: 31767 | F36: =DATEDIF(E36,TODAY(),"Y") -> 35 | G36: 9 | H36: 40969 | I36: =DATEDIF(H36,TODAY(),"M") -> 120 | J36: =IF(I36>6,"يستحق","لايستحق") -> يستحق | K36: =180+H36 -> 41149 | L36: 21 | N36: =W36+AC36+AI36+AO36+AU36+BA36+BG36+BM36+BS36+BY36+CE36+CK36 -> 0 | O36: =X36+AD36+AJ36+AP36+AV36+BB36+BH36+BN36+BT36+BZ36+CF36+CL36 -> 0 | P36: =N36+O36 -> 0 | Q36: =L36-P36 -> 21 | S36: =Y36+AE36+AK36+AQ36+AW36+BC36+BI36+BO36+BU36+CA36+CG36+CM36 -> 0 | T36: =Z36+AF36+AL36+AR36+AX36+BD36+BJ36+BP36+BV36+CB36+CH36+CN36 -> 0 | U36: =AA36+AG36+AM36+AS36+AY36+BE36+BK36+BQ36+BW36+CC36+CI36+CO36 -> 0
C37: مساعد تجليد | D37: الانتاج | E37: 20682 | F37: =DATEDIF(E37,TODAY(),"Y") -> 65 | G37: 4 | H37: 42375 | I37: =DATEDIF(H37,TODAY(),"M") -> 73 | J37: =IF(I37>6,"يستحق","لايستحق") -> يستحق | K37: =180+H37 -> 42555 | L37: 21 | N37: =W37+AC37+AI37+AO37+AU37+BA37+BG37+BM37+BS37+BY37+CE37+CK37 -> 0 | O37: =X37+AD37+AJ37+AP37+AV37+BB37+BH37+BN37+BT37+BZ37+CF37+CL37 -> 0 | P37: =N37+O37 -> 0 | Q37: =L37-P37 -> 21 | S37: =Y37+AE37+AK37+AQ37+AW37+BC37+BI37+BO37+BU37+CA37+CG37+CM37 -> 0 | T37: =Z37+AF37+AL37+AR37+AX37+BD37+BJ37+BP37+BV37+CB37+CH37+CN37 -> 0 | U37: =AA37+AG37+AM37+AS37+AY37+BE37+BK37+BQ37+BW37+CC37+CI37+CO37 -> 0
C38: مساعد تجليد | D38: الانتاج | E38: 33131 | F38: =DATEDIF(E38,TODAY(),"Y") -> 31 | G38: 5 | H38: 41698 | I38: =DATEDIF(H38,TODAY(),"M") -> 96 | J38: =IF(I38>6,"يستحق","لايستحق") -> يستحق | K38: =180+H38 -> 41878 | L38: 21 | N38: =W38+AC38+AI38+AO38+AU38+BA38+BG38+BM38+BS38+BY38+CE38+CK38 -> 0 | O38: =X38+AD38+AJ38+AP38+AV38+BB38+BH38+BN38+BT38+BZ38+CF38+CL38 -> 0 | P38: =N38+O38 -> 0 | Q38: =L38-P38 -> 21 | S38: =Y38+AE38+AK38+AQ38+AW38+BC38+BI38+BO38+BU38+CA38+CG38+CM38 -> 0 | T38: =Z38+AF38+AL38+AR38+AX38+BD38+BJ38+BP38+BV38+CB38+CH38+CN38 -> 0 | U38: =AA38+AG38+AM38+AS38+AY38+BE38+BK38+BQ38+BW38+CC38+CI38+CO38 -> 0
C39: مساعد تجليد | D39: الانتاج | E39: 22884 | F39: =DATEDIF(E39,TODAY(),"Y") -> 59 | H39: 43831 | I39: =DATEDIF(H39,TODAY(),"M") -> 26 | J39: =IF(I39>6,"يستحق","لايستحق") -> يستحق | K39: =180+H39 -> 44011 | L39: 21 | N39: =W39+AC39+AI39+AO39+AU39+BA39+BG39+BM39+BS39+BY39+CE39+CK39 -> 0 | O39: =X39+AD39+AJ39+AP39+AV39+BB39+BH39+BN39+BT39+BZ39+CF39+CL39 -> 0 | P39: =N39+O39 -> 0 | Q39: =L39-P39 -> 21 | S39: =Y39+AE39+AK39+AQ39+AW39+BC39+BI39+BO39+BU39+CA39+CG39+CM39 -> 0 | T39: =Z39+AF39+AL39+AR39+AX39+BD39+BJ39+BP39+BV39+CB39+CH39+CN39 -> 0 | U39: =AA39+AG39+AM39+AS39+AY39+BE39+BK39+BQ39+BW39+CC39+CI39+CO39 -> 0
C40: مساعد اول طباعة | D40: الانتاج | E40: 31197 | F40: =DATEDIF(E40,TODAY(),"Y") -> 36 | G40: 5 | H40: 42406 | I40: =DATEDIF(H40,TODAY(),"M") -> 72 | J40: =IF(I40>6,"يستحق","لايستحق") -> يستحق | K40: =180+H40 -> 42586 | L40: 21 | N40: =W40+AC40+AI40+AO40+AU40+BA40+BG40+BM40+BS40+BY40+CE40+CK40 -> 0 | O40: =X40+AD40+AJ40+AP40+AV40+BB40+BH40+BN40+BT40+BZ40+CF40+CL40 -> 0 | P40: =N40+O40 -> 0 | Q40: =L40-P40 -> 21 | S40: =Y40+AE40+AK40+AQ40+AW40+BC40+BI40+BO40+BU40+CA40+CG40+CM40 -> 0 | T40: =Z40+AF40+AL40+AR40+AX40+BD40+BJ40+BP40+BV40+CB40+CH40+CN40 -> 0 | U40: =AA40+AG40+AM40+AS40+AY40+BE40+BK40+BQ40+BW40+CC40+CI40+CO40 -> 0
C41: مساعد تجليد | D41: الانتاج | E41: 25426 | F41: =DATEDIF(E41,TODAY(),"Y") -> 52 | G41: 8 | H41: 42381 | I41: =DATEDIF(H41,TODAY(),"M") -> 73 | J41: =IF(I41>6,"يستحق","لايستحق") -> يستحق | K41: =180+H41 -> 42561 | L41: 21 | N41: =W41+AC41+AI41+AO41+AU41+BA41+BG41+BM41+BS41+BY41+CE41+CK41 -> 0 | O41: =X41+AD41+AJ41+AP41+AV41+BB41+BH41+BN41+BT41+BZ41+CF41+CL41 -> 0 | P41: =N41+O41 -> 0 | Q41: =L41-P41 -> 21 | S41: =Y41+AE41+AK41+AQ41+AW41+BC41+BI41+BO41+BU41+CA41+CG41+CM41 -> 0 | T41: =Z41+AF41+AL41+AR41+AX41+BD41+BJ41+BP41+BV41+CB41+CH41+CN41 -> 0 | U41: =AA41+AG41+AM41+AS41+AY41+BE41+BK41+BQ41+BW41+CC41+CI41+CO41 -> 0
C42: مساعد تجليد | D42: الانتاج | E42: 21151 | F42: =DATEDIF(E42,TODAY(),"Y") -> 64 | H42: 43831 | I42: =DATEDIF(H42,TODAY(),"M") -> 26 | J42: =IF(I42>6,"يستحق","لايستحق") -> يستحق | K42: =180+H42 -> 44011 | L42: 21 | N42: =W42+AC42+AI42+AO42+AU42+BA42+BG42+BM42+BS42+BY42+CE42+CK42 -> 0 | O42: =X42+AD42+AJ42+AP42+AV42+BB42+BH42+BN42+BT42+BZ42+CF42+CL42 -> 0 | P42: =N42+O42 -> 0 | Q42: =L42-P42 -> 21 | S42: =Y42+AE42+AK42+AQ42+AW42+BC42+BI42+BO42+BU42+CA42+CG42+CM42 -> 0 | T42: =Z42+AF42+AL42+AR42+AX42+BD42+BJ42+BP42+BV42+CB42+CH42+CN42 -> 0 | U42: =AA42+AG42+AM42+AS42+AY42+BE42+BK42+BQ42+BW42+CC42+CI42+CO42 -> 0
C43: مساعد تجليد | D43: الانتاج | E43: 26003 | F43: =DATEDIF(E43,TODAY(),"Y") -> 50 | G43: 4 | H43: 44197 | I43: =DATEDIF(H43,TODAY(),"M") -> 14 | J43: =IF(I43>6,"يستحق","لايستحق") -> يستحق | K43: =180+H43 -> 44377 | L43: 21 | N43: =W43+AC43+AI43+AO43+AU43+BA43+BG43+BM43+BS43+BY43+CE43+CK43 -> 0 | O43: =X43+AD43+AJ43+AP43+AV43+BB43+BH43+BN43+BT43+BZ43+CF43+CL43 -> 0 | P43: =N43+O43 -> 0 | Q43: =L43-P43 -> 21 | S43: =Y43+AE43+AK43+AQ43+AW43+BC43+BI43+BO43+BU43+CA43+CG43+CM43 -> 0 | T43: =Z43+AF43+AL43+AR43+AX43+BD43+BJ43+BP43+BV43+CB43+CH43+CN43 -> 0 | U43: =AA43+AG43+AM43+AS43+AY43+BE43+BK43+BQ43+BW43+CC43+CI43+CO43 -> 0
C44: مساعد اول ماكينة ظرف الي | D44: الانتاج | E44: 33762 | F44: =DATEDIF(E44,TODAY(),"Y") -> 29 | G44: 3 | H44: 43104 | I44: =DATEDIF(H44,TODAY(),"M") -> 49 | J44: =IF(I44>6,"يستحق","لايستحق") -> يستحق | K44: =180+H44 -> 43284 | L44: 21 | N44: =W44+AC44+AI44+AO44+AU44+BA44+BG44+BM44+BS44+BY44+CE44+CK44 -> 0 | O44: =X44+AD44+AJ44+AP44+AV44+BB44+BH44+BN44+BT44+BZ44+CF44+CL44 -> 0 | P44: =N44+O44 -> 0 | Q44: =L44-P44 -> 21 | S44: =Y44+AE44+AK44+AQ44+AW44+BC44+BI44+BO44+BU44+CA44+CG44+CM44 -> 0 | T44: =Z44+AF44+AL44+AR44+AX44+BD44+BJ44+BP44+BV44+CB44+CH44+CN44 -> 0 | U44: =AA44+AG44+AM44+AS44+AY44+BE44+BK44+BQ44+BW44+CC44+CI44+CO44 -> 0
C45: مساعد تجليد | D45: الانتاج | E45: 37648 | F45: =DATEDIF(E45,TODAY(),"Y") -> 19 | G45: 1 | H45: 44197 | I45: =DATEDIF(H45,TODAY(),"M") -> 14 | J45: =IF(I45>6,"يستحق","لايستحق") -> يستحق | K45: =180+H45 -> 44377 | L45: 21 | N45: =W45+AC45+AI45+AO45+AU45+BA45+BG45+BM45+BS45+BY45+CE45+CK45 -> 0 | O45: =X45+AD45+AJ45+AP45+AV45+BB45+BH45+BN45+BT45+BZ45+CF45+CL45 -> 0 | P45: =N45+O45 -> 0 | Q45: =L45-P45 -> 21 | S45: =Y45+AE45+AK45+AQ45+AW45+BC45+BI45+BO45+BU45+CA45+CG45+CM45 -> 0 | T45: =Z45+AF45+AL45+AR45+AX45+BD45+BJ45+BP45+BV45+CB45+CH45+CN45 -> 0 | U45: =AA45+AG45+AM45+AS45+AY45+BE45+BK45+BQ45+BW45+CC45+CI45+CO45 -> 0
C46: عامل مكبس | D46: الانتاج | E46: 32407 | F46: =DATEDIF(E46,TODAY(),"Y") -> 33 | G46: 1 | H46: 44197 | I46: =DATEDIF(H46,TODAY(),"M") -> 14 | J46: =IF(I46>6,"يستحق","لايستحق") -> يستحق | K46: =180+H46 -> 44377 | L46: 21 | N46: =W46+AC46+AI46+AO46+AU46+BA46+BG46+BM46+BS46+BY46+CE46+CK46 -> 0 | O46: =X46+AD46+AJ46+AP46+AV46+BB46+BH46+BN46+BT46+BZ46+CF46+CL46 -> 0 | P46: =N46+O46 -> 0 | Q46: =L46-P46 -> 21 | S46: =Y46+AE46+AK46+AQ46+AW46+BC46+BI46+BO46+BU46+CA46+CG46+CM46 -> 0 | T46: =Z46+AF46+AL46+AR46+AX46+BD46+BJ46+BP46+BV46+CB46+CH46+CN46 -> 0 | U46: =AA46+AG46+AM46+AS46+AY46+BE46+BK46+BQ46+BW46+CC46+CI46+CO46 -> 0
C47: مساعد طباعة | D47: الانتاج | E47: 35423 | F47: =DATEDIF(E47,TODAY(),"Y") -> 25 | G47: 2 | H47: 43971 | I47: =DATEDIF(H47,TODAY(),"M") -> 21 | J47: =IF(I47>6,"يستحق","لايستحق") -> يستحق | K47: =180+H47 -> 44151 | L47: 21 | N47: =W47+AC47+AI47+AO47+AU47+BA47+BG47+BM47+BS47+BY47+CE47+CK47 -> 0 | O47: =X47+AD47+AJ47+AP47+AV47+BB47+BH47+BN47+BT47+BZ47+CF47+CL47 -> 0 | P47: =N47+O47 -> 0 | Q47: =L47-P47 -> 21 | S47: =Y47+AE47+AK47+AQ47+AW47+BC47+BI47+BO47+BU47+CA47+CG47+CM47 -> 0 | T47: =Z47+AF47+AL47+AR47+AX47+BD47+BJ47+BP47+BV47+CB47+CH47+CN47 -> 0 | U47: =AA47+AG47+AM47+AS47+AY47+BE47+BK47+BQ47+BW47+CC47+CI47+CO47 -> 0
C48: مساعد تجليد | D48: الانتاج | E48: 34591 | F48: =DATEDIF(E48,TODAY(),"Y") -> 27 | G48: 1 | H48: 44197 | I48: =DATEDIF(H48,TODAY(),"M") -> 14 | J48: =IF(I48>6,"يستحق","لايستحق") -> يستحق | K48: =180+H48 -> 44377 | L48: 21 | N48: =W48+AC48+AI48+AO48+AU48+BA48+BG48+BM48+BS48+BY48+CE48+CK48 -> 0 | O48: =X48+AD48+AJ48+AP48+AV48+BB48+BH48+BN48+BT48+BZ48+CF48+CL48 -> 0 | P48: =N48+O48 -> 0 | Q48: =L48-P48 -> 21 | S48: =Y48+AE48+AK48+AQ48+AW48+BC48+BI48+BO48+BU48+CA48+CG48+CM48 -> 0 | T48: =Z48+AF48+AL48+AR48+AX48+BD48+BJ48+BP48+BV48+CB48+CH48+CN48 -> 0 | U48: =AA48+AG48+AM48+AS48+AY48+BE48+BK48+BQ48+BW48+CC48+CI48+CO48 -> 0
C49: مساعد تكسير | D49: الانتاج | E49: 36916 | F49: =DATEDIF(E49,TODAY(),"Y") -> 21 | G49: 1 | H49: 44197 | I49: =DATEDIF(H49,TODAY(),"M") -> 14 | J49: =IF(I49>6,"يستحق","لايستحق") -> يستحق | K49: =180+H49 -> 44377 | L49: 21 | N49: =W49+AC49+AI49+AO49+AU49+BA49+BG49+BM49+BS49+BY49+CE49+CK49 -> 0 | O49: =X49+AD49+AJ49+AP49+AV49+BB49+BH49+BN49+BT49+BZ49+CF49+CL49 -> 0 | P49: =N49+O49 -> 0 | Q49: =L49-P49 -> 21 | S49: =Y49+AE49+AK49+AQ49+AW49+BC49+BI49+BO49+BU49+CA49+CG49+CM49 -> 0 | T49: =Z49+AF49+AL49+AR49+AX49+BD49+BJ49+BP49+BV49+CB49+CH49+CN49 -> 0 | U49: =AA49+AG49+AM49+AS49+AY49+BE49+BK49+BQ49+BW49+CC49+CI49+CO49 -> 0
C50: امين مخزن | D50: الانتاج | E50: 35317 | F50: =DATEDIF(E50,TODAY(),"Y") -> 25 | G50: 1 | H50: 44228 | I50: =DATEDIF(H50,TODAY(),"M") -> 13 | J50: =IF(I50>6,"يستحق","لايستحق") -> يستحق | K50: =180+H50 -> 44408 | L50: 21 | N50: =W50+AC50+AI50+AO50+AU50+BA50+BG50+BM50+BS50+BY50+CE50+CK50 -> 0 | O50: =X50+AD50+AJ50+AP50+AV50+BB50+BH50+BN50+BT50+BZ50+CF50+CL50 -> 0 | P50: =N50+O50 -> 0 | Q50: =L50-P50 -> 21 | S50: =Y50+AE50+AK50+AQ50+AW50+BC50+BI50+BO50+BU50+CA50+CG50+CM50 -> 0 | T50: =Z50+AF50+AL50+AR50+AX50+BD50+BJ50+BP50+BV50+CB50+CH50+CN50 -> 0 | U50: =AA50+AG50+AM50+AS50+AY50+BE50+BK50+BQ50+BW50+CC50+CI50+CO50 -> 0
C51: مساعد طباعة | D51: الانتاج | E51: 31238 | F51: =DATEDIF(E51,TODAY(),"Y") -> 36 | G51: 1 | H51: 44228 | I51: =DATEDIF(H51,TODAY(),"M") -> 13 | J51: =IF(I51>6,"يستحق","لايستحق") -> يستحق | K51: =180+H51 -> 44408 | L51: 21 | N51: =W51+AC51+AI51+AO51+AU51+BA51+BG51+BM51+BS51+BY51+CE51+CK51 -> 0 | O51: =X51+AD51+AJ51+AP51+AV51+BB51+BH51+BN51+BT51+BZ51+CF51+CL51 -> 0 | P51: =N51+O51 -> 0 | Q51: =L51-P51 -> 21 | S51: =Y51+AE51+AK51+AQ51+AW51+BC51+BI51+BO51+BU51+CA51+CG51+CM51 -> 0 | T51: =Z51+AF51+AL51+AR51+AX51+BD51+BJ51+BP51+BV51+CB51+CH51+CN51 -> 0 | U51: =AA51+AG51+AM51+AS51+AY51+BE51+BK51+BQ51+BW51+CC51+CI51+CO51 -> 0
...

Sheet كارت رصيد الاجازات 
C4: كارت رصيد الاجازات
K5: عودة
A8: رقم الموظف | C8: 1008
A10: الاسم | C10: =VLOOKUP(C8,'برنامج الاجازات '!A5:B100,2,0) -> #N/A
A12: المسمي الوظيفي | C12: =VLOOKUP(C8,'برنامج الاجازات '!A5:C100,3,0) -> #N/A | F12: الادارة / المشروع | H12: =VLOOKUP(C8,'برنامج الاجازات '!A5:D100,4,0) -> #N/A
A14: تاريخ التعيين | C14: =VLOOKUP(C8,'برنامج الاجازات '!A5:H100,8,0) -> #N/A | F14: تاريخ استحقاق الرصيد السنوى | H14: =VLOOKUP(C8,'برنامج الاجازات '!A5:K100,11,0) -> #N/A
A16: الرصيد السنوي | C16: =VLOOKUP(C8,'برنامج الاجازات '!A5:L100,12,0) -> #N/A
A18: رصيد الاعتيادى المستهلك | I18: =VLOOKUP(C8,'برنامج الاجازات '!A5:N100,14,0) -> #N/A
A19: رصيد العارضة المستهلك | I19: =VLOOKUP(C8,'برنامج الاجازات '!A5:O100,15,0) -> #N/A
A20: اجازة بدل راحة | I20: =VLOOKUP(C8,'برنامج الاجازات '!A5:T100,20,0) -> #N/A
A21: اجازة مرضي | I21: =VLOOKUP(C8,'برنامج الاجازات '!A5:S100,19,0) -> #N/A
A22: اجازة بدون أجر | I22: =VLOOKUP(C8,'برنامج الاجازات '!A5:U100,21,0) -> #N/A
C24: باقي رصيد الاجازات | I24: =C16-(SUM(I18:I19)) -> #N/A
