Workbook

Sheet الرئيسية
B2: Costing | D2: الكارت المعياري | H2: The production plan | M2: الخطة الانتاجية
B4: Sheet
B7: ساعة | D7: ساعات العمل | H7: ساعات | I7: الطاقة | J7: اسم الصنف | L7: رقم | N7: ساعات | O7: الطاقة | P7: اسم الصنف | R7: رقم
B9: يوم | D9: أيـــــام الشهر | H9: التشغيل | I9: المتاحة | N9: التشغيل | O9: المتاحة
L10: 1 | R10: 6
B11: صنف | D11: عدد الاصناف
L14: 2 | R14: 7
L18: 3 | R18: 8
L22: 4 | R22: 9
L26: 5 | R26: 10
H32: =SUM(H10:H29)+SUM(N10:N29) -> 0 | N32: إجمالي عدد ساعات التشغيل لجميع الاصناف

Sheet اجمالي التكاليف خلال الفترة
B2: إجمالي التكاليف خلال الفترة
B4: التكاليف الغير مباشرة الثابتة | E4: التكاليف الغير مباشرة المتغيرة | H4: الأجور التشغيلية
B5: إجمالي التكلفة | C5: الحساب | E5: إجمالي التكلفة | F5: الحساب | H5: إجمالي التكلفة | I5: الحساب
C6: تكلفة ثابتة 1 | F6: تكلفة متغيرة 1 | I6: الاجور الثابتة
C7: تكلفة ثابتة 2 | F7: تكلفة متغيرة 2 | I7: الاجور المتغيرة
C8: تكلفة ثابتة 3 | F8: تكلفة متغيرة 3
C9: تكلفة ثابتة 4 | F9: تكلفة متغيرة 4 | H9: المواد الخام المباشرة للوحدة الواحدة
C10: تكلفة ثابتة 5 | F10: تكلفة متغيرة 5 | H10: التكلفة الوحدة | I10: الحساب
C11: تكلفة ثابتة 6 | F11: تكلفة متغيرة 6 | I11: خام 1
C12: تكلفة ثابتة 7 | F12: تكلفة متغيرة 7 | I12: خام 2
C13: تكلفة ثابتة 8 | F13: تكلفة متغيرة 8 | I13: خام 3
C14: تكلفة ثابتة 9 | F14: تكلفة متغيرة 9 | I14: خام 4
C15: تكلفة ثابتة 10 | F15: تكلفة متغيرة 10 | I15: خام 5

Sheet اهلاك خطوط الانتاج
B2: في الساعة | C2: =B14 -> 0 | D2: اهلاك خط الانتاج
E4: شهر | F4: 12 | G4: السنة
E5: يوم | F5: 30 | G5: الشهر
E6: ساعة | F6: 16 | G6: التشغيل
B8: قيمة أهلاك خطوط الانتاج خلال الفترات | F8: % | G8: قيمة | H8: العمر الانتاجي | I8: اسم
B9: في الساعة الواحدة | C9: اليومي | D9: الشهري | E9: السنوي | G9: الاصل | H9: سنوياً | I9: الخط
B10: =C10/$F$6 -> 0 | C10: =D10/$F$5 -> 0 | D10: =E10/$F$4 -> 0 | E10: =G10*F10 -> 0 | F10: =1/H10 -> 0.05 | H10: 20 | I10: خط 1
B11: =C11/$F$6 -> 0 | C11: =D11/$F$5 -> 0 | D11: =E11/$F$4 -> 0 | E11: =G11*F11 -> 0 | F11: =1/H11 -> 0.2 | H11: 5 | I11: خط 2
B12: =C12/$F$6 -> 0 | C12: =D12/$F$5 -> 0 | D12: =E12/$F$4 -> 0 | E12: =G12*F12 -> 0 | F12: =1/H12 -> 0.1 | H12: 10 | I12: خط 3
B13: =C13/$F$6 -> 0 | C13: =D13/$F$5 -> 0 | D13: =E13/$F$4 -> 0 | E13: =G13*F13 -> 0 | F13: =1/H13 -> 0.033333333 | H13: 30 | I13: خط 4
B14: =SUM(B10:B13) -> 0 | C14: =SUM(C10:C13) -> 0 | D14: =SUM(D10:D13) -> 0 | E14: =SUM(E10:E13) -> 0 | G14: =SUM(G10:G13) -> 0 | H14: =SUM(H10:H13) -> 65 | I14: الإجمالي

Sheet توزيع التكاليف
B1: توزيعات التكاليف على عناصر اصناف المخزون طبقاً لعدد ساعات التشغيل
B3: الصنف | C3: 1 | D3: 2 | E3: 3 | F3: 4 | G3: 5 | H3: 6 | I3: 7 | J3: 8 | K3: 9 | L3: 10 | M3: =SUM(C6:L6) -> #DIV/0!
B4: الاسم | C4: =الرئيسية!J10 -> 0 | D4: =الرئيسية!J14 -> 0 | E4: =الرئيسية!J18 -> 0 | F4: =الرئيسية!J22 -> 0 | G4: =الرئيسية!J26 -> 0 | H4: =الرئيسية!P10 -> 0 | I4: =الرئيسية!P14 -> 0 | J4: =الرئيسية!P18 -> 0 | K4: =الرئيسية!P22 -> 0 | L4: =الرئيسية!P26 -> 0
B6: % نسب التوزيع | C6: =الرئيسية!H10/الرئيسية!$H$32 -> #DIV/0! | D6: =الرئيسية!H14/الرئيسية!$H$32 -> #DIV/0! | E6: =الرئيسية!H18/الرئيسية!$H$32 -> #DIV/0! | F6: =الرئيسية!H22/الرئيسية!$H$32 -> #DIV/0! | G6: =الرئيسية!H26/الرئيسية!$H$32 -> #DIV/0! | H6: =الرئيسية!N10/الرئيسية!$H$32 -> #DIV/0! | I6: =الرئيسية!N14/الرئيسية!$H$32 -> #DIV/0! | J6: =الرئيسية!N18/الرئيسية!$H$32 -> #DIV/0! | K6: =الرئيسية!N22/الرئيسية!$H$32 -> #DIV/0! | L6: =الرئيسية!N26/الرئيسية!$H$32 -> #DIV/0!
B8: إجمالي الاجور التشغيلية | C8: =C10+C9 -> #DIV/0! | D8: =D10+D9 -> #DIV/0! | E8: =E10+E9 -> #DIV/0! | F8: =F10+F9 -> #DIV/0! | G8: =G10+G9 -> #DIV/0! | H8: =H10+H9 -> #DIV/0! | I8: =I10+I9 -> #DIV/0! | J8: =J10+J9 -> #DIV/0! | ... L8: =L10+L9 -> #DIV/0! | M8: =SUM(C8:L8) -> #DIV/0!
B9: الاجور المتغيرة | C9: ='اجمالي التكاليف خلال الفترة'!$H$7*C6 -> #DIV/0! | D9: ='اجمالي التكاليف خلال الفترة'!$H$7*D6 -> #DIV/0! | E9: ='اجمالي التكاليف خلال الفترة'!$H$7*E6 -> #DIV/0! | F9: ='اجمالي التكاليف خلال الفترة'!$H$7*F6 -> #DIV/0! | G9: ='اجمالي التكاليف خلال الفترة'!$H$7*G6 -> #DIV/0! | H9: ='اجمالي التكاليف خلال الفترة'!$H$7*H6 -> #DIV/0! | I9: ='اجمالي التكاليف خلال الفترة'!$H$7*I6 -> #DIV/0! | J9: ='اجمالي التكاليف خلال الفترة'!$H$7*J6 -> #DIV/0! | ... L9: ='اجمالي التكاليف خلال الفترة'!$H$7*L6 -> #DIV/0! | M9: =SUM(C9:L9) -> #DIV/0!
B10: الاجور الثابتة | C10: ='اجمالي التكاليف خلال الفترة'!$H$6*C6 -> #DIV/0! | D10: ='اجمالي التكاليف خلال الفترة'!$H$6*D6 -> #DIV/0! | E10: ='اجمالي التكاليف خلال الفترة'!$H$6*E6 -> #DIV/0! | F10: ='اجمالي التكاليف خلال الفترة'!$H$6*F6 -> #DIV/0! | G10: ='اجمالي التكاليف خلال الفترة'!$H$6*G6 -> #DIV/0! | H10: ='اجمالي التكاليف خلال الفترة'!$H$6*H6 -> #DIV/0! | I10: ='اجمالي التكاليف خلال الفترة'!$H$6*I6 -> #DIV/0! | J10: ='اجمالي التكاليف خلال الفترة'!$H$6*J6 -> #DIV/0! | ... L10: ='اجمالي التكاليف خلال الفترة'!$H$6*L6 -> #DIV/0! | M10: =SUM(C10:L10) -> #DIV/0!
B12: إجمالي ت.غ.م المتغيرة | C12: =SUM(C13:C22) -> #DIV/0! | D12: =SUM(D13:D22) -> #DIV/0! | E12: =SUM(E13:E22) -> #DIV/0! | F12: =SUM(F13:F22) -> #DIV/0! | G12: =SUM(G13:G22) -> #DIV/0! | H12: =SUM(H13:H22) -> #DIV/0! | I12: =SUM(I13:I22) -> #DIV/0! | J12: =SUM(J13:J22) -> #DIV/0! | ... L12: =SUM(L13:L22) -> #DIV/0! | M12: =SUM(C12:L12) -> #DIV/0!
B13: ='اجمالي التكاليف خلال الفترة'!F6 -> تكلفة متغيرة 1 | C13: ='اجمالي التكاليف خلال الفترة'!$E$6*C6 -> #DIV/0! | D13: ='اجمالي التكاليف خلال الفترة'!$E$6*D6 -> #DIV/0! | E13: ='اجمالي التكاليف خلال الفترة'!$E$6*E6 -> #DIV/0! | F13: ='اجمالي التكاليف خلال الفترة'!$E$6*F6 -> #DIV/0! | G13: ='اجمالي التكاليف خلال الفترة'!$E$6*G6 -> #DIV/0! | H13: ='اجمالي التكاليف خلال الفترة'!$E$6*H6 -> #DIV/0! | I13: ='اجمالي التكاليف خلال الفترة'!$E$6*I6 -> #DIV/0! | J13: ='اجمالي التكاليف خلال الفترة'!$E$6*J6 -> #DIV/0! | ... L13: ='اجمالي التكاليف خلال الفترة'!$E$6*L6 -> #DIV/0! | M13: =SUM(C13:L13) -> #DIV/0!
B14: ='اجمالي التكاليف خلال الفترة'!F7 -> تكلفة متغيرة 2 | C14: ='اجمالي التكاليف خلال الفترة'!$E$7*C6 -> #DIV/0! | D14: ='اجمالي التكاليف خلال الفترة'!$E$7*D6 -> #DIV/0! | E14: ='اجمالي التكاليف خلال الفترة'!$E$7*E6 -> #DIV/0! | F14: ='اجمالي التكاليف خلال الفترة'!$E$7*F6 -> #DIV/0! | G14: ='اجمالي التكاليف خلال الفترة'!$E$7*G6 -> #DIV/0! | H14: ='اجمالي التكاليف خلال الفترة'!$E$7*H6 -> #DIV/0! | I14: ='اجمالي التكاليف خلال الفترة'!$E$7*I6 -> #DIV/0! | J14: ='اجمالي التكاليف خلال الفترة'!$E$7*J6 -> #DIV/0! | ... L14: ='اجمالي التكاليف خلال الفترة'!$E$7*L6 -> #DIV/0! | M14: =SUM(C14:L14) -> #DIV/0!
B15: ='اجمالي التكاليف خلال الفترة'!F8 -> تكلفة متغيرة 3 | C15: ='اجمالي التكاليف خلال الفترة'!$E$8*C6 -> #DIV/0! | D15: ='اجمالي التكاليف خلال الفترة'!$E$8*D6 -> #DIV/0! | E15: ='اجمالي التكاليف خلال الفترة'!$E$8*E6 -> #DIV/0! | F15: ='اجمالي التكاليف خلال الفترة'!$E$8*F6 -> #DIV/0! | G15: ='اجمالي التكاليف خلال الفترة'!$E$8*G6 -> #DIV/0! | H15: ='اجمالي التكاليف خلال الفترة'!$E$8*H6 -> #DIV/0! | I15: ='اجمالي التكاليف خلال الفترة'!$E$8*I6 -> #DIV/0! | J15: ='اجمالي التكاليف خلال الفترة'!$E$8*J6 -> #DIV/0! | ... L15: ='اجمالي التكاليف خلال الفترة'!$E$8*L6 -> #DIV/0! | M15: =SUM(C15:L15) -> #DIV/0!
B16: ='اجمالي التكاليف خلال الفترة'!F9 -> تكلفة متغيرة 4 | C16: ='اجمالي التكاليف خلال الفترة'!$E$9*C6 -> #DIV/0! | D16: ='اجمالي التكاليف خلال الفترة'!$E$9*D6 -> #DIV/0! | E16: ='اجمالي التكاليف خلال الفترة'!$E$9*E6 -> #DIV/0! | F16: ='اجمالي التكاليف خلال الفترة'!$E$9*F6 -> #DIV/0! | G16: ='اجمالي التكاليف خلال الفترة'!$E$9*G6 -> #DIV/0! | H16: ='اجمالي التكاليف خلال الفترة'!$E$9*H6 -> #DIV/0! | I16: ='اجمالي التكاليف خلال الفترة'!$E$9*I6 -> #DIV/0! | J16: ='اجمالي التكاليف خلال الفترة'!$E$9*J6 -> #DIV/0! | ... L16: ='اجمالي التكاليف خلال الفترة'!$E$9*L6 -> #DIV/0! | M16: =SUM(C16:L16) -> #DIV/0!
B17: ='اجمالي التكاليف خلال الفترة'!F10 -> تكلفة متغيرة 5 | C17: ='اجمالي التكاليف خلال الفترة'!$E$10*C6 -> #DIV/0! | D17: ='اجمالي التكاليف خلال الفترة'!$E$10*D6 -> #DIV/0! | E17: ='اجمالي التكاليف خلال الفترة'!$E$10*E6 -> #DIV/0! | F17: ='اجمالي التكاليف خلال الفترة'!$E$10*F6 -> #DIV/0! | G17: ='اجمالي التكاليف خلال الفترة'!$E$10*G6 -> #DIV/0! | H17: ='اجمالي التكاليف خلال الفترة'!$E$10*H6 -> #DIV/0! | I17: ='اجمالي التكاليف خلال الفترة'!$E$10*I6 -> #DIV/0! | J17: ='اجمالي التكاليف خلال الفترة'!$E$10*J6 -> #DIV/0! | ... L17: ='اجمالي التكاليف خلال الفترة'!$E$10*L6 -> #DIV/0! | M17: =SUM(C17:L17) -> #DIV/0!
B18: ='اجمالي التكاليف خلال الفترة'!F11 -> تكلفة متغيرة 6 | C18: ='اجمالي التكاليف خلال الفترة'!$E$11*C6 -> #DIV/0! | D18: ='اجمالي التكاليف خلال الفترة'!$E$11*D6 -> #DIV/0! | E18: ='اجمالي التكاليف خلال الفترة'!$E$11*E6 -> #DIV/0! | F18: ='اجمالي التكاليف خلال الفترة'!$E$11*F6 -> #DIV/0! | G18: ='اجمالي التكاليف خلال الفترة'!$E$11*G6 -> #DIV/0! | H18: ='اجمالي التكاليف خلال الفترة'!$E$11*H6 -> #DIV/0! | I18: ='اجمالي التكاليف خلال الفترة'!$E$11*I6 -> #DIV/0! | J18: ='اجمالي التكاليف خلال الفترة'!$E$11*J6 -> #DIV/0! | ... L18: ='اجمالي التكاليف خلال الفترة'!$E$11*L6 -> #DIV/0! | M18: =SUM(C18:L18) -> #DIV/0!
B19: ='اجمالي التكاليف خلال الفترة'!F12 -> تكلفة متغيرة 7 | C19: ='اجمالي التكاليف خلال الفترة'!$E$12*C6 -> #DIV/0! | D19: ='اجمالي التكاليف خلال الفترة'!$E$12*D6 -> #DIV/0! | E19: ='اجمالي التكاليف خلال الفترة'!$E$12*E6 -> #DIV/0! | F19: ='اجمالي التكاليف خلال الفترة'!$E$12*F6 -> #DIV/0! | G19: ='اجمالي التكاليف خلال الفترة'!$E$12*G6 -> #DIV/0! | H19: ='اجمالي التكاليف خلال الفترة'!$E$12*H6 -> #DIV/0! | I19: ='اجمالي التكاليف خلال الفترة'!$E$12*I6 -> #DIV/0! | J19: ='اجمالي التكاليف خلال الفترة'!$E$12*J6 -> #DIV/0! | ... L19: ='اجمالي التكاليف خلال الفترة'!$E$12*L6 -> #DIV/0! | M19: =SUM(C19:L19) -> #DIV/0!
B20: ='اجمالي التكاليف خلال الفترة'!F13 -> تكلفة متغيرة 8 | C20: ='اجمالي التكاليف خلال الفترة'!$E$13*C6 -> #DIV/0! | D20: ='اجمالي التكاليف خلال الفترة'!$E$13*D6 -> #DIV/0! | E20: ='اجمالي التكاليف خلال الفترة'!$E$13*E6 -> #DIV/0! | F20: ='اجمالي التكاليف خلال الفترة'!$E$13*F6 -> #DIV/0! | G20: ='اجمالي التكاليف خلال الفترة'!$E$13*G6 -> #DIV/0! | H20: ='اجمالي التكاليف خلال الفترة'!$E$13*H6 -> #DIV/0! | I20: ='اجمالي التكاليف خلال الفترة'!$E$13*I6 -> #DIV/0! | J20: ='اجمالي التكاليف خلال الفترة'!$E$13*J6 -> #DIV/0! | ... L20: ='اجمالي التكاليف خلال الفترة'!$E$13*L6 -> #DIV/0! | M20: =SUM(C20:L20) -> #DIV/0!
B21: ='اجمالي التكاليف خلال الفترة'!F14 -> تكلفة متغيرة 9 | C21: ='اجمالي التكاليف خلال الفترة'!$E$14*C6 -> #DIV/0! | D21: ='اجمالي التكاليف خلال الفترة'!$E$14*D6 -> #DIV/0! | E21: ='اجمالي التكاليف خلال الفترة'!$E$14*E6 -> #DIV/0! | F21: ='اجمالي التكاليف خلال الفترة'!$E$14*F6 -> #DIV/0! | G21: ='اجمالي التكاليف خلال الفترة'!$E$14*G6 -> #DIV/0! | H21: ='اجمالي التكاليف خلال الفترة'!$E$14*H6 -> #DIV/0! | I21: ='اجمالي التكاليف خلال الفترة'!$E$14*I6 -> #DIV/0! | J21: ='اجمالي التكاليف خلال الفترة'!$E$14*J6 -> #DIV/0! | ... L21: ='اجمالي التكاليف خلال الفترة'!$E$14*L6 -> #DIV/0! | M21: =SUM(C21:L21) -> #DIV/0!
B22: ='اجمالي التكاليف خلال الفترة'!F15 -> تكلفة متغيرة 10 | C22: ='اجمالي التكاليف خلال الفترة'!$E$15*C6 -> #DIV/0! | D22: ='اجمالي التكاليف خلال الفترة'!$E$15*D6 -> #DIV/0! | E22: ='اجمالي التكاليف خلال الفترة'!$E$15*E6 -> #DIV/0! | F22: ='اجمالي التكاليف خلال الفترة'!$E$15*F6 -> #DIV/0! | G22: ='اجمالي التكاليف خلال الفترة'!$E$15*G6 -> #DIV/0! | H22: ='اجمالي التكاليف خلال الفترة'!$E$15*H6 -> #DIV/0! | I22: ='اجمالي التكاليف خلال الفترة'!$E$15*I6 -> #DIV/0! | J22: ='اجمالي التكاليف خلال الفترة'!$E$15*J6 -> #DIV/0! | ... L22: ='اجمالي التكاليف خلال الفترة'!$E$15*L6 -> #DIV/0! | M22: =SUM(C22:L22) -> #DIV/0!
B24: إجمالي ت.غ.م الثابتة | C24: =SUM(C25:C34) -> #DIV/0! | D24: =SUM(D25:D34) -> #DIV/0! | E24: =SUM(E25:E34) -> #DIV/0! | F24: =SUM(F25:F34) -> #DIV/0! | G24: =SUM(G25:G34) -> #DIV/0! | H24: =SUM(H25:H34) -> #DIV/0! | I24: =SUM(I25:I34) -> #DIV/0! | J24: =SUM(J25:J34) -> #DIV/0! | ... L24: =SUM(L25:L34) -> #DIV/0! | M24: =SUM(C24:L24) -> #DIV/0!
B25: ='اجمالي التكاليف خلال الفترة'!C6 -> تكلفة ثابتة 1 | C25: ='اجمالي التكاليف خلال الفترة'!$B$6*C6 -> #DIV/0! | D25: ='اجمالي التكاليف خلال الفترة'!$B$6*D6 -> #DIV/0! | E25: ='اجمالي التكاليف خلال الفترة'!$B$6*E6 -> #DIV/0! | F25: ='اجمالي التكاليف خلال الفترة'!$B$6*F6 -> #DIV/0! | G25: ='اجمالي التكاليف خلال الفترة'!$B$6*G6 -> #DIV/0! | H25: ='اجمالي التكاليف خلال الفترة'!$B$6*H6 -> #DIV/0! | I25: ='اجمالي التكاليف خلال الفترة'!$B$6*I6 -> #DIV/0! | J25: ='اجمالي التكاليف خلال الفترة'!$B$6*J6 -> #DIV/0! | ... L25: ='اجمالي التكاليف خلال الفترة'!$B$6*L6 -> #DIV/0! | M25: =SUM(C25:L25) -> #DIV/0!
B26: ='اجمالي التكاليف خلال الفترة'!C7 -> تكلفة ثابتة 2 | C26: ='اجمالي التكاليف خلال الفترة'!$B$7*C6 -> #DIV/0! | D26: ='اجمالي التكاليف خلال الفترة'!$B$7*D6 -> #DIV/0! | E26: ='اجمالي التكاليف خلال الفترة'!$B$7*E6 -> #DIV/0! | F26: ='اجمالي التكاليف خلال الفترة'!$B$7*F6 -> #DIV/0! | G26: ='اجمالي التكاليف خلال الفترة'!$B$7*G6 -> #DIV/0! | H26: ='اجمالي التكاليف خلال الفترة'!$B$7*H6 -> #DIV/0! | I26: ='اجمالي التكاليف خلال الفترة'!$B$7*I6 -> #DIV/0! | J26: ='اجمالي التكاليف خلال الفترة'!$B$7*J6 -> #DIV/0! | ... L26: ='اجمالي التكاليف خلال الفترة'!$B$7*L6 -> #DIV/0! | M26: =SUM(C26:L26) -> #DIV/0!
B27: ='اجمالي التكاليف خلال الفترة'!C8 -> تكلفة ثابتة 3 | C27: ='اجمالي التكاليف خلال الفترة'!$B$8*C6 -> #DIV/0! | D27: ='اجمالي التكاليف خلال الفترة'!$B$8*D6 -> #DIV/0! | E27: ='اجمالي التكاليف خلال الفترة'!$B$8*E6 -> #DIV/0! | F27: ='اجمالي التكاليف خلال الفترة'!$B$8*F6 -> #DIV/0! | G27: ='اجمالي التكاليف خلال الفترة'!$B$8*G6 -> #DIV/0! | H27: ='اجمالي التكاليف خلال الفترة'!$B$8*H6 -> #DIV/0! | I27: ='اجمالي التكاليف خلال الفترة'!$B$8*I6 -> #DIV/0! | J27: ='اجمالي التكاليف خلال الفترة'!$B$8*J6 -> #DIV/0! | ... L27: ='اجمالي التكاليف خلال الفترة'!$B$8*L6 -> #DIV/0! | M27: =SUM(C27:L27) -> #DIV/0!
B28: ='اجمالي التكاليف خلال الفترة'!C9 -> تكلفة ثابتة 4 | C28: ='اجمالي التكاليف خلال الفترة'!$B$9*C6 -> #DIV/0! | D28: ='اجمالي التكاليف خلال الفترة'!$B$9*D6 -> #DIV/0! | E28: ='اجمالي التكاليف خلال الفترة'!$B$9*E6 -> #DIV/0! | F28: ='اجمالي التكاليف خلال الفترة'!$B$9*F6 -> #DIV/0! | G28: ='اجمالي التكاليف خلال الفترة'!$B$9*G6 -> #DIV/0! | H28: ='اجمالي التكاليف خلال الفترة'!$B$9*H6 -> #DIV/0! | I28: ='اجمالي التكاليف خلال الفترة'!$B$9*I6 -> #DIV/0! | J28: ='اجمالي التكاليف خلال الفترة'!$B$9*J6 -> #DIV/0! | ... L28: ='اجمالي التكاليف خلال الفترة'!$B$9*L6 -> #DIV/0! | M28: =SUM(C28:L28) -> #DIV/0!
B29: ='اجمالي التكاليف خلال الفترة'!C10 -> تكلفة ثابتة 5 | C29: ='اجمالي التكاليف خلال الفترة'!$B$10*C6 -> #DIV/0! | D29: ='اجمالي التكاليف خلال الفترة'!$B$10*D6 -> #DIV/0! | E29: ='اجمالي التكاليف خلال الفترة'!$B$10*E6 -> #DIV/0! | F29: ='اجمالي التكاليف خلال الفترة'!$B$10*F6 -> #DIV/0! | G29: ='اجمالي التكاليف خلال الفترة'!$B$10*G6 -> #DIV/0! | H29: ='اجمالي التكاليف خلال الفترة'!$B$10*H6 -> #DIV/0! | I29: ='اجمالي التكاليف خلال الفترة'!$B$10*I6 -> #DIV/0! | J29: ='اجمالي التكاليف خلال الفترة'!$B$10*J6 -> #DIV/0! | ... L29: ='اجمالي التكاليف خلال الفترة'!$B$10*L6 -> #DIV/0! | M29: =SUM(C29:L29) -> #DIV/0!
B30: ='اجمالي التكاليف خلال الفترة'!C11 -> تكلفة ثابتة 6 | C30: ='اجمالي التكاليف خلال الفترة'!$B$11*C6 -> #DIV/0! | D30: ='اجمالي التكاليف خلال الفترة'!$B$11*D6 -> #DIV/0! | E30: ='اجمالي التكاليف خلال الفترة'!$B$11*E6 -> #DIV/0! | F30: ='اجمالي التكاليف خلال الفترة'!$B$11*F6 -> #DIV/0! | G30: ='اجمالي التكاليف خلال الفترة'!$B$11*G6 -> #DIV/0! | H30: ='اجمالي التكاليف خلال الفترة'!$B$11*H6 -> #DIV/0! | I30: ='اجمالي التكاليف خلال الفترة'!$B$11*I6 -> #DIV/0! | J30: ='اجمالي التكاليف خلال الفترة'!$B$11*J6 -> #DIV/0! | ... L30: ='اجمالي التكاليف خلال الفترة'!$B$11*L6 -> #DIV/0! | M30: =SUM(C30:L30) -> #DIV/0!
B31: ='اجمالي التكاليف خلال الفترة'!C12 -> تكلفة ثابتة 7 | C31: ='اجمالي التكاليف خلال الفترة'!$B$12*C6 -> #DIV/0! | D31: ='اجمالي التكاليف خلال الفترة'!$B$12*D6 -> #DIV/0! | E31: ='اجمالي التكاليف خلال الفترة'!$B$12*E6 -> #DIV/0! | F31: ='اجمالي التكاليف خلال الفترة'!$B$12*F6 -> #DIV/0! | G31: ='اجمالي التكاليف خلال الفترة'!$B$12*G6 -> #DIV/0! | H31: ='اجمالي التكاليف خلال الفترة'!$B$12*H6 -> #DIV/0! | I31: ='اجمالي التكاليف خلال الفترة'!$B$12*I6 -> #DIV/0! | J31: ='اجمالي التكاليف خلال الفترة'!$B$12*J6 -> #DIV/0! | ... L31: ='اجمالي التكاليف خلال الفترة'!$B$12*L6 -> #DIV/0! | M31: =SUM(C31:L31) -> #DIV/0!
B32: ='اجمالي التكاليف خلال الفترة'!C13 -> تكلفة ثابتة 8 | C32: ='اجمالي التكاليف خلال الفترة'!$B$13*C6 -> #DIV/0! | D32: ='اجمالي التكاليف خلال الفترة'!$B$13*D6 -> #DIV/0! | E32: ='اجمالي التكاليف خلال الفترة'!$B$13*E6 -> #DIV/0! | F32: ='اجمالي التكاليف خلال الفترة'!$B$13*F6 -> #DIV/0! | G32: ='اجمالي التكاليف خلال الفترة'!$B$13*G6 -> #DIV/0! | H32: ='اجمالي التكاليف خلال الفترة'!$B$13*H6 -> #DIV/0! | I32: ='اجمالي التكاليف خلال الفترة'!$B$13*I6 -> #DIV/0! | J32: ='اجمالي التكاليف خلال الفترة'!$B$13*J6 -> #DIV/0! | ... L32: ='اجمالي التكاليف خلال الفترة'!$B$13*L6 -> #DIV/0! | M32: =SUM(C32:L32) -> #DIV/0!
B33: ='اجمالي التكاليف خلال الفترة'!C14 -> تكلفة ثابتة 9 | C33: ='اجمالي التكاليف خلال الفترة'!$B$14*C6 -> #DIV/0! | D33: ='اجمالي التكاليف خلال الفترة'!$B$14*D6 -> #DIV/0! | E33: ='اجمالي التكاليف خلال الفترة'!$B$14*E6 -> #DIV/0! | F33: ='اجمالي التكاليف خلال الفترة'!$B$14*F6 -> #DIV/0! | G33: ='اجمالي التكاليف خلال الفترة'!$B$14*G6 -> #DIV/0! | H33: ='اجمالي التكاليف خلال الفترة'!$B$14*H6 -> #DIV/0! | I33: ='اجمالي التكاليف خلال الفترة'!$B$14*I6 -> #DIV/0! | J33: ='اجمالي التكاليف خلال الفترة'!$B$14*J6 -> #DIV/0! | ... L33: ='اجمالي التكاليف خلال الفترة'!$B$14*L6 -> #DIV/0! | M33: =SUM(C33:L33) -> #DIV/0!
B34: ='اجمالي التكاليف خلال الفترة'!C15 -> تكلفة ثابتة 10 | C34: ='اجمالي التكاليف خلال الفترة'!$B$15*C6 -> #DIV/0! | D34: ='اجمالي التكاليف خلال الفترة'!$B$15*D6 -> #DIV/0! | E34: ='اجمالي التكاليف خلال الفترة'!$B$15*E6 -> #DIV/0! | F34: ='اجمالي التكاليف خلال الفترة'!$B$15*F6 -> #DIV/0! | G34: ='اجمالي التكاليف خلال الفترة'!$B$15*G6 -> #DIV/0! | H34: ='اجمالي التكاليف خلال الفترة'!$B$15*H6 -> #DIV/0! | I34: ='اجمالي التكاليف خلال الفترة'!$B$15*I6 -> #DIV/0! | J34: ='اجمالي التكاليف خلال الفترة'!$B$15*J6 -> #DIV/0! | ... L34: ='اجمالي التكاليف خلال الفترة'!$B$15*L6 -> #DIV/0! | M34: =SUM(C34:L34) -> #DIV/0!

Sheet الصنف 1
B2: =F2/الرئيسية!H10 -> #DIV/0! | D2: معدل ساعات التشغيل | F2: =الرئيسية!I10 -> 0 | G2: الطاقة المتاحة
B5: =F5/B2 -> #DIV/0! | D5: ساعات التشغيل | F5: 1 | G5: عدد الوحدات
B8: =B57 -> #DIV/0! | D8: نقطة التعادل | G8: سعر البيع
B11: =B21+B25+B38+B50 -> #DIV/0! | D11: وحدة | E11: =F5 -> 1 | F11: =الرئيسية!J10 -> 0 | G11: إجمالي التكلفة التقديرية للمنتج
B13: القيمة للوحدة | C13: سعر | D13: كمية | F13: الحساب | G13: التكلفة
D14: القياس | E14: وحده
B16: =C16*D16 -> 0 | C16: ='اجمالي التكاليف خلال الفترة'!H11 -> 0 | D16: 0.75 | E16: كيلو | F16: ='اجمالي التكاليف خلال الفترة'!I11 -> خام 1 | G16: المواد مباشرة
B17: =C17*D17 -> 0 | C17: ='اجمالي التكاليف خلال الفترة'!H12 -> 0 | D17: 0.6 | E17: عدد | F17: ='اجمالي التكاليف خلال الفترة'!I12 -> خام 2
B18: =C18*D18 -> 0 | C18: ='اجمالي التكاليف خلال الفترة'!H13 -> 0 | D18: 0.7 | E18: كيلو | F18: ='اجمالي التكاليف خلال الفترة'!I13 -> خام 3
B19: =C19*D19 -> 0 | C19: ='اجمالي التكاليف خلال الفترة'!H14 -> 0 | D19: 0.9 | E19: عدد | F19: ='اجمالي التكاليف خلال الفترة'!I14 -> خام 4
B20: =C20*D20 -> 0 | C20: ='اجمالي التكاليف خلال الفترة'!H15 -> 0 | D20: 1 | E20: كيلو | F20: ='اجمالي التكاليف خلال الفترة'!I15 -> خام 5
B21: =SUM(B16:B20)*D21 -> 0 | C21: وحدة | D21: =F5 -> 1 | E21: لانتاج | F21: إجمالي التكلفة المعيارية للمواد المباشرة
B23: =D23*C23 -> #DIV/0! | C23: ='توزيع التكاليف'!C10/الرئيسية!$H$10 -> #DIV/0! | D23: =$B$5 -> #DIV/0! | E23: ساعة | F23: تشغيلي | G23: الاجور الثابتة
B24: =D24*C24 -> #DIV/0! | C24: ='توزيع التكاليف'!C9/الرئيسية!$H$10 -> #DIV/0! | D24: =$B$5 -> #DIV/0! | E24: ساعة | F24: اضافي | G24: اجور متغيرة
B25: =SUM(B23:B24) -> #DIV/0! | C25: وحدة | D25: =F5 -> 1 | E25: لانتاج | F25: إجمالي التكلفة المعيارية للأجور المباشرة
B27: =D27*C27 -> #DIV/0! | C27: ='توزيع التكاليف'!C13/الرئيسية!$H$10 -> #DIV/0! | D27: =$B$5 -> #DIV/0! | E27: ساعة | F27: ='اجمالي التكاليف خلال الفترة'!F6 -> تكلفة متغيرة 1 | G27: التكاليف الغير
B28: =D28*C28 -> #DIV/0! | C28: ='توزيع التكاليف'!C14/الرئيسية!$H$10 -> #DIV/0! | D28: =$B$5 -> #DIV/0! | E28: ساعة | F28: ='اجمالي التكاليف خلال الفترة'!F7 -> تكلفة متغيرة 2
B29: =D29*C29 -> #DIV/0! | C29: ='توزيع التكاليف'!C15/الرئيسية!$H$10 -> #DIV/0! | D29: =$B$5 -> #DIV/0! | E29: ساعة | F29: ='اجمالي التكاليف خلال الفترة'!F8 -> تكلفة متغيرة 3
B30: =D30*C30 -> #DIV/0! | C30: ='توزيع التكاليف'!C16/الرئيسية!$H$10 -> #DIV/0! | D30: =$B$5 -> #DIV/0! | E30: ساعة | F30: ='اجمالي التكاليف خلال الفترة'!F9 -> تكلفة متغيرة 4
B31: =D31*C31 -> #DIV/0! | C31: ='توزيع التكاليف'!C17/الرئيسية!$H$10 -> #DIV/0! | D31: =$B$5 -> #DIV/0! | E31: ساعة | F31: ='اجمالي التكاليف خلال الفترة'!F10 -> تكلفة متغيرة 5 | G31: مباشرة
B32: =D32*C32 -> #DIV/0! | C32: ='توزيع التكاليف'!C18/الرئيسية!$H$10 -> #DIV/0! | D32: =$B$5 -> #DIV/0! | E32: ساعة | F32: ='اجمالي التكاليف خلال الفترة'!F11 -> تكلفة متغيرة 6
B33: =D33*C33 -> #DIV/0! | C33: ='توزيع التكاليف'!C19/الرئيسية!$H$10 -> #DIV/0! | D33: =$B$5 -> #DIV/0! | E33: ساعة | F33: ='اجمالي التكاليف خلال الفترة'!F12 -> تكلفة متغيرة 7
B34: =D34*C34 -> #DIV/0! | C34: ='توزيع التكاليف'!C20/الرئيسية!$H$10 -> #DIV/0! | D34: =$B$5 -> #DIV/0! | E34: ساعة | F34: ='اجمالي التكاليف خلال الفترة'!F13 -> تكلفة متغيرة 8 | G34: المتغيرة
B35: =D35*C35 -> #DIV/0! | C35: ='توزيع التكاليف'!C21/الرئيسية!$H$10 -> #DIV/0! | D35: =$B$5 -> #DIV/0! | E35: ساعة | F35: ='اجمالي التكاليف خلال الفترة'!F14 -> تكلفة متغيرة 9
B36: =D36*C36 -> #DIV/0! | C36: ='توزيع التكاليف'!C22/الرئيسية!$H$10 -> #DIV/0! | D36: =$B$5 -> #DIV/0! | E36: ساعة | F36: ='اجمالي التكاليف خلال الفترة'!F15 -> تكلفة متغيرة 10
B37: =D37*C37 -> #DIV/0! | C37: ='اهلاك خطوط الانتاج'!C2/F5*B5 -> #DIV/0! | D37: =$B$5 -> #DIV/0! | E37: ساعة | F37: ='اهلاك خطوط الانتاج'!$D$2 -> اهلاك خط الانتاج
B38: =SUM(B27:B37) -> #DIV/0! | C38: وحدة | D38: =F5 -> 1 | E38: لانتاج / بيع | F38: إجمالي التكلفة المعيارية الصناعية الغير مباشرة
B40: =D40*C40 -> #DIV/0! | C40: ='توزيع التكاليف'!C25/الرئيسية!$H$10 -> #DIV/0! | D40: =$B$5 -> #DIV/0! | E40: ساعة | F40: ='اجمالي التكاليف خلال الفترة'!C6 -> تكلفة ثابتة 1 | G40: التكاليف الغير
B41: =D41*C41 -> #DIV/0! | C41: ='توزيع التكاليف'!C26/الرئيسية!$H$10 -> #DIV/0! | D41: =$B$5 -> #DIV/0! | E41: ساعة | F41: ='اجمالي التكاليف خلال الفترة'!C7 -> تكلفة ثابتة 2
B42: =D42*C42 -> #DIV/0! | C42: ='توزيع التكاليف'!C27/الرئيسية!$H$10 -> #DIV/0! | D42: =$B$5 -> #DIV/0! | E42: ساعة | F42: ='اجمالي التكاليف خلال الفترة'!C8 -> تكلفة ثابتة 3
B43: =D43*C43 -> #DIV/0! | C43: ='توزيع التكاليف'!C28/الرئيسية!$H$10 -> #DIV/0! | D43: =$B$5 -> #DIV/0! | E43: ساعة | F43: ='اجمالي التكاليف خلال الفترة'!C9 -> تكلفة ثابتة 4
B44: =D44*C44 -> #DIV/0! | C44: ='توزيع التكاليف'!C29/الرئيسية!$H$10 -> #DIV/0! | D44: =$B$5 -> #DIV/0! | E44: ساعة | F44: ='اجمالي التكاليف خلال الفترة'!C10 -> تكلفة ثابتة 5 | G44: مباشرة
B45: =D45*C45 -> #DIV/0! | C45: ='توزيع التكاليف'!C30/الرئيسية!$H$10 -> #DIV/0! | D45: =$B$5 -> #DIV/0! | E45: ساعة | F45: ='اجمالي التكاليف خلال الفترة'!C11 -> تكلفة ثابتة 6
B46: =D46*C46 -> #DIV/0! | C46: ='توزيع التكاليف'!C31/الرئيسية!$H$10 -> #DIV/0! | D46: =$B$5 -> #DIV/0! | E46: ساعة | F46: ='اجمالي التكاليف خلال الفترة'!C12 -> تكلفة ثابتة 7
B47: =D47*C47 -> #DIV/0! | C47: ='توزيع التكاليف'!C32/الرئيسية!$H$10 -> #DIV/0! | D47: =$B$5 -> #DIV/0! | E47: ساعة | F47: ='اجمالي التكاليف خلال الفترة'!C13 -> تكلفة ثابتة 8 | G47: الثابتة
B48: =D48*C48 -> #DIV/0! | C48: ='توزيع التكاليف'!C33/الرئيسية!$H$10 -> #DIV/0! | D48: =$B$5 -> #DIV/0! | E48: ساعة | F48: ='اجمالي التكاليف خلال الفترة'!C14 -> تكلفة ثابتة 9
B49: =D49*C49 -> #DIV/0! | C49: ='توزيع التكاليف'!C34/الرئيسية!$H$10 -> #DIV/0! | D49: =$B$5 -> #DIV/0! | E49: ساعة | F49: ='اجمالي التكاليف خلال الفترة'!C15 -> تكلفة ثابتة 10
B50: =SUM(B40:B49) -> #DIV/0! | C50: وحدة | D50: =F5 -> 1 | E50: لانتاج / بيع | F50: إجمالي التكلفة المعيارية الصناعية الغير مباشرة
B53: معادلات تحديد نقطة التعادل
B55: الوصول | C55: التكلفة المتغيرة | D55: إجمالي | F55: سعر البيع | G55: إجمالي
...

Sheet الصنف 2
B2: =F2/الرئيسية!H14 -> #DIV/0! | D2: معدل ساعات التشغيل | F2: =الرئيسية!I14 -> 0 | G2: الطاقة المتاحة
B5: =F5/B2 -> #DIV/0! | D5: ساعات التشغيل | F5: 1 | G5: عدد الوحدات
B8: =B57 -> #DIV/0! | D8: نقطة التعادل | G8: سعر البيع
B11: =B21+B25+B38+B50 -> #DIV/0! | D11: وحدة | E11: =F5 -> 1 | F11: =الرئيسية!J14 -> 0 | G11: إجمالي التكلفة التقديرية للمنتج
B13: القيمة للوحدة | C13: سعر | D13: كمية | F13: الحساب | G13: التكلفة
D14: القياس | E14: وحده
B16: =C16*D16 -> 0 | C16: ='اجمالي التكاليف خلال الفترة'!H11 -> 0 | D16: 1 | E16: كيلو | F16: ='اجمالي التكاليف خلال الفترة'!I11 -> خام 1 | G16: المواد مباشرة
B17: =C17*D17 -> 0 | C17: ='اجمالي التكاليف خلال الفترة'!H12 -> 0 | D17: 1 | E17: عدد | F17: ='اجمالي التكاليف خلال الفترة'!I12 -> خام 2
B18: =C18*D18 -> 0 | C18: ='اجمالي التكاليف خلال الفترة'!H13 -> 0 | D18: 1 | E18: كيلو | F18: ='اجمالي التكاليف خلال الفترة'!I13 -> خام 3
B19: =C19*D19 -> 0 | C19: ='اجمالي التكاليف خلال الفترة'!H14 -> 0 | D19: 1 | E19: عدد | F19: ='اجمالي التكاليف خلال الفترة'!I14 -> خام 4
B20: =C20*D20 -> 0 | C20: ='اجمالي التكاليف خلال الفترة'!H15 -> 0 | D20: 1 | E20: كيلو | F20: ='اجمالي التكاليف خلال الفترة'!I15 -> خام 5
B21: =SUM(B16:B20)*D21 -> 0 | C21: وحدة | D21: =F5 -> 1 | E21: لانتاج | F21: إجمالي التكلفة المعيارية للمواد المباشرة
B23: =D23*C23 -> #DIV/0! | C23: ='توزيع التكاليف'!D10/الرئيسية!$H$14 -> #DIV/0! | D23: =$B$5 -> #DIV/0! | E23: ساعة | F23: تشغيلي | G23: الاجور الثابتة
B24: =D24*C24 -> #DIV/0! | C24: ='توزيع التكاليف'!D9/الرئيسية!$H$14 -> #DIV/0! | D24: =$B$5 -> #DIV/0! | E24: ساعة | F24: اضافي | G24: اجور متغيرة
B25: =SUM(B23:B24) -> #DIV/0! | C25: وحدة | D25: =F5 -> 1 | E25: لانتاج | F25: إجمالي التكلفة المعيارية للأجور المباشرة
B27: =D27*C27 -> #DIV/0! | C27: ='توزيع التكاليف'!D13/الرئيسية!$H$14 -> #DIV/0! | D27: =$B$5 -> #DIV/0! | E27: ساعة | F27: ='اجمالي التكاليف خلال الفترة'!F6 -> تكلفة متغيرة 1 | G27: التكاليف الغير
B28: =D28*C28 -> #DIV/0! | C28: ='توزيع التكاليف'!D14/الرئيسية!$H$14 -> #DIV/0! | D28: =$B$5 -> #DIV/0! | E28: ساعة | F28: ='اجمالي التكاليف خلال الفترة'!F7 -> تكلفة متغيرة 2
B29: =D29*C29 -> #DIV/0! | C29: ='توزيع التكاليف'!D15/الرئيسية!$H$14 -> #DIV/0! | D29: =$B$5 -> #DIV/0! | E29: ساعة | F29: ='اجمالي التكاليف خلال الفترة'!F8 -> تكلفة متغيرة 3
B30: =D30*C30 -> #DIV/0! | C30: ='توزيع التكاليف'!D16/الرئيسية!$H$14 -> #DIV/0! | D30: =$B$5 -> #DIV/0! | E30: ساعة | F30: ='اجمالي التكاليف خلال الفترة'!F9 -> تكلفة متغيرة 4
B31: =D31*C31 -> #DIV/0! | C31: ='توزيع التكاليف'!D17/الرئيسية!$H$14 -> #DIV/0! | D31: =$B$5 -> #DIV/0! | E31: ساعة | F31: ='اجمالي التكاليف خلال الفترة'!F10 -> تكلفة متغيرة 5 | G31: مباشرة
B32: =D32*C32 -> #DIV/0! | C32: ='توزيع التكاليف'!D18/الرئيسية!$H$14 -> #DIV/0! | D32: =$B$5 -> #DIV/0! | E32: ساعة | F32: ='اجمالي التكاليف خلال الفترة'!F11 -> تكلفة متغيرة 6
B33: =D33*C33 -> #DIV/0! | C33: ='توزيع التكاليف'!D19/الرئيسية!$H$14 -> #DIV/0! | D33: =$B$5 -> #DIV/0! | E33: ساعة | F33: ='اجمالي التكاليف خلال الفترة'!F12 -> تكلفة متغيرة 7
B34: =D34*C34 -> #DIV/0! | C34: ='توزيع التكاليف'!D20/الرئيسية!$H$14 -> #DIV/0! | D34: =$B$5 -> #DIV/0! | E34: ساعة | F34: ='اجمالي التكاليف خلال الفترة'!F13 -> تكلفة متغيرة 8 | G34: المتغيرة
B35: =D35*C35 -> #DIV/0! | C35: ='توزيع التكاليف'!D21/الرئيسية!$H$14 -> #DIV/0! | D35: =$B$5 -> #DIV/0! | E35: ساعة | F35: ='اجمالي التكاليف خلال الفترة'!F14 -> تكلفة متغيرة 9
B36: =D36*C36 -> #DIV/0! | C36: ='توزيع التكاليف'!D22/الرئيسية!$H$14 -> #DIV/0! | D36: =$B$5 -> #DIV/0! | E36: ساعة | F36: ='اجمالي التكاليف خلال الفترة'!F15 -> تكلفة متغيرة 10
B37: =D37*C37 -> #DIV/0! | C37: ='اهلاك خطوط الانتاج'!C2/F5*B5 -> #DIV/0! | D37: =$B$5 -> #DIV/0! | E37: ساعة | F37: ='اهلاك خطوط الانتاج'!$D$2 -> اهلاك خط الانتاج
B38: =SUM(B27:B37) -> #DIV/0! | C38: وحدة | D38: =F5 -> 1 | E38: لانتاج / بيع | F38: إجمالي التكلفة المعيارية الصناعية الغير مباشرة
B40: =D40*C40 -> #DIV/0! | C40: ='توزيع التكاليف'!D25/الرئيسية!$H$14 -> #DIV/0! | D40: =$B$5 -> #DIV/0! | E40: ساعة | F40: ='اجمالي التكاليف خلال الفترة'!C6 -> تكلفة ثابتة 1 | G40: التكاليف الغير
B41: =D41*C41 -> #DIV/0! | C41: ='توزيع التكاليف'!D26/الرئيسية!$H$14 -> #DIV/0! | D41: =$B$5 -> #DIV/0! | E41: ساعة | F41: ='اجمالي التكاليف خلال الفترة'!C7 -> تكلفة ثابتة 2
B42: =D42*C42 -> #DIV/0! | C42: ='توزيع التكاليف'!D27/الرئيسية!$H$14 -> #DIV/0! | D42: =$B$5 -> #DIV/0! | E42: ساعة | F42: ='اجمالي التكاليف خلال الفترة'!C8 -> تكلفة ثابتة 3
B43: =D43*C43 -> #DIV/0! | C43: ='توزيع التكاليف'!D28/الرئيسية!$H$14 -> #DIV/0! | D43: =$B$5 -> #DIV/0! | E43: ساعة | F43: ='اجمالي التكاليف خلال الفترة'!C9 -> تكلفة ثابتة 4
B44: =D44*C44 -> #DIV/0! | C44: ='توزيع التكاليف'!D29/الرئيسية!$H$14 -> #DIV/0! | D44: =$B$5 -> #DIV/0! | E44: ساعة | F44: ='اجمالي التكاليف خلال الفترة'!C10 -> تكلفة ثابتة 5 | G44: مباشرة
B45: =D45*C45 -> #DIV/0! | C45: ='توزيع التكاليف'!D30/الرئيسية!$H$14 -> #DIV/0! | D45: =$B$5 -> #DIV/0! | E45: ساعة | F45: ='اجمالي التكاليف خلال الفترة'!C11 -> تكلفة ثابتة 6
B46: =D46*C46 -> #DIV/0! | C46: ='توزيع التكاليف'!D31/الرئيسية!$H$14 -> #DIV/0! | D46: =$B$5 -> #DIV/0! | E46: ساعة | F46: ='اجمالي التكاليف خلال الفترة'!C12 -> تكلفة ثابتة 7
B47: =D47*C47 -> #DIV/0! | C47: ='توزيع التكاليف'!D32/الرئيسية!$H$14 -> #DIV/0! | D47: =$B$5 -> #DIV/0! | E47: ساعة | F47: ='اجمالي التكاليف خلال الفترة'!C13 -> تكلفة ثابتة 8 | G47: الثابتة
B48: =D48*C48 -> #DIV/0! | C48: ='توزيع التكاليف'!D33/الرئيسية!$H$14 -> #DIV/0! | D48: =$B$5 -> #DIV/0! | E48: ساعة | F48: ='اجمالي التكاليف خلال الفترة'!C14 -> تكلفة ثابتة 9
B49: =D49*C49 -> #DIV/0! | C49: ='توزيع التكاليف'!D34/الرئيسية!$H$14 -> #DIV/0! | D49: =$B$5 -> #DIV/0! | E49: ساعة | F49: ='اجمالي التكاليف خلال الفترة'!C15 -> تكلفة ثابتة 10
B50: =SUM(B40:B49) -> #DIV/0! | C50: وحدة | D50: =F5 -> 1 | E50: لانتاج / بيع | F50: إجمالي التكلفة المعيارية الصناعية الغير مباشرة
B53: معادلات تحديد نقطة التعادل
B55: الوصول | C55: التكلفة المتغيرة | D55: إجمالي | F55: سعر البيع | G55: إجمالي
...

Sheet الصنف 3
B2: =F2/الرئيسية!H18 -> #DIV/0! | D2: معدل ساعات التشغيل | F2: =الرئيسية!I18 -> 0 | G2: الطاقة المتاحة
B5: =F5/B2 -> #DIV/0! | D5: ساعات التشغيل | F5: 1 | G5: عدد الوحدات
B8: =B57 -> #DIV/0! | D8: نقطة التعادل | G8: سعر البيع
B11: =B21+B25+B38+B50 -> #DIV/0! | D11: وحدة | E11: =F5 -> 1 | F11: =الرئيسية!J18 -> 0 | G11: إجمالي التكلفة التقديرية للمنتج
B13: القيمة للوحدة | C13: سعر | D13: كمية | F13: الحساب | G13: التكلفة
D14: القياس | E14: وحده
B16: =C16*D16 -> 0 | C16: ='اجمالي التكاليف خلال الفترة'!H11 -> 0 | D16: 1 | E16: كيلو | F16: ='اجمالي التكاليف خلال الفترة'!I11 -> خام 1 | G16: المواد مباشرة
B17: =C17*D17 -> 0 | C17: ='اجمالي التكاليف خلال الفترة'!H12 -> 0 | D17: 1 | E17: عدد | F17: ='اجمالي التكاليف خلال الفترة'!I12 -> خام 2
B18: =C18*D18 -> 0 | C18: ='اجمالي التكاليف خلال الفترة'!H13 -> 0 | D18: 1 | E18: كيلو | F18: ='اجمالي التكاليف خلال الفترة'!I13 -> خام 3
B19: =C19*D19 -> 0 | C19: ='اجمالي التكاليف خلال الفترة'!H14 -> 0 | D19: 1 | E19: عدد | F19: ='اجمالي التكاليف خلال الفترة'!I14 -> خام 4
B20: =C20*D20 -> 0 | C20: ='اجمالي التكاليف خلال الفترة'!H15 -> 0 | D20: 1 | E20: كيلو | F20: ='اجمالي التكاليف خلال الفترة'!I15 -> خام 5
B21: =SUM(B16:B20)*D21 -> 0 | C21: وحدة | D21: =F5 -> 1 | E21: لانتاج | F21: إجمالي التكلفة المعيارية للمواد المباشرة
B23: =D23*C23 -> #DIV/0! | C23: ='توزيع التكاليف'!E10/الرئيسية!$H$18 -> #DIV/0! | D23: =$B$5 -> #DIV/0! | E23: ساعة | F23: تشغيلي | G23: الاجور الثابتة
B24: =D24*C24 -> #DIV/0! | C24: ='توزيع التكاليف'!E9/الرئيسية!$H$18 -> #DIV/0! | D24: =$B$5 -> #DIV/0! | E24: ساعة | F24: اضافي | G24: اجور متغيرة
B25: =SUM(B23:B24) -> #DIV/0! | C25: وحدة | D25: =F5 -> 1 | E25: لانتاج | F25: إجمالي التكلفة المعيارية للأجور المباشرة
B27: =D27*C27 -> #DIV/0! | C27: ='توزيع التكاليف'!E13/الرئيسية!$H$18 -> #DIV/0! | D27: =$B$5 -> #DIV/0! | E27: ساعة | F27: ='اجمالي التكاليف خلال الفترة'!F6 -> تكلفة متغيرة 1 | G27: التكاليف الغير
B28: =D28*C28 -> #DIV/0! | C28: ='توزيع التكاليف'!E14/الرئيسية!$H$18 -> #DIV/0! | D28: =$B$5 -> #DIV/0! | E28: ساعة | F28: ='اجمالي التكاليف خلال الفترة'!F7 -> تكلفة متغيرة 2
B29: =D29*C29 -> #DIV/0! | C29: ='توزيع التكاليف'!E15/الرئيسية!$H$18 -> #DIV/0! | D29: =$B$5 -> #DIV/0! | E29: ساعة | F29: ='اجمالي التكاليف خلال الفترة'!F8 -> تكلفة متغيرة 3
B30: =D30*C30 -> #DIV/0! | C30: ='توزيع التكاليف'!E16/الرئيسية!$H$18 -> #DIV/0! | D30: =$B$5 -> #DIV/0! | E30: ساعة | F30: ='اجمالي التكاليف خلال الفترة'!F9 -> تكلفة متغيرة 4
B31: =D31*C31 -> #DIV/0! | C31: ='توزيع التكاليف'!E17/الرئيسية!$H$18 -> #DIV/0! | D31: =$B$5 -> #DIV/0! | E31: ساعة | F31: ='اجمالي التكاليف خلال الفترة'!F10 -> تكلفة متغيرة 5 | G31: مباشرة
B32: =D32*C32 -> #DIV/0! | C32: ='توزيع التكاليف'!E18/الرئيسية!$H$18 -> #DIV/0! | D32: =$B$5 -> #DIV/0! | E32: ساعة | F32: ='اجمالي التكاليف خلال الفترة'!F11 -> تكلفة متغيرة 6
B33: =D33*C33 -> #DIV/0! | C33: ='توزيع التكاليف'!E19/الرئيسية!$H$18 -> #DIV/0! | D33: =$B$5 -> #DIV/0! | E33: ساعة | F33: ='اجمالي التكاليف خلال الفترة'!F12 -> تكلفة متغيرة 7
B34: =D34*C34 -> #DIV/0! | C34: ='توزيع التكاليف'!E20/الرئيسية!$H$18 -> #DIV/0! | D34: =$B$5 -> #DIV/0! | E34: ساعة | F34: ='اجمالي التكاليف خلال الفترة'!F13 -> تكلفة متغيرة 8 | G34: المتغيرة
B35: =D35*C35 -> #DIV/0! | C35: ='توزيع التكاليف'!E21/الرئيسية!$H$18 -> #DIV/0! | D35: =$B$5 -> #DIV/0! | E35: ساعة | F35: ='اجمالي التكاليف خلال الفترة'!F14 -> تكلفة متغيرة 9
B36: =D36*C36 -> #DIV/0! | C36: ='توزيع التكاليف'!E22/الرئيسية!$H$18 -> #DIV/0! | D36: =$B$5 -> #DIV/0! | E36: ساعة | F36: ='اجمالي التكاليف خلال الفترة'!F15 -> تكلفة متغيرة 10
B37: =D37*C37 -> #DIV/0! | C37: ='اهلاك خطوط الانتاج'!C2/F5*B5 -> #DIV/0! | D37: =$B$5 -> #DIV/0! | E37: ساعة | F37: ='اهلاك خطوط الانتاج'!$D$2 -> اهلاك خط الانتاج
B38: =SUM(B27:B37) -> #DIV/0! | C38: وحدة | D38: =F5 -> 1 | E38: لانتاج / بيع | F38: إجمالي التكلفة المعيارية الصناعية الغير مباشرة
B40: =D40*C40 -> #DIV/0! | C40: ='توزيع التكاليف'!E25/الرئيسية!$H$18 -> #DIV/0! | D40: =$B$5 -> #DIV/0! | E40: ساعة | F40: ='اجمالي التكاليف خلال الفترة'!C6 -> تكلفة ثابتة 1 | G40: التكاليف الغير
B41: =D41*C41 -> #DIV/0! | C41: ='توزيع التكاليف'!E26/الرئيسية!$H$18 -> #DIV/0! | D41: =$B$5 -> #DIV/0! | E41: ساعة | F41: ='اجمالي التكاليف خلال الفترة'!C7 -> تكلفة ثابتة 2
B42: =D42*C42 -> #DIV/0! | C42: ='توزيع التكاليف'!E27/الرئيسية!$H$18 -> #DIV/0! | D42: =$B$5 -> #DIV/0! | E42: ساعة | F42: ='اجمالي التكاليف خلال الفترة'!C8 -> تكلفة ثابتة 3
B43: =D43*C43 -> #DIV/0! | C43: ='توزيع التكاليف'!E28/الرئيسية!$H$18 -> #DIV/0! | D43: =$B$5 -> #DIV/0! | E43: ساعة | F43: ='اجمالي التكاليف خلال الفترة'!C9 -> تكلفة ثابتة 4
B44: =D44*C44 -> #DIV/0! | C44: ='توزيع التكاليف'!E29/الرئيسية!$H$18 -> #DIV/0! | D44: =$B$5 -> #DIV/0! | E44: ساعة | F44: ='اجمالي التكاليف خلال الفترة'!C10 -> تكلفة ثابتة 5 | G44: مباشرة
B45: =D45*C45 -> #DIV/0! | C45: ='توزيع التكاليف'!E30/الرئيسية!$H$18 -> #DIV/0! | D45: =$B$5 -> #DIV/0! | E45: ساعة | F45: ='اجمالي التكاليف خلال الفترة'!C11 -> تكلفة ثابتة 6
B46: =D46*C46 -> #DIV/0! | C46: ='توزيع التكاليف'!E31/الرئيسية!$H$18 -> #DIV/0! | D46: =$B$5 -> #DIV/0! | E46: ساعة | F46: ='اجمالي التكاليف خلال الفترة'!C12 -> تكلفة ثابتة 7
B47: =D47*C47 -> #DIV/0! | C47: ='توزيع التكاليف'!E32/الرئيسية!$H$18 -> #DIV/0! | D47: =$B$5 -> #DIV/0! | E47: ساعة | F47: ='اجمالي التكاليف خلال الفترة'!C13 -> تكلفة ثابتة 8 | G47: الثابتة
B48: =D48*C48 -> #DIV/0! | C48: ='توزيع التكاليف'!E33/الرئيسية!$H$18 -> #DIV/0! | D48: =$B$5 -> #DIV/0! | E48: ساعة | F48: ='اجمالي التكاليف خلال الفترة'!C14 -> تكلفة ثابتة 9
B49: =D49*C49 -> #DIV/0! | C49: ='توزيع التكاليف'!E34/الرئيسية!$H$18 -> #DIV/0! | D49: =$B$5 -> #DIV/0! | E49: ساعة | F49: ='اجمالي التكاليف خلال الفترة'!C15 -> تكلفة ثابتة 10
B50: =SUM(B40:B49) -> #DIV/0! | C50: وحدة | D50: =F5 -> 1 | E50: لانتاج / بيع | F50: إجمالي التكلفة المعيارية الصناعية الغير مباشرة
B53: معادلات تحديد نقطة التعادل
B55: الوصول | C55: التكلفة المتغيرة | D55: إجمالي | F55: سعر البيع | G55: إجمالي
...

Sheet الصنف 4
B2: =F2/الرئيسية!H22 -> #DIV/0! | D2: معدل ساعات التشغيل | F2: =الرئيسية!I22 -> 0 | G2: الطاقة المتاحة
B5: =F5/B2 -> #DIV/0! | D5: ساعات التشغيل | F5: 1 | G5: عدد الوحدات
B8: =B57 -> #DIV/0! | D8: نقطة التعادل | G8: سعر البيع
B11: =B21+B25+B38+B50 -> #DIV/0! | D11: وحدة | E11: =F5 -> 1 | F11: =الرئيسية!J22 -> 0 | G11: إجمالي التكلفة التقديرية للمنتج
B13: القيمة للوحدة | C13: سعر | D13: كمية | F13: الحساب | G13: التكلفة
D14: القياس | E14: وحده
B16: =C16*D16 -> 0 | C16: ='اجمالي التكاليف خلال الفترة'!H11 -> 0 | D16: 1 | E16: كيلو | F16: ='اجمالي التكاليف خلال الفترة'!I11 -> خام 1 | G16: المواد مباشرة
B17: =C17*D17 -> 0 | C17: ='اجمالي التكاليف خلال الفترة'!H12 -> 0 | D17: 1 | E17: عدد | F17: ='اجمالي التكاليف خلال الفترة'!I12 -> خام 2
B18: =C18*D18 -> 0 | C18: ='اجمالي التكاليف خلال الفترة'!H13 -> 0 | D18: 1 | E18: كيلو | F18: ='اجمالي التكاليف خلال الفترة'!I13 -> خام 3
B19: =C19*D19 -> 0 | C19: ='اجمالي التكاليف خلال الفترة'!H14 -> 0 | D19: 1 | E19: عدد | F19: ='اجمالي التكاليف خلال الفترة'!I14 -> خام 4
B20: =C20*D20 -> 0 | C20: ='اجمالي التكاليف خلال الفترة'!H15 -> 0 | D20: 1 | E20: كيلو | F20: ='اجمالي التكاليف خلال الفترة'!I15 -> خام 5
B21: =SUM(B16:B20)*D21 -> 0 | C21: وحدة | D21: =F5 -> 1 | E21: لانتاج | F21: إجمالي التكلفة المعيارية للمواد المباشرة
B23: =D23*C23 -> #DIV/0! | C23: ='توزيع التكاليف'!F10/الرئيسية!$H$22 -> #DIV/0! | D23: =$B$5 -> #DIV/0! | E23: ساعة | F23: تشغيلي | G23: الاجور الثابتة
B24: =D24*C24 -> #DIV/0! | C24: ='توزيع التكاليف'!F9/الرئيسية!$H$22 -> #DIV/0! | D24: =$B$5 -> #DIV/0! | E24: ساعة | F24: اضافي | G24: اجور متغيرة
B25: =SUM(B23:B24) -> #DIV/0! | C25: وحدة | D25: =F5 -> 1 | E25: لانتاج | F25: إجمالي التكلفة المعيارية للأجور المباشرة
B27: =D27*C27 -> #DIV/0! | C27: ='توزيع التكاليف'!F13/الرئيسية!$H$22 -> #DIV/0! | D27: =$B$5 -> #DIV/0! | E27: ساعة | F27: ='اجمالي التكاليف خلال الفترة'!F6 -> تكلفة متغيرة 1 | G27: التكاليف الغير
B28: =D28*C28 -> #DIV/0! | C28: ='توزيع التكاليف'!F14/الرئيسية!$H$22 -> #DIV/0! | D28: =$B$5 -> #DIV/0! | E28: ساعة | F28: ='اجمالي التكاليف خلال الفترة'!F7 -> تكلفة متغيرة 2
B29: =D29*C29 -> #DIV/0! | C29: ='توزيع التكاليف'!F15/الرئيسية!$H$22 -> #DIV/0! | D29: =$B$5 -> #DIV/0! | E29: ساعة | F29: ='اجمالي التكاليف خلال الفترة'!F8 -> تكلفة متغيرة 3
B30: =D30*C30 -> #DIV/0! | C30: ='توزيع التكاليف'!F16/الرئيسية!$H$22 -> #DIV/0! | D30: =$B$5 -> #DIV/0! | E30: ساعة | F30: ='اجمالي التكاليف خلال الفترة'!F9 -> تكلفة متغيرة 4
B31: =D31*C31 -> #DIV/0! | C31: ='توزيع التكاليف'!F17/الرئيسية!$H$22 -> #DIV/0! | D31: =$B$5 -> #DIV/0! | E31: ساعة | F31: ='اجمالي التكاليف خلال الفترة'!F10 -> تكلفة متغيرة 5 | G31: مباشرة
B32: =D32*C32 -> #DIV/0! | C32: ='توزيع التكاليف'!F18/الرئيسية!$H$22 -> #DIV/0! | D32: =$B$5 -> #DIV/0! | E32: ساعة | F32: ='اجمالي التكاليف خلال الفترة'!F11 -> تكلفة متغيرة 6
B33: =D33*C33 -> #DIV/0! | C33: ='توزيع التكاليف'!F19/الرئيسية!$H$22 -> #DIV/0! | D33: =$B$5 -> #DIV/0! | E33: ساعة | F33: ='اجمالي التكاليف خلال الفترة'!F12 -> تكلفة متغيرة 7
B34: =D34*C34 -> #DIV/0! | C34: ='توزيع التكاليف'!F20/الرئيسية!$H$22 -> #DIV/0! | D34: =$B$5 -> #DIV/0! | E34: ساعة | F34: ='اجمالي التكاليف خلال الفترة'!F13 -> تكلفة متغيرة 8 | G34: المتغيرة
B35: =D35*C35 -> #DIV/0! | C35: ='توزيع التكاليف'!F21/الرئيسية!$H$22 -> #DIV/0! | D35: =$B$5 -> #DIV/0! | E35: ساعة | F35: ='اجمالي التكاليف خلال الفترة'!F14 -> تكلفة متغيرة 9
B36: =D36*C36 -> #DIV/0! | C36: ='توزيع التكاليف'!F22/الرئيسية!$H$22 -> #DIV/0! | D36: =$B$5 -> #DIV/0! | E36: ساعة | F36: ='اجمالي التكاليف خلال الفترة'!F15 -> تكلفة متغيرة 10
B37: =D37*C37 -> #DIV/0! | C37: ='اهلاك خطوط الانتاج'!C2/F5*B5 -> #DIV/0! | D37: =$B$5 -> #DIV/0! | E37: ساعة | F37: ='اهلاك خطوط الانتاج'!$D$2 -> اهلاك خط الانتاج
B38: =SUM(B27:B37) -> #DIV/0! | C38: وحدة | D38: =F5 -> 1 | E38: لانتاج / بيع | F38: إجمالي التكلفة المعيارية الصناعية الغير مباشرة
B40: =D40*C40 -> #DIV/0! | C40: ='توزيع التكاليف'!F25/الرئيسية!$H$22 -> #DIV/0! | D40: =$B$5 -> #DIV/0! | E40: ساعة | F40: ='اجمالي التكاليف خلال الفترة'!C6 -> تكلفة ثابتة 1 | G40: التكاليف الغير
B41: =D41*C41 -> #DIV/0! | C41: ='توزيع التكاليف'!F26/الرئيسية!$H$22 -> #DIV/0! | D41: =$B$5 -> #DIV/0! | E41: ساعة | F41: ='اجمالي التكاليف خلال الفترة'!C7 -> تكلفة ثابتة 2
B42: =D42*C42 -> #DIV/0! | C42: ='توزيع التكاليف'!F27/الرئيسية!$H$22 -> #DIV/0! | D42: =$B$5 -> #DIV/0! | E42: ساعة | F42: ='اجمالي التكاليف خلال الفترة'!C8 -> تكلفة ثابتة 3
B43: =D43*C43 -> #DIV/0! | C43: ='توزيع التكاليف'!F28/الرئيسية!$H$22 -> #DIV/0! | D43: =$B$5 -> #DIV/0! | E43: ساعة | F43: ='اجمالي التكاليف خلال الفترة'!C9 -> تكلفة ثابتة 4
B44: =D44*C44 -> #DIV/0! | C44: ='توزيع التكاليف'!F29/الرئيسية!$H$22 -> #DIV/0! | D44: =$B$5 -> #DIV/0! | E44: ساعة | F44: ='اجمالي التكاليف خلال الفترة'!C10 -> تكلفة ثابتة 5 | G44: مباشرة
B45: =D45*C45 -> #DIV/0! | C45: ='توزيع التكاليف'!F30/الرئيسية!$H$22 -> #DIV/0! | D45: =$B$5 -> #DIV/0! | E45: ساعة | F45: ='اجمالي التكاليف خلال الفترة'!C11 -> تكلفة ثابتة 6
B46: =D46*C46 -> #DIV/0! | C46: ='توزيع التكاليف'!F31/الرئيسية!$H$22 -> #DIV/0! | D46: =$B$5 -> #DIV/0! | E46: ساعة | F46: ='اجمالي التكاليف خلال الفترة'!C12 -> تكلفة ثابتة 7
B47: =D47*C47 -> #DIV/0! | C47: ='توزيع التكاليف'!F32/الرئيسية!$H$22 -> #DIV/0! | D47: =$B$5 -> #DIV/0! | E47: ساعة | F47: ='اجمالي التكاليف خلال الفترة'!C13 -> تكلفة ثابتة 8 | G47: الثابتة
B48: =D48*C48 -> #DIV/0! | C48: ='توزيع التكاليف'!F33/الرئيسية!$H$22 -> #DIV/0! | D48: =$B$5 -> #DIV/0! | E48: ساعة | F48: ='اجمالي التكاليف خلال الفترة'!C14 -> تكلفة ثابتة 9
B49: =D49*C49 -> #DIV/0! | C49: ='توزيع التكاليف'!F34/الرئيسية!$H$22 -> #DIV/0! | D49: =$B$5 -> #DIV/0! | E49: ساعة | F49: ='اجمالي التكاليف خلال الفترة'!C15 -> تكلفة ثابتة 10
B50: =SUM(B40:B49) -> #DIV/0! | C50: وحدة | D50: =F5 -> 1 | E50: لانتاج / بيع | F50: إجمالي التكلفة المعيارية الصناعية الغير مباشرة
B53: معادلات تحديد نقطة التعادل
B55: الوصول | C55: التكلفة المتغيرة | D55: إجمالي | F55: سعر البيع | G55: إجمالي
...

Sheet الصنف 5
B2: =F2/الرئيسية!H26 -> #DIV/0! | D2: معدل ساعات التشغيل | F2: =الرئيسية!I26 -> 0 | G2: الطاقة المتاحة
B5: =F5/B2 -> #DIV/0! | D5: ساعات التشغيل | F5: 1 | G5: عدد الوحدات
B8: =B57 -> #DIV/0! | D8: نقطة التعادل | G8: سعر البيع
B11: =B21+B25+B38+B50 -> #DIV/0! | D11: وحدة | E11: =F5 -> 1 | F11: =الرئيسية!J26 -> 0 | G11: إجمالي التكلفة التقديرية للمنتج
B13: القيمة للوحدة | C13: سعر | D13: كمية | F13: الحساب | G13: التكلفة
D14: القياس | E14: وحده
B16: =C16*D16 -> 0 | C16: ='اجمالي التكاليف خلال الفترة'!H11 -> 0 | D16: 1 | E16: كيلو | F16: ='اجمالي التكاليف خلال الفترة'!I11 -> خام 1 | G16: المواد مباشرة
B17: =C17*D17 -> 0 | C17: ='اجمالي التكاليف خلال الفترة'!H12 -> 0 | D17: 1 | E17: عدد | F17: ='اجمالي التكاليف خلال الفترة'!I12 -> خام 2
B18: =C18*D18 -> 0 | C18: ='اجمالي التكاليف خلال الفترة'!H13 -> 0 | D18: 1 | E18: كيلو | F18: ='اجمالي التكاليف خلال الفترة'!I13 -> خام 3
B19: =C19*D19 -> 0 | C19: ='اجمالي التكاليف خلال الفترة'!H14 -> 0 | D19: 1 | E19: عدد | F19: ='اجمالي التكاليف خلال الفترة'!I14 -> خام 4
B20: =C20*D20 -> 0 | C20: ='اجمالي التكاليف خلال الفترة'!H15 -> 0 | D20: 1 | E20: كيلو | F20: ='اجمالي التكاليف خلال الفترة'!I15 -> خام 5
B21: =SUM(B16:B20)*D21 -> 0 | C21: وحدة | D21: =F5 -> 1 | E21: لانتاج | F21: إجمالي التكلفة المعيارية للمواد المباشرة
B23: =D23*C23 -> #DIV/0! | C23: ='توزيع التكاليف'!G10/الرئيسية!$H$26 -> #DIV/0! | D23: =$B$5 -> #DIV/0! | E23: ساعة | F23: تشغيلي | G23: الاجور الثابتة
B24: =D24*C24 -> #DIV/0! | C24: ='توزيع التكاليف'!G9/الرئيسية!$H$26 -> #DIV/0! | D24: =$B$5 -> #DIV/0! | E24: ساعة | F24: اضافي | G24: اجور متغيرة
B25: =SUM(B23:B24) -> #DIV/0! | C25: وحدة | D25: =F5 -> 1 | E25: لانتاج | F25: إجمالي التكلفة المعيارية للأجور المباشرة
B27: =D27*C27 -> #DIV/0! | C27: ='توزيع التكاليف'!G13/الرئيسية!$H$26 -> #DIV/0! | D27: =$B$5 -> #DIV/0! | E27: ساعة | F27: ='اجمالي التكاليف خلال الفترة'!F6 -> تكلفة متغيرة 1 | G27: التكاليف الغير
B28: =D28*C28 -> #DIV/0! | C28: ='توزيع التكاليف'!G14/الرئيسية!$H$26 -> #DIV/0! | D28: =$B$5 -> #DIV/0! | E28: ساعة | F28: ='اجمالي التكاليف خلال الفترة'!F7 -> تكلفة متغيرة 2
B29: =D29*C29 -> #DIV/0! | C29: ='توزيع التكاليف'!G15/الرئيسية!$H$26 -> #DIV/0! | D29: =$B$5 -> #DIV/0! | E29: ساعة | F29: ='اجمالي التكاليف خلال الفترة'!F8 -> تكلفة متغيرة 3
B30: =D30*C30 -> #DIV/0! | C30: ='توزيع التكاليف'!G16/الرئيسية!$H$26 -> #DIV/0! | D30: =$B$5 -> #DIV/0! | E30: ساعة | F30: ='اجمالي التكاليف خلال الفترة'!F9 -> تكلفة متغيرة 4
B31: =D31*C31 -> #DIV/0! | C31: ='توزيع التكاليف'!G17/الرئيسية!$H$26 -> #DIV/0! | D31: =$B$5 -> #DIV/0! | E31: ساعة | F31: ='اجمالي التكاليف خلال الفترة'!F10 -> تكلفة متغيرة 5 | G31: مباشرة
B32: =D32*C32 -> #DIV/0! | C32: ='توزيع التكاليف'!G18/الرئيسية!$H$26 -> #DIV/0! | D32: =$B$5 -> #DIV/0! | E32: ساعة | F32: ='اجمالي التكاليف خلال الفترة'!F11 -> تكلفة متغيرة 6
B33: =D33*C33 -> #DIV/0! | C33: ='توزيع التكاليف'!G19/الرئيسية!$H$26 -> #DIV/0! | D33: =$B$5 -> #DIV/0! | E33: ساعة | F33: ='اجمالي التكاليف خلال الفترة'!F12 -> تكلفة متغيرة 7
B34: =D34*C34 -> #DIV/0! | C34: ='توزيع التكاليف'!G20/الرئيسية!$H$26 -> #DIV/0! | D34: =$B$5 -> #DIV/0! | E34: ساعة | F34: ='اجمالي التكاليف خلال الفترة'!F13 -> تكلفة متغيرة 8 | G34: المتغيرة
B35: =D35*C35 -> #DIV/0! | C35: ='توزيع التكاليف'!G21/الرئيسية!$H$26 -> #DIV/0! | D35: =$B$5 -> #DIV/0! | E35: ساعة | F35: ='اجمالي التكاليف خلال الفترة'!F14 -> تكلفة متغيرة 9
B36: =D36*C36 -> #DIV/0! | C36: ='توزيع التكاليف'!G22/الرئيسية!$H$26 -> #DIV/0! | D36: =$B$5 -> #DIV/0! | E36: ساعة | F36: ='اجمالي التكاليف خلال الفترة'!F15 -> تكلفة متغيرة 10
B37: =D37*C37 -> #DIV/0! | C37: ='اهلاك خطوط الانتاج'!C2/F5*B5 -> #DIV/0! | D37: =$B$5 -> #DIV/0! | E37: ساعة | F37: ='اهلاك خطوط الانتاج'!$D$2 -> اهلاك خط الانتاج
B38: =SUM(B27:B37) -> #DIV/0! | C38: وحدة | D38: =F5 -> 1 | E38: لانتاج / بيع | F38: إجمالي التكلفة المعيارية الصناعية الغير مباشرة
B40: =D40*C40 -> #DIV/0! | C40: ='توزيع التكاليف'!G25/الرئيسية!$H$26 -> #DIV/0! | D40: =$B$5 -> #DIV/0! | E40: ساعة | F40: ='اجمالي التكاليف خلال الفترة'!C6 -> تكلفة ثابتة 1 | G40: التكاليف الغير
B41: =D41*C41 -> #DIV/0! | C41: ='توزيع التكاليف'!G26/الرئيسية!$H$26 -> #DIV/0! | D41: =$B$5 -> #DIV/0! | E41: ساعة | F41: ='اجمالي التكاليف خلال الفترة'!C7 -> تكلفة ثابتة 2
B42: =D42*C42 -> #DIV/0! | C42: ='توزيع التكاليف'!G27/الرئيسية!$H$26 -> #DIV/0! | D42: =$B$5 -> #DIV/0! | E42: ساعة | F42: ='اجمالي التكاليف خلال الفترة'!C8 -> تكلفة ثابتة 3
B43: =D43*C43 -> #DIV/0! | C43: ='توزيع التكاليف'!G28/الرئيسية!$H$26 -> #DIV/0! | D43: =$B$5 -> #DIV/0! | E43: ساعة | F43: ='اجمالي التكاليف خلال الفترة'!C9 -> تكلفة ثابتة 4
B44: =D44*C44 -> #DIV/0! | C44: ='توزيع التكاليف'!G29/الرئيسية!$H$26 -> #DIV/0! | D44: =$B$5 -> #DIV/0! | E44: ساعة | F44: ='اجمالي التكاليف خلال الفترة'!C10 -> تكلفة ثابتة 5 | G44: مباشرة
B45: =D45*C45 -> #DIV/0! | C45: ='توزيع التكاليف'!G30/الرئيسية!$H$26 -> #DIV/0! | D45: =$B$5 -> #DIV/0! | E45: ساعة | F45: ='اجمالي التكاليف خلال الفترة'!C11 -> تكلفة ثابتة 6
B46: =D46*C46 -> #DIV/0! | C46: ='توزيع التكاليف'!G31/الرئيسية!$H$26 -> #DIV/0! | D46: =$B$5 -> #DIV/0! | E46: ساعة | F46: ='اجمالي التكاليف خلال الفترة'!C12 -> تكلفة ثابتة 7
B47: =D47*C47 -> #DIV/0! | C47: ='توزيع التكاليف'!G32/الرئيسية!$H$26 -> #DIV/0! | D47: =$B$5 -> #DIV/0! | E47: ساعة | F47: ='اجمالي التكاليف خلال الفترة'!C13 -> تكلفة ثابتة 8 | G47: الثابتة
B48: =D48*C48 -> #DIV/0! | C48: ='توزيع التكاليف'!G33/الرئيسية!$H$26 -> #DIV/0! | D48: =$B$5 -> #DIV/0! | E48: ساعة | F48: ='اجمالي التكاليف خلال الفترة'!C14 -> تكلفة ثابتة 9
B49: =D49*C49 -> #DIV/0! | C49: ='توزيع التكاليف'!G34/الرئيسية!$H$26 -> #DIV/0! | D49: =$B$5 -> #DIV/0! | E49: ساعة | F49: ='اجمالي التكاليف خلال الفترة'!C15 -> تكلفة ثابتة 10
B50: =SUM(B40:B49) -> #DIV/0! | C50: وحدة | D50: =F5 -> 1 | E50: لانتاج / بيع | F50: إجمالي التكلفة المعيارية الصناعية الغير مباشرة
B53: معادلات تحديد نقطة التعادل
B55: الوصول | C55: التكلفة المتغيرة | D55: إجمالي | F55: سعر البيع | G55: إجمالي
...

Sheet الصنف 6
B2: =F2/الرئيسية!N10 -> #DIV/0! | D2: معدل ساعات التشغيل | F2: =الرئيسية!O10 -> 0 | G2: الطاقة المتاحة
B5: =F5/B2 -> #DIV/0! | D5: ساعات التشغيل | F5: 1 | G5: عدد الوحدات
B8: =B57 -> #DIV/0! | D8: نقطة التعادل | G8: سعر البيع
B11: =B21+B25+B38+B50 -> #DIV/0! | D11: وحدة | E11: =F5 -> 1 | F11: =الرئيسية!P10 -> 0 | G11: إجمالي التكلفة التقديرية للمنتج
B13: القيمة للوحدة | C13: سعر | D13: كمية | F13: الحساب | G13: التكلفة
D14: القياس | E14: وحده
B16: =C16*D16 -> 0 | C16: ='اجمالي التكاليف خلال الفترة'!H11 -> 0 | D16: 1 | E16: كيلو | F16: ='اجمالي التكاليف خلال الفترة'!I11 -> خام 1 | G16: المواد مباشرة
B17: =C17*D17 -> 0 | C17: ='اجمالي التكاليف خلال الفترة'!H12 -> 0 | D17: 1 | E17: عدد | F17: ='اجمالي التكاليف خلال الفترة'!I12 -> خام 2
B18: =C18*D18 -> 0 | C18: ='اجمالي التكاليف خلال الفترة'!H13 -> 0 | D18: 1 | E18: كيلو | F18: ='اجمالي التكاليف خلال الفترة'!I13 -> خام 3
B19: =C19*D19 -> 0 | C19: ='اجمالي التكاليف خلال الفترة'!H14 -> 0 | D19: 1 | E19: عدد | F19: ='اجمالي التكاليف خلال الفترة'!I14 -> خام 4
B20: =C20*D20 -> 0 | C20: ='اجمالي التكاليف خلال الفترة'!H15 -> 0 | D20: 1 | E20: كيلو | F20: ='اجمالي التكاليف خلال الفترة'!I15 -> خام 5
B21: =SUM(B16:B20)*D21 -> 0 | C21: وحدة | D21: =F5 -> 1 | E21: لانتاج | F21: إجمالي التكلفة المعيارية للمواد المباشرة
B23: =D23*C23 -> #DIV/0! | C23: ='توزيع التكاليف'!H10/الرئيسية!$N$10 -> #DIV/0! | D23: =$B$5 -> #DIV/0! | E23: ساعة | F23: تشغيلي | G23: الاجور الثابتة
B24: =D24*C24 -> #DIV/0! | C24: ='توزيع التكاليف'!H9/الرئيسية!$N$10 -> #DIV/0! | D24: =$B$5 -> #DIV/0! | E24: ساعة | F24: اضافي | G24: اجور متغيرة
B25: =SUM(B23:B24) -> #DIV/0! | C25: وحدة | D25: =F5 -> 1 | E25: لانتاج | F25: إجمالي التكلفة المعيارية للأجور المباشرة
B27: =D27*C27 -> #DIV/0! | C27: ='توزيع التكاليف'!H13/الرئيسية!$N$10 -> #DIV/0! | D27: =$B$5 -> #DIV/0! | E27: ساعة | F27: ='اجمالي التكاليف خلال الفترة'!F6 -> تكلفة متغيرة 1 | G27: التكاليف الغير
B28: =D28*C28 -> #DIV/0! | C28: ='توزيع التكاليف'!H14/الرئيسية!$N$10 -> #DIV/0! | D28: =$B$5 -> #DIV/0! | E28: ساعة | F28: ='اجمالي التكاليف خلال الفترة'!F7 -> تكلفة متغيرة 2
B29: =D29*C29 -> #DIV/0! | C29: ='توزيع التكاليف'!H15/الرئيسية!$N$10 -> #DIV/0! | D29: =$B$5 -> #DIV/0! | E29: ساعة | F29: ='اجمالي التكاليف خلال الفترة'!F8 -> تكلفة متغيرة 3
B30: =D30*C30 -> #DIV/0! | C30: ='توزيع التكاليف'!H16/الرئيسية!$N$10 -> #DIV/0! | D30: =$B$5 -> #DIV/0! | E30: ساعة | F30: ='اجمالي التكاليف خلال الفترة'!F9 -> تكلفة متغيرة 4
B31: =D31*C31 -> #DIV/0! | C31: ='توزيع التكاليف'!H17/الرئيسية!$N$10 -> #DIV/0! | D31: =$B$5 -> #DIV/0! | E31: ساعة | F31: ='اجمالي التكاليف خلال الفترة'!F10 -> تكلفة متغيرة 5 | G31: مباشرة
B32: =D32*C32 -> #DIV/0! | C32: ='توزيع التكاليف'!H18/الرئيسية!$N$10 -> #DIV/0! | D32: =$B$5 -> #DIV/0! | E32: ساعة | F32: ='اجمالي التكاليف خلال الفترة'!F11 -> تكلفة متغيرة 6
B33: =D33*C33 -> #DIV/0! | C33: ='توزيع التكاليف'!H19/الرئيسية!$N$10 -> #DIV/0! | D33: =$B$5 -> #DIV/0! | E33: ساعة | F33: ='اجمالي التكاليف خلال الفترة'!F12 -> تكلفة متغيرة 7
B34: =D34*C34 -> #DIV/0! | C34: ='توزيع التكاليف'!H20/الرئيسية!$N$10 -> #DIV/0! | D34: =$B$5 -> #DIV/0! | E34: ساعة | F34: ='اجمالي التكاليف خلال الفترة'!F13 -> تكلفة متغيرة 8 | G34: المتغيرة
B35: =D35*C35 -> #DIV/0! | C35: ='توزيع التكاليف'!H21/الرئيسية!$N$10 -> #DIV/0! | D35: =$B$5 -> #DIV/0! | E35: ساعة | F35: ='اجمالي التكاليف خلال الفترة'!F14 -> تكلفة متغيرة 9
B36: =D36*C36 -> #DIV/0! | C36: ='توزيع التكاليف'!H22/الرئيسية!$N$10 -> #DIV/0! | D36: =$B$5 -> #DIV/0! | E36: ساعة | F36: ='اجمالي التكاليف خلال الفترة'!F15 -> تكلفة متغيرة 10
B37: =D37*C37 -> #DIV/0! | C37: ='اهلاك خطوط الانتاج'!C2/F5*B5 -> #DIV/0! | D37: =$B$5 -> #DIV/0! | E37: ساعة | F37: ='اهلاك خطوط الانتاج'!$D$2 -> اهلاك خط الانتاج
B38: =SUM(B27:B37) -> #DIV/0! | C38: وحدة | D38: =F5 -> 1 | E38: لانتاج / بيع | F38: إجمالي التكلفة المعيارية الصناعية الغير مباشرة
B40: =D40*C40 -> #DIV/0! | C40: ='توزيع التكاليف'!H25/الرئيسية!$N$10 -> #DIV/0! | D40: =$B$5 -> #DIV/0! | E40: ساعة | F40: ='اجمالي التكاليف خلال الفترة'!C6 -> تكلفة ثابتة 1 | G40: التكاليف الغير
B41: =D41*C41 -> #DIV/0! | C41: ='توزيع التكاليف'!H26/الرئيسية!$N$10 -> #DIV/0! | D41: =$B$5 -> #DIV/0! | E41: ساعة | F41: ='اجمالي التكاليف خلال الفترة'!C7 -> تكلفة ثابتة 2
B42: =D42*C42 -> #DIV/0! | C42: ='توزيع التكاليف'!H27/الرئيسية!$N$10 -> #DIV/0! | D42: =$B$5 -> #DIV/0! | E42: ساعة | F42: ='اجمالي التكاليف خلال الفترة'!C8 -> تكلفة ثابتة 3
B43: =D43*C43 -> #DIV/0! | C43: ='توزيع التكاليف'!H28/الرئيسية!$N$10 -> #DIV/0! | D43: =$B$5 -> #DIV/0! | E43: ساعة | F43: ='اجمالي التكاليف خلال الفترة'!C9 -> تكلفة ثابتة 4
B44: =D44*C44 -> #DIV/0! | C44: ='توزيع التكاليف'!H29/الرئيسية!$N$10 -> #DIV/0! | D44: =$B$5 -> #DIV/0! | E44: ساعة | F44: ='اجمالي التكاليف خلال الفترة'!C10 -> تكلفة ثابتة 5 | G44: مباشرة
B45: =D45*C45 -> #DIV/0! | C45: ='توزيع التكاليف'!H30/الرئيسية!$N$10 -> #DIV/0! | D45: =$B$5 -> #DIV/0! | E45: ساعة | F45: ='اجمالي التكاليف خلال الفترة'!C11 -> تكلفة ثابتة 6
B46: =D46*C46 -> #DIV/0! | C46: ='توزيع التكاليف'!H31/الرئيسية!$N$10 -> #DIV/0! | D46: =$B$5 -> #DIV/0! | E46: ساعة | F46: ='اجمالي التكاليف خلال الفترة'!C12 -> تكلفة ثابتة 7
B47: =D47*C47 -> #DIV/0! | C47: ='توزيع التكاليف'!H32/الرئيسية!$N$10 -> #DIV/0! | D47: =$B$5 -> #DIV/0! | E47: ساعة | F47: ='اجمالي التكاليف خلال الفترة'!C13 -> تكلفة ثابتة 8 | G47: الثابتة
B48: =D48*C48 -> #DIV/0! | C48: ='توزيع التكاليف'!H33/الرئيسية!$N$10 -> #DIV/0! | D48: =$B$5 -> #DIV/0! | E48: ساعة | F48: ='اجمالي التكاليف خلال الفترة'!C14 -> تكلفة ثابتة 9
B49: =D49*C49 -> #DIV/0! | C49: ='توزيع التكاليف'!H34/الرئيسية!$N$10 -> #DIV/0! | D49: =$B$5 -> #DIV/0! | E49: ساعة | F49: ='اجمالي التكاليف خلال الفترة'!C15 -> تكلفة ثابتة 10
B50: =SUM(B40:B49) -> #DIV/0! | C50: وحدة | D50: =F5 -> 1 | E50: لانتاج / بيع | F50: إجمالي التكلفة المعيارية الصناعية الغير مباشرة
B53: معادلات تحديد نقطة التعادل
B55: الوصول | C55: التكلفة المتغيرة | D55: إجمالي | F55: سعر البيع | G55: إجمالي
...

Sheet الصنف 7
B2: =F2/الرئيسية!N14 -> #DIV/0! | D2: معدل ساعات التشغيل | F2: =الرئيسية!O14 -> 0 | G2: الطاقة المتاحة
B5: =F5/B2 -> #DIV/0! | D5: ساعات التشغيل | F5: 1 | G5: عدد الوحدات
B8: =B57 -> #DIV/0! | D8: نقطة التعادل | G8: سعر البيع
B11: =B21+B25+B38+B50 -> #DIV/0! | D11: وحدة | E11: =F5 -> 1 | F11: =الرئيسية!P14 -> 0 | G11: إجمالي التكلفة التقديرية للمنتج
B13: القيمة للوحدة | C13: سعر | D13: كمية | F13: الحساب | G13: التكلفة
D14: القياس | E14: وحده
B16: =C16*D16 -> 0 | C16: ='اجمالي التكاليف خلال الفترة'!H11 -> 0 | D16: 1 | E16: كيلو | F16: ='اجمالي التكاليف خلال الفترة'!I11 -> خام 1 | G16: المواد مباشرة
B17: =C17*D17 -> 0 | C17: ='اجمالي التكاليف خلال الفترة'!H12 -> 0 | D17: 1 | E17: عدد | F17: ='اجمالي التكاليف خلال الفترة'!I12 -> خام 2
B18: =C18*D18 -> 0 | C18: ='اجمالي التكاليف خلال الفترة'!H13 -> 0 | D18: 1 | E18: كيلو | F18: ='اجمالي التكاليف خلال الفترة'!I13 -> خام 3
B19: =C19*D19 -> 0 | C19: ='اجمالي التكاليف خلال الفترة'!H14 -> 0 | D19: 1 | E19: عدد | F19: ='اجمالي التكاليف خلال الفترة'!I14 -> خام 4
B20: =C20*D20 -> 0 | C20: ='اجمالي التكاليف خلال الفترة'!H15 -> 0 | D20: 1 | E20: كيلو | F20: ='اجمالي التكاليف خلال الفترة'!I15 -> خام 5
B21: =SUM(B16:B20)*D21 -> 0 | C21: وحدة | D21: =F5 -> 1 | E21: لانتاج | F21: إجمالي التكلفة المعيارية للمواد المباشرة
B23: =D23*C23 -> #DIV/0! | C23: ='توزيع التكاليف'!I10/الرئيسية!$N$14 -> #DIV/0! | D23: =$B$5 -> #DIV/0! | E23: ساعة | F23: تشغيلي | G23: الاجور الثابتة
B24: =D24*C24 -> #DIV/0! | C24: ='توزيع التكاليف'!I9/الرئيسية!$N$14 -> #DIV/0! | D24: =$B$5 -> #DIV/0! | E24: ساعة | F24: اضافي | G24: اجور متغيرة
B25: =SUM(B23:B24) -> #DIV/0! | C25: وحدة | D25: =F5 -> 1 | E25: لانتاج | F25: إجمالي التكلفة المعيارية للأجور المباشرة
B27: =D27*C27 -> #DIV/0! | C27: ='توزيع التكاليف'!I13/الرئيسية!$N$14 -> #DIV/0! | D27: =$B$5 -> #DIV/0! | E27: ساعة | F27: ='اجمالي التكاليف خلال الفترة'!F6 -> تكلفة متغيرة 1 | G27: التكاليف الغير
B28: =D28*C28 -> #DIV/0! | C28: ='توزيع التكاليف'!I14/الرئيسية!$N$14 -> #DIV/0! | D28: =$B$5 -> #DIV/0! | E28: ساعة | F28: ='اجمالي التكاليف خلال الفترة'!F7 -> تكلفة متغيرة 2
B29: =D29*C29 -> #DIV/0! | C29: ='توزيع التكاليف'!I15/الرئيسية!$N$14 -> #DIV/0! | D29: =$B$5 -> #DIV/0! | E29: ساعة | F29: ='اجمالي التكاليف خلال الفترة'!F8 -> تكلفة متغيرة 3
B30: =D30*C30 -> #DIV/0! | C30: ='توزيع التكاليف'!I16/الرئيسية!$N$14 -> #DIV/0! | D30: =$B$5 -> #DIV/0! | E30: ساعة | F30: ='اجمالي التكاليف خلال الفترة'!F9 -> تكلفة متغيرة 4
B31: =D31*C31 -> #DIV/0! | C31: ='توزيع التكاليف'!I17/الرئيسية!$N$14 -> #DIV/0! | D31: =$B$5 -> #DIV/0! | E31: ساعة | F31: ='اجمالي التكاليف خلال الفترة'!F10 -> تكلفة متغيرة 5 | G31: مباشرة
B32: =D32*C32 -> #DIV/0! | C32: ='توزيع التكاليف'!I18/الرئيسية!$N$14 -> #DIV/0! | D32: =$B$5 -> #DIV/0! | E32: ساعة | F32: ='اجمالي التكاليف خلال الفترة'!F11 -> تكلفة متغيرة 6
B33: =D33*C33 -> #DIV/0! | C33: ='توزيع التكاليف'!I19/الرئيسية!$N$14 -> #DIV/0! | D33: =$B$5 -> #DIV/0! | E33: ساعة | F33: ='اجمالي التكاليف خلال الفترة'!F12 -> تكلفة متغيرة 7
B34: =D34*C34 -> #DIV/0! | C34: ='توزيع التكاليف'!I20/الرئيسية!$N$14 -> #DIV/0! | D34: =$B$5 -> #DIV/0! | E34: ساعة | F34: ='اجمالي التكاليف خلال الفترة'!F13 -> تكلفة متغيرة 8 | G34: المتغيرة
B35: =D35*C35 -> #DIV/0! | C35: ='توزيع التكاليف'!I21/الرئيسية!$N$14 -> #DIV/0! | D35: =$B$5 -> #DIV/0! | E35: ساعة | F35: ='اجمالي التكاليف خلال الفترة'!F14 -> تكلفة متغيرة 9
B36: =D36*C36 -> #DIV/0! | C36: ='توزيع التكاليف'!I22/الرئيسية!$N$14 -> #DIV/0! | D36: =$B$5 -> #DIV/0! | E36: ساعة | F36: ='اجمالي التكاليف خلال الفترة'!F15 -> تكلفة متغيرة 10
B37: =D37*C37 -> #DIV/0! | C37: ='اهلاك خطوط الانتاج'!C2/F5*B5 -> #DIV/0! | D37: =$B$5 -> #DIV/0! | E37: ساعة | F37: ='اهلاك خطوط الانتاج'!$D$2 -> اهلاك خط الانتاج
B38: =SUM(B27:B37) -> #DIV/0! | C38: وحدة | D38: =F5 -> 1 | E38: لانتاج / بيع | F38: إجمالي التكلفة المعيارية الصناعية الغير مباشرة
B40: =D40*C40 -> #DIV/0! | C40: ='توزيع التكاليف'!I25/الرئيسية!$N$14 -> #DIV/0! | D40: =$B$5 -> #DIV/0! | E40: ساعة | F40: ='اجمالي التكاليف خلال الفترة'!C6 -> تكلفة ثابتة 1 | G40: التكاليف الغير
B41: =D41*C41 -> #DIV/0! | C41: ='توزيع التكاليف'!I26/الرئيسية!$N$14 -> #DIV/0! | D41: =$B$5 -> #DIV/0! | E41: ساعة | F41: ='اجمالي التكاليف خلال الفترة'!C7 -> تكلفة ثابتة 2
B42: =D42*C42 -> #DIV/0! | C42: ='توزيع التكاليف'!I27/الرئيسية!$N$14 -> #DIV/0! | D42: =$B$5 -> #DIV/0! | E42: ساعة | F42: ='اجمالي التكاليف خلال الفترة'!C8 -> تكلفة ثابتة 3
B43: =D43*C43 -> #DIV/0! | C43: ='توزيع التكاليف'!I28/الرئيسية!$N$14 -> #DIV/0! | D43: =$B$5 -> #DIV/0! | E43: ساعة | F43: ='اجمالي التكاليف خلال الفترة'!C9 -> تكلفة ثابتة 4
B44: =D44*C44 -> #DIV/0! | C44: ='توزيع التكاليف'!I29/الرئيسية!$N$14 -> #DIV/0! | D44: =$B$5 -> #DIV/0! | E44: ساعة | F44: ='اجمالي التكاليف خلال الفترة'!C10 -> تكلفة ثابتة 5 | G44: مباشرة
B45: =D45*C45 -> #DIV/0! | C45: ='توزيع التكاليف'!I30/الرئيسية!$N$14 -> #DIV/0! | D45: =$B$5 -> #DIV/0! | E45: ساعة | F45: ='اجمالي التكاليف خلال الفترة'!C11 -> تكلفة ثابتة 6
B46: =D46*C46 -> #DIV/0! | C46: ='توزيع التكاليف'!I31/الرئيسية!$N$14 -> #DIV/0! | D46: =$B$5 -> #DIV/0! | E46: ساعة | F46: ='اجمالي التكاليف خلال الفترة'!C12 -> تكلفة ثابتة 7
B47: =D47*C47 -> #DIV/0! | C47: ='توزيع التكاليف'!I32/الرئيسية!$N$14 -> #DIV/0! | D47: =$B$5 -> #DIV/0! | E47: ساعة | F47: ='اجمالي التكاليف خلال الفترة'!C13 -> تكلفة ثابتة 8 | G47: الثابتة
B48: =D48*C48 -> #DIV/0! | C48: ='توزيع التكاليف'!I33/الرئيسية!$N$14 -> #DIV/0! | D48: =$B$5 -> #DIV/0! | E48: ساعة | F48: ='اجمالي التكاليف خلال الفترة'!C14 -> تكلفة ثابتة 9
B49: =D49*C49 -> #DIV/0! | C49: ='توزيع التكاليف'!I34/الرئيسية!$N$14 -> #DIV/0! | D49: =$B$5 -> #DIV/0! | E49: ساعة | F49: ='اجمالي التكاليف خلال الفترة'!C15 -> تكلفة ثابتة 10
B50: =SUM(B40:B49) -> #DIV/0! | C50: وحدة | D50: =F5 -> 1 | E50: لانتاج / بيع | F50: إجمالي التكلفة المعيارية الصناعية الغير مباشرة
B53: معادلات تحديد نقطة التعادل
B55: الوصول | C55: التكلفة المتغيرة | D55: إجمالي | F55: سعر البيع | G55: إجمالي
...

Sheet الصنف 8
B2: =F2/الرئيسية!N18 -> #DIV/0! | D2: معدل ساعات التشغيل | F2: =الرئيسية!O18 -> 0 | G2: الطاقة المتاحة
B5: =F5/B2 -> #DIV/0! | D5: ساعات التشغيل | F5: 1 | G5: عدد الوحدات
B8: =B57 -> #DIV/0! | D8: نقطة التعادل | G8: سعر البيع
B11: =B21+B25+B38+B50 -> #DIV/0! | D11: وحدة | E11: =F5 -> 1 | F11: =الرئيسية!P18 -> 0 | G11: إجمالي التكلفة التقديرية للمنتج
B13: القيمة للوحدة | C13: سعر | D13: كمية | F13: الحساب | G13: التكلفة
D14: القياس | E14: وحده
B16: =C16*D16 -> 0 | C16: ='اجمالي التكاليف خلال الفترة'!H11 -> 0 | D16: 1 | E16: كيلو | F16: ='اجمالي التكاليف خلال الفترة'!I11 -> خام 1 | G16: المواد مباشرة
B17: =C17*D17 -> 0 | C17: ='اجمالي التكاليف خلال الفترة'!H12 -> 0 | D17: 1 | E17: عدد | F17: ='اجمالي التكاليف خلال الفترة'!I12 -> خام 2
B18: =C18*D18 -> 0 | C18: ='اجمالي التكاليف خلال الفترة'!H13 -> 0 | D18: 1 | E18: كيلو | F18: ='اجمالي التكاليف خلال الفترة'!I13 -> خام 3
B19: =C19*D19 -> 0 | C19: ='اجمالي التكاليف خلال الفترة'!H14 -> 0 | D19: 1 | E19: عدد | F19: ='اجمالي التكاليف خلال الفترة'!I14 -> خام 4
B20: =C20*D20 -> 0 | C20: ='اجمالي التكاليف خلال الفترة'!H15 -> 0 | D20: 1 | E20: كيلو | F20: ='اجمالي التكاليف خلال الفترة'!I15 -> خام 5
